{
  "version": 8,
  "blockIdVersion": 11,
  "anchorX": 0,
  "anchorY": 0,
  "anchorZ": 0,
  "blocks": [
    {
      "x": -3,
      "y": 2,
      "z": -2,
      "name": "Plant_Leaves_Jungle",
      "support": 15
    },
    {
      "x": -3,
      "y": 2,
      "z": -1,
      "name": "Plant_Leaves_Jungle",
      "support": 15
    },
    {
      "x": -3,
      "y": 2,
      "z": 0,
      "name": "Plant_Leaves_Jungle",
      "support": 15
    },
    {
      "x": -3,
      "y": 1,
      "z": 1,
      "name": "Plant_Leaves_Jungle",
      "support": 15
    },
    {
      "x": -2,
      "y": 1,
      "z": -2,
      "name": "Plant_Leaves_Jungle",
      "support": 15
    },
    {
      "x": -2,
      "y": 1,
      "z": -1,
      "name": "Plant_Leaves_Jungle",
      "support": 15
    },
    {
      "x": -2,
      "y": 2,
      "z": -1,
      "name": "Ingredient_Hay"
    },
    {
      "x": -2,
      "y": 3,
      "z": -1,
      "name": "Plant_Vine_Rug"
    },
    {
      "x": -2,
      "y": 1,
      "z": 0,
      "name": "Plant_Leaves_Jungle",
      "support": 15
    },
    {
      "x": -2,
      "y": 2,
      "z": 0,
      "name": "Ingredient_Hay"
    },
    {
      "x": -2,
      "y": 1,
      "z": 1,
      "name": "Ingredient_Hay"
    },
    {
      "x": -2,
      "y": 2,
      "z": 1,
      "name": "Ingredient_Hay"
    },
    {
      "x": -2,
      "y": 3,
      "z": 1,
      "name": "Empty"
    },
    {
      "x": -2,
      "y": 4,
      "z": 1,
      "name": "Empty"
    },
    {
      "x": -2,
      "y": 0,
      "z": 2,
      "name": "Plant_Leaves_Jungle",
      "support": 15
    },
    {
      "x": -2,
      "y": 1,
      "z": 2,
      "name": "Ingredient_Hay"
    },
    {
      "x": -2,
      "y": 2,
      "z": 2,
      "name": "Ingredient_Hay"
    },
    {
      "x": -2,
      "y": 1,
      "z": 3,
      "name": "Plant_Leaves_Jungle",
      "support": 15
    },
    {
      "x": -2,
      "y": 2,
      "z": 3,
      "name": "Plant_Leaves_Jungle",
      "support": 15
    },
    {
      "x": -1,
      "y": 1,
      "z": -3,
      "name": "Plant_Leaves_Jungle",
      "support": 15
    },
    {
      "x": -1,
      "y": 1,
      "z": -2,
      "name": "Plant_Leaves_Jungle",
      "support": 15
    },
    {
      "x": -1,
      "y": 2,
      "z": -2,
      "name": "Plant_Leaves_Jungle",
      "support": 15
    },
    {
      "x": -1,
      "y": 1,
      "z": -1,
      "name": "Ingredient_Hay"
    },
    {
      "x": -1,
      "y": 2,
      "z": -1,
      "name": "Ingredient_Hay"
    },
    {
      "x": -1,
      "y": 3,
      "z": -1,
      "name": "Plant_Vine_Rug"
    },
    {
      "x": -1,
      "y": 4,
      "z": -1,
      "name": "Empty"
    },
    {
      "x": -1,
      "y": 0,
      "z": 0,
      "name": "Plant_Leaves_Jungle",
      "support": 15
    },
    {
      "x": -1,
      "y": 1,
      "z": 0,
      "name": "Ingredient_Hay"
    },
    {
      "x": -1,
      "y": 2,
      "z": 0,
      "name": "Soil_Dirt_Lush_Half"
    },
    {
      "x": -1,
      "y": 3,
      "z": 0,
      "name": "Empty"
    },
    {
      "x": -1,
      "y": 4,
      "z": 0,
      "name": "Empty"
    },
    {
      "x": -1,
      "y": 1,
      "z": 1,
      "name": "Ingredient_Hay"
    },
    {
      "x": -1,
      "y": 2,
      "z": 1,
      "name": "Plant_Vine_Rug"
    },
    {
      "x": -1,
      "y": 3,
      "z": 1,
      "name": "Empty"
    },
    {
      "x": -1,
      "y": 4,
      "z": 1,
      "name": "Empty"
    },
    {
      "x": -1,
      "y": 5,
      "z": 1,
      "name": "Empty"
    },
    {
      "x": -1,
      "y": 1,
      "z": 2,
      "name": "Ingredient_Hay"
    },
    {
      "x": -1,
      "y": 2,
      "z": 2,
      "name": "Soil_Dirt_Lush_Half"
    },
    {
      "x": -1,
      "y": 3,
      "z": 2,
      "name": "Empty"
    },
    {
      "x": -1,
      "y": 4,
      "z": 2,
      "name": "Empty"
    },
    {
      "x": -1,
      "y": 0,
      "z": 3,
      "name": "Plant_Leaves_Jungle",
      "support": 15
    },
    {
      "x": -1,
      "y": 1,
      "z": 3,
      "name": "Ingredient_Hay"
    },
    {
      "x": -1,
      "y": 2,
      "z": 3,
      "name": "Ingredient_Hay"
    },
    {
      "x": -1,
      "y": 3,
      "z": 3,
      "name": "Plant_Vine_Rug"
    },
    {
      "x": -1,
      "y": 1,
      "z": 4,
      "name": "Plant_Leaves_Jungle",
      "support": 15
    },
    {
      "x": 0,
      "y": 1,
      "z": -3,
      "name": "Plant_Leaves_Jungle",
      "support": 15
    },
    {
      "x": 0,
      "y": 2,
      "z": -3,
      "name": "Plant_Leaves_Jungle",
      "support": 15
    },
    {
      "x": 0,
      "y": 1,
      "z": -2,
      "name": "Plant_Leaves_Jungle",
      "support": 15
    },
    {
      "x": 0,
      "y": 2,
      "z": -2,
      "name": "Ingredient_Hay"
    },
    {
      "x": 0,
      "y": 3,
      "z": -2,
      "name": "Plant_Vine_Rug"
    },
    {
      "x": 0,
      "y": 1,
      "z": -1,
      "name": "Ingredient_Hay"
    },
    {
      "x": 0,
      "y": 2,
      "z": -1,
      "name": "Ingredient_Hay"
    },
    {
      "x": 0,
      "y": 3,
      "z": -1,
      "name": "Empty"
    },
    {
      "x": 0,
      "y": 4,
      "z": -1,
      "name": "Empty"
    },
    {
      "x": 0,
      "y": 0,
      "z": 0,
      "name": "Plant_Leaves_Jungle",
      "support": 15
    },
    {
      "x": 0,
      "y": 1,
      "z": 0,
      "name": "Ingredient_Hay"
    },
    {
      "x": 0,
      "y": 2,
      "z": 0,
      "name": "Plant_Vine_Rug"
    },
    {
      "x": 0,
      "y": 3,
      "z": 0,
      "name": "Empty"
    },
    {
      "x": 0,
      "y": 4,
      "z": 0,
      "name": "Empty"
    },
    {
      "x": 0,
      "y": 5,
      "z": 0,
      "name": "Empty"
    },
    {
      "x": 0,
      "y": 1,
      "z": 1,
      "name": "Ingredient_Hay"
    },
    {
      "x": 0,
      "y": 2,
      "z": 1,
      "name": "Plant_Vine_Rug"
    },
    {
      "x": 0,
      "y": 3,
      "z": 1,
      "name": "Empty"
    },
    {
      "x": 0,
      "y": 4,
      "z": 1,
      "name": "Empty"
    },
    {
      "x": 0,
      "y": 5,
      "z": 1,
      "name": "Empty"
    },
    {
      "x": 0,
      "y": 1,
      "z": 2,
      "name": "Ingredient_Hay"
    },
    {
      "x": 0,
      "y": 2,
      "z": 2,
      "name": "Plant_Vine_Rug"
    },
    {
      "x": 0,
      "y": 3,
      "z": 2,
      "name": "Empty"
    },
    {
      "x": 0,
      "y": 4,
      "z": 2,
      "name": "Empty"
    },
    {
      "x": 0,
      "y": 5,
      "z": 2,
      "name": "Empty"
    },
    {
      "x": 0,
      "y": 0,
      "z": 3,
      "name": "Plant_Leaves_Jungle",
      "support": 15
    },
    {
      "x": 0,
      "y": 1,
      "z": 3,
      "name": "Ingredient_Hay"
    },
    {
      "x": 0,
      "y": 2,
      "z": 3,
      "name": "Ingredient_Hay"
    },
    {
      "x": 0,
      "y": 3,
      "z": 3,
      "name": "Plant_Vine_Rug"
    },
    {
      "x": 0,
      "y": 4,
      "z": 3,
      "name": "Empty"
    },
    {
      "x": 0,
      "y": 1,
      "z": 4,
      "name": "Plant_Leaves_Jungle",
      "support": 15
    },
    {
      "x": 1,
      "y": 2,
      "z": -2,
      "name": "Plant_Leaves_Jungle",
      "support": 15
    },
    {
      "x": 1,
      "y": 1,
      "z": -1,
      "name": "Plant_Leaves_Jungle",
      "support": 15
    },
    {
      "x": 1,
      "y": 2,
      "z": -1,
      "name": "Ingredient_Hay"
    },
    {
      "x": 1,
      "y": 3,
      "z": -1,
      "name": "Plant_Leaves_Jungle",
      "support": 15
    },
    {
      "x": 1,
      "y": 4,
      "z": -1,
      "name": "Empty"
    },
    {
      "x": 1,
      "y": 1,
      "z": 0,
      "name": "Ingredient_Hay"
    },
    {
      "x": 1,
      "y": 2,
      "z": 0,
      "name": "Plant_Vine_Rug"
    },
    {
      "x": 1,
      "y": 3,
      "z": 0,
      "name": "Empty"
    },
    {
      "x": 1,
      "y": 4,
      "z": 0,
      "name": "Empty"
    },
    {
      "x": 1,
      "y": 5,
      "z": 0,
      "name": "Empty"
    },
    {
      "x": 1,
      "y": 1,
      "z": 1,
      "name": "Ingredient_Hay"
    },
    {
      "x": 1,
      "y": 2,
      "z": 1,
      "name": "Plant_Vine_Rug"
    },
    {
      "x": 1,
      "y": 3,
      "z": 1,
      "name": "Empty"
    },
    {
      "x": 1,
      "y": 4,
      "z": 1,
      "name": "Empty"
    },
    {
      "x": 1,
      "y": 5,
      "z": 1,
      "name": "Empty"
    },
    {
      "x": 1,
      "y": 0,
      "z": 2,
      "name": "Plant_Leaves_Jungle",
      "support": 15
    },
    {
      "x": 1,
      "y": 1,
      "z": 2,
      "name": "Ingredient_Hay"
    },
    {
      "x": 1,
      "y": 2,
      "z": 2,
      "name": "Soil_Dirt_Lush_Half"
    },
    {
      "x": 1,
      "y": 3,
      "z": 2,
      "name": "Empty"
    },
    {
      "x": 1,
      "y": 4,
      "z": 2,
      "name": "Empty"
    },
    {
      "x": 1,
      "y": 5,
      "z": 2,
      "name": "Empty"
    },
    {
      "x": 1,
      "y": 0,
      "z": 3,
      "name": "Plant_Leaves_Jungle",
      "support": 15
    },
    {
      "x": 1,
      "y": 1,
      "z": 3,
      "name": "Plant_Leaves_Jungle",
      "support": 15
    },
    {
      "x": 1,
      "y": 2,
      "z": 3,
      "name": "Ingredient_Hay"
    },
    {
      "x": 1,
      "y": 3,
      "z": 3,
      "name": "Plant_Vine_Rug"
    },
    {
      "x": 1,
      "y": 4,
      "z": 3,
      "name": "Empty"
    },
    {
      "x": 1,
      "y": 2,
      "z": 4,
      "name": "Plant_Leaves_Jungle",
      "support": 15
    },
    {
      "x": 2,
      "y": 2,
      "z": -2,
      "name": "Plant_Leaves_Jungle",
      "support": 15
    },
    {
      "x": 2,
      "y": 1,
      "z": -1,
      "name": "Plant_Leaves_Jungle",
      "support": 15
    },
    {
      "x": 2,
      "y": 2,
      "z": -1,
      "name": "Ingredient_Hay"
    },
    {
      "x": 2,
      "y": 3,
      "z": -1,
      "name": "Plant_Vine_Rug"
    },
    {
      "x": 2,
      "y": 1,
      "z": 0,
      "name": "Ingredient_Hay"
    },
    {
      "x": 2,
      "y": 2,
      "z": 0,
      "name": "Soil_Dirt_Lush_Half"
    },
    {
      "x": 2,
      "y": 3,
      "z": 0,
      "name": "Empty"
    },
    {
      "x": 2,
      "y": 4,
      "z": 0,
      "name": "Empty"
    },
    {
      "x": 2,
      "y": 0,
      "z": 1,
      "name": "Plant_Leaves_Jungle",
      "support": 15
    },
    {
      "x": 2,
      "y": 1,
      "z": 1,
      "name": "Ingredient_Hay"
    },
    {
      "x": 2,
      "y": 2,
      "z": 1,
      "name": "Soil_Dirt_Lush_Half"
    },
    {
      "x": 2,
      "y": 3,
      "z": 1,
      "name": "Empty"
    },
    {
      "x": 2,
      "y": 4,
      "z": 1,
      "name": "Empty"
    },
    {
      "x": 2,
      "y": 5,
      "z": 1,
      "name": "Empty"
    },
    {
      "x": 2,
      "y": 0,
      "z": 2,
      "name": "Plant_Leaves_Jungle",
      "support": 15
    },
    {
      "x": 2,
      "y": 1,
      "z": 2,
      "name": "Ingredient_Hay"
    },
    {
      "x": 2,
      "y": 2,
      "z": 2,
      "name": "Ingredient_Hay"
    },
    {
      "x": 2,
      "y": 3,
      "z": 2,
      "name": "Empty"
    },
    {
      "x": 2,
      "y": 4,
      "z": 2,
      "name": "Empty"
    },
    {
      "x": 2,
      "y": 5,
      "z": 2,
      "name": "Empty"
    },
    {
      "x": 2,
      "y": 1,
      "z": 3,
      "name": "Plant_Leaves_Jungle",
      "support": 15
    },
    {
      "x": 2,
      "y": 2,
      "z": 3,
      "name": "Plant_Leaves_Jungle",
      "support": 15
    },
    {
      "x": 3,
      "y": 2,
      "z": -1,
      "name": "Plant_Leaves_Jungle",
      "support": 15
    },
    {
      "x": 3,
      "y": 1,
      "z": 0,
      "name": "Plant_Leaves_Jungle",
      "support": 15
    },
    {
      "x": 3,
      "y": 2,
      "z": 0,
      "name": "Ingredient_Hay"
    },
    {
      "x": 3,
      "y": 3,
      "z": 0,
      "name": "Plant_Vine_Rug"
    },
    {
      "x": 3,
      "y": 1,
      "z": 1,
      "name": "Plant_Leaves_Jungle",
      "support": 15
    },
    {
      "x": 3,
      "y": 2,
      "z": 1,
      "name": "Ingredient_Hay"
    }
  ],
  "entities": [
    {
      "Components": {
        "UtilityInventory": {
          "Inventory": {
            "Id": "Empty"
          },
          "ActiveSlot": -1
        },
        "EffectController": {},
        "UIComponentList": {},
        "HotbarInventory": {
          "Inventory": {
            "Id": "Simple",
            "Capacity": 3,
            "Items": {}
          },
          "ActiveSlot": 0
        },
        "Transform": {
          "Position": {
            "X": 0.5367391109466553,
            "Y": 3.607280731201172,
            "Z": 1.5307044982910156
          },
          "Rotation": {
            "Pitch": 0.0,
            "Yaw": -2.97363018989563,
            "Roll": 0.0
          }
        },
        "EntityScale": {
          "Scale": 1.0
        },
        "StorageInventory": {
          "Inventory": {
            "Id": "Empty"
          }
        },
        "Velocity": {
          "Velocity": {
            "X": 0.0,
            "Y": 0.0,
            "Z": 0.0
          }
        },
        "PrefabCopyable": {},
        "Interactions": {
          "Interactions": {
            "Use": "*UseNPC"
          }
        },
        "Model": {
          "Model": {
            "Id": "Pterodactyl",
            "Scale": 1.0325268507003784,
            "Static": false
          }
        },
        "UUID": {
          "UUID": {
            "$binary": "aOqa2r1HPHiXQlcKKOnJIQ==",
            "$type": "04"
          }
        },
        "EntityStats": {
          "Version": 5,
          "Stats": {
            "Oxygen": {
              "Id": "Oxygen",
              "Value": 100.0
            },
            "Mana": {
              "Id": "Mana",
              "Value": 0.0
            },
            "Health": {
              "Id": "Health",
              "Value": 60.0,
              "Modifiers": {
                "NPC_Max": {
                  "Id": "Static",
                  "CalculationType": "Additive",
                  "Amount": -40.0
                }
              }
            },
            "GlidingActive": {
              "Id": "GlidingActive",
              "Value": 0.0
            },
            "Immunity": {
              "Id": "Immunity",
              "Value": 0.0
            },
            "Stamina": {
              "Id": "Stamina",
              "Value": 10.0
            },
            "SignatureCharges": {
              "Id": "SignatureCharges",
              "Value": 0.0
            },
            "Ammo": {
              "Id": "Ammo",
              "Value": 0.0
            },
            "Unknown": {
              "Id": "Unknown",
              "Value": 0.0
            },
            "SignatureEnergy": {
              "Id": "SignatureEnergy",
              "Value": 0.0
            },
            "DeployablePreview": {
              "Id": "DeployablePreview",
              "Value": 0.0
            },
            "StaminaRegenDelay": {
              "Id": "StaminaRegenDelay",
              "Value": 0.0
            },
            "MagicCharges": {
              "Id": "MagicCharges",
              "Value": 0.0
            }
          }
        },
        "NPC": {
          "Version": 5,
          "UUID": {
            "$binary": "NF93yqTSMruIpR52GKPT5Q==",
            "$type": "04"
          },
          "Inventory": {
            "Version": 4,
            "ActiveHotbarSlot": 0,
            "ActiveToolsSlot": -1,
            "ActiveUtilitySlot": -1
          },
          "HvrPhs": 0.0,
          "HvrHght": 0.0,
          "MdlScl": 1.0325268507003784,
          "SpawnInstant": "0001-01-01T12:00:00Z",
          "WorldgenId": 0,
          "PathManager": {},
          "LeashPos": {
            "X": 3.4487016201019287,
            "Y": 57.7527961730957,
            "Z": 4.465680122375488
          },
          "LeashHdg": -2.97363018989563,
          "LeashPtch": 0.0,
          "RoleName": "Pterodactyl",
          "ActiveMC": "Fly"
        },
        "ArmorInventory": {
          "Inventory": {
            "Id": "Simple",
            "Capacity": 4,
            "Items": {}
          }
        },
        "HeadRotation": {
          "Rotation": {
            "Pitch": 0.0,
            "Yaw": -2.97363018989563,
            "Roll": 0.0
          }
        }
      }
    }
  ]
}