{
  "version": 8,
  "blockIdVersion": 11,
  "anchorX": 0,
  "anchorY": 0,
  "anchorZ": 0,
  "blocks": [
    {
      "x": -17,
      "y": 40,
      "z": -8,
      "name": "Rock_Volcanic"
    },
    {
      "x": -17,
      "y": 39,
      "z": -7,
      "name": "Rock_Volcanic"
    },
    {
      "x": -17,
      "y": 40,
      "z": -7,
      "name": "Rock_Volcanic"
    },
    {
      "x": -17,
      "y": 41,
      "z": -7,
      "name": "Rock_Volcanic"
    },
    {
      "x": -17,
      "y": 39,
      "z": -6,
      "name": "Rock_Volcanic"
    },
    {
      "x": -17,
      "y": 40,
      "z": -6,
      "name": "Rock_Volcanic"
    },
    {
      "x": -17,
      "y": 41,
      "z": -6,
      "name": "Rock_Volcanic"
    },
    {
      "x": -17,
      "y": 42,
      "z": -6,
      "name": "Rock_Volcanic"
    },
    {
      "x": -17,
      "y": 43,
      "z": -6,
      "name": "Rock_Volcanic"
    },
    {
      "x": -17,
      "y": 21,
      "z": -5,
      "name": "Rock_Volcanic"
    },
    {
      "x": -17,
      "y": 38,
      "z": -5,
      "name": "Rock_Volcanic"
    },
    {
      "x": -17,
      "y": 39,
      "z": -5,
      "name": "Rock_Volcanic"
    },
    {
      "x": -17,
      "y": 40,
      "z": -5,
      "name": "Rock_Volcanic"
    },
    {
      "x": -17,
      "y": 41,
      "z": -5,
      "name": "Rock_Volcanic"
    },
    {
      "x": -17,
      "y": 42,
      "z": -5,
      "name": "Rock_Volcanic"
    },
    {
      "x": -17,
      "y": 43,
      "z": -5,
      "name": "Rock_Volcanic"
    },
    {
      "x": -17,
      "y": 19,
      "z": -4,
      "name": "Rock_Volcanic"
    },
    {
      "x": -17,
      "y": 20,
      "z": -4,
      "name": "Rock_Volcanic"
    },
    {
      "x": -17,
      "y": 21,
      "z": -4,
      "name": "Rock_Volcanic"
    },
    {
      "x": -17,
      "y": 22,
      "z": -4,
      "name": "Rock_Volcanic"
    },
    {
      "x": -17,
      "y": 40,
      "z": -4,
      "name": "Rock_Volcanic"
    },
    {
      "x": -17,
      "y": 18,
      "z": -3,
      "name": "Rock_Volcanic"
    },
    {
      "x": -17,
      "y": 19,
      "z": -3,
      "name": "Rock_Volcanic"
    },
    {
      "x": -17,
      "y": 20,
      "z": -3,
      "name": "Rock_Volcanic"
    },
    {
      "x": -17,
      "y": 21,
      "z": -3,
      "name": "Rock_Volcanic"
    },
    {
      "x": -17,
      "y": 22,
      "z": -3,
      "name": "Rock_Volcanic"
    },
    {
      "x": -17,
      "y": 18,
      "z": -2,
      "name": "Rock_Volcanic"
    },
    {
      "x": -17,
      "y": 19,
      "z": -2,
      "name": "Rock_Volcanic"
    },
    {
      "x": -17,
      "y": 20,
      "z": -2,
      "name": "Rock_Volcanic"
    },
    {
      "x": -17,
      "y": 21,
      "z": -2,
      "name": "Rock_Volcanic"
    },
    {
      "x": -17,
      "y": 22,
      "z": -2,
      "name": "Rock_Volcanic"
    },
    {
      "x": -17,
      "y": 52,
      "z": -2,
      "name": "Rock_Volcanic"
    },
    {
      "x": -17,
      "y": 53,
      "z": -2,
      "name": "Rock_Volcanic"
    },
    {
      "x": -17,
      "y": 54,
      "z": -2,
      "name": "Rock_Volcanic"
    },
    {
      "x": -17,
      "y": 17,
      "z": -1,
      "name": "Rock_Volcanic"
    },
    {
      "x": -17,
      "y": 18,
      "z": -1,
      "name": "Rock_Volcanic"
    },
    {
      "x": -17,
      "y": 19,
      "z": -1,
      "name": "Rock_Volcanic"
    },
    {
      "x": -17,
      "y": 20,
      "z": -1,
      "name": "Rock_Volcanic"
    },
    {
      "x": -17,
      "y": 21,
      "z": -1,
      "name": "Rock_Volcanic"
    },
    {
      "x": -17,
      "y": 50,
      "z": -1,
      "name": "Rock_Volcanic"
    },
    {
      "x": -17,
      "y": 51,
      "z": -1,
      "name": "Rock_Volcanic"
    },
    {
      "x": -17,
      "y": 52,
      "z": -1,
      "name": "Rock_Volcanic"
    },
    {
      "x": -17,
      "y": 17,
      "z": 0,
      "name": "Rock_Volcanic"
    },
    {
      "x": -17,
      "y": 18,
      "z": 0,
      "name": "Rock_Volcanic"
    },
    {
      "x": -17,
      "y": 19,
      "z": 0,
      "name": "Rock_Volcanic"
    },
    {
      "x": -17,
      "y": 20,
      "z": 0,
      "name": "Rock_Volcanic"
    },
    {
      "x": -17,
      "y": 21,
      "z": 0,
      "name": "Rock_Volcanic"
    },
    {
      "x": -17,
      "y": 51,
      "z": 0,
      "name": "Rock_Volcanic"
    },
    {
      "x": -17,
      "y": 52,
      "z": 0,
      "name": "Rock_Volcanic"
    },
    {
      "x": -17,
      "y": 17,
      "z": 1,
      "name": "Rock_Volcanic"
    },
    {
      "x": -17,
      "y": 18,
      "z": 1,
      "name": "Rock_Volcanic"
    },
    {
      "x": -17,
      "y": 19,
      "z": 1,
      "name": "Rock_Volcanic"
    },
    {
      "x": -17,
      "y": 20,
      "z": 1,
      "name": "Rock_Volcanic"
    },
    {
      "x": -17,
      "y": 21,
      "z": 1,
      "name": "Rock_Volcanic"
    },
    {
      "x": -17,
      "y": 52,
      "z": 1,
      "name": "Rock_Volcanic"
    },
    {
      "x": -17,
      "y": 17,
      "z": 2,
      "name": "Rock_Volcanic"
    },
    {
      "x": -17,
      "y": 18,
      "z": 2,
      "name": "Rock_Volcanic"
    },
    {
      "x": -17,
      "y": 19,
      "z": 2,
      "name": "Rock_Volcanic"
    },
    {
      "x": -17,
      "y": 20,
      "z": 2,
      "name": "Rock_Volcanic"
    },
    {
      "x": -17,
      "y": 21,
      "z": 2,
      "name": "Rock_Volcanic"
    },
    {
      "x": -17,
      "y": 17,
      "z": 3,
      "name": "Rock_Volcanic"
    },
    {
      "x": -17,
      "y": 18,
      "z": 3,
      "name": "Rock_Volcanic"
    },
    {
      "x": -17,
      "y": 19,
      "z": 3,
      "name": "Rock_Volcanic"
    },
    {
      "x": -17,
      "y": 20,
      "z": 3,
      "name": "Rock_Volcanic"
    },
    {
      "x": -17,
      "y": 21,
      "z": 3,
      "name": "Rock_Volcanic"
    },
    {
      "x": -17,
      "y": 17,
      "z": 4,
      "name": "Rock_Volcanic"
    },
    {
      "x": -17,
      "y": 18,
      "z": 4,
      "name": "Rock_Volcanic"
    },
    {
      "x": -17,
      "y": 19,
      "z": 4,
      "name": "Rock_Volcanic"
    },
    {
      "x": -16,
      "y": 39,
      "z": -9,
      "name": "Rock_Volcanic"
    },
    {
      "x": -16,
      "y": 40,
      "z": -9,
      "name": "Rock_Volcanic"
    },
    {
      "x": -16,
      "y": 39,
      "z": -8,
      "name": "Rock_Volcanic"
    },
    {
      "x": -16,
      "y": 40,
      "z": -8,
      "name": "Rock_Volcanic"
    },
    {
      "x": -16,
      "y": 41,
      "z": -8,
      "name": "Soil_Volcanic_Gravel"
    },
    {
      "x": -16,
      "y": 42,
      "z": -8,
      "name": "Soil_Volcanic_Gravel"
    },
    {
      "x": -16,
      "y": 23,
      "z": -7,
      "name": "Rock_Volcanic"
    },
    {
      "x": -16,
      "y": 24,
      "z": -7,
      "name": "Rock_Volcanic"
    },
    {
      "x": -16,
      "y": 38,
      "z": -7,
      "name": "Rock_Volcanic"
    },
    {
      "x": -16,
      "y": 39,
      "z": -7,
      "name": "Soil_Volcanic_Gravel"
    },
    {
      "x": -16,
      "y": 40,
      "z": -7,
      "name": "Rock_Volcanic"
    },
    {
      "x": -16,
      "y": 41,
      "z": -7,
      "name": "Rock_Volcanic"
    },
    {
      "x": -16,
      "y": 42,
      "z": -7,
      "name": "Soil_Volcanic_Gravel"
    },
    {
      "x": -16,
      "y": 43,
      "z": -7,
      "name": "Soil_Volcanic_Gravel"
    },
    {
      "x": -16,
      "y": 56,
      "z": -7,
      "name": "Rock_Volcanic"
    },
    {
      "x": -16,
      "y": 21,
      "z": -6,
      "name": "Rock_Volcanic"
    },
    {
      "x": -16,
      "y": 22,
      "z": -6,
      "name": "Rock_Volcanic"
    },
    {
      "x": -16,
      "y": 23,
      "z": -6,
      "name": "Rock_Volcanic"
    },
    {
      "x": -16,
      "y": 24,
      "z": -6,
      "name": "Soil_Volcanic_Gravel"
    },
    {
      "x": -16,
      "y": 25,
      "z": -6,
      "name": "Rock_Volcanic"
    },
    {
      "x": -16,
      "y": 37,
      "z": -6,
      "name": "Soil_Volcanic_Gravel"
    },
    {
      "x": -16,
      "y": 38,
      "z": -6,
      "name": "Rock_Volcanic"
    },
    {
      "x": -16,
      "y": 39,
      "z": -6,
      "name": "Soil_Volcanic_Gravel"
    },
    {
      "x": -16,
      "y": 40,
      "z": -6,
      "name": "Rock_Volcanic"
    },
    {
      "x": -16,
      "y": 41,
      "z": -6,
      "name": "Rock_Volcanic"
    },
    {
      "x": -16,
      "y": 42,
      "z": -6,
      "name": "Rock_Volcanic"
    },
    {
      "x": -16,
      "y": 43,
      "z": -6,
      "name": "Rock_Volcanic"
    },
    {
      "x": -16,
      "y": 44,
      "z": -6,
      "name": "Rock_Volcanic"
    },
    {
      "x": -16,
      "y": 54,
      "z": -6,
      "name": "Rock_Volcanic"
    },
    {
      "x": -16,
      "y": 55,
      "z": -6,
      "name": "Rock_Volcanic"
    },
    {
      "x": -16,
      "y": 56,
      "z": -6,
      "name": "Rock_Volcanic"
    },
    {
      "x": -16,
      "y": 19,
      "z": -5,
      "name": "Rock_Volcanic"
    },
    {
      "x": -16,
      "y": 20,
      "z": -5,
      "name": "Rock_Volcanic"
    },
    {
      "x": -16,
      "y": 21,
      "z": -5,
      "name": "Rock_Volcanic"
    },
    {
      "x": -16,
      "y": 22,
      "z": -5,
      "name": "Rock_Volcanic"
    },
    {
      "x": -16,
      "y": 23,
      "z": -5,
      "name": "Soil_Volcanic_Gravel"
    },
    {
      "x": -16,
      "y": 24,
      "z": -5,
      "name": "Rock_Volcanic"
    },
    {
      "x": -16,
      "y": 25,
      "z": -5,
      "name": "Rock_Volcanic"
    },
    {
      "x": -16,
      "y": 37,
      "z": -5,
      "name": "Rock_Volcanic"
    },
    {
      "x": -16,
      "y": 38,
      "z": -5,
      "name": "Rock_Volcanic"
    },
    {
      "x": -16,
      "y": 39,
      "z": -5,
      "name": "Soil_Volcanic_Gravel"
    },
    {
      "x": -16,
      "y": 40,
      "z": -5,
      "name": "Rock_Volcanic"
    },
    {
      "x": -16,
      "y": 41,
      "z": -5,
      "name": "Rock_Volcanic"
    },
    {
      "x": -16,
      "y": 42,
      "z": -5,
      "name": "Rock_Volcanic"
    },
    {
      "x": -16,
      "y": 43,
      "z": -5,
      "name": "Rock_Volcanic"
    },
    {
      "x": -16,
      "y": 44,
      "z": -5,
      "name": "Rock_Volcanic"
    },
    {
      "x": -16,
      "y": 45,
      "z": -5,
      "name": "Rock_Volcanic"
    },
    {
      "x": -16,
      "y": 53,
      "z": -5,
      "name": "Rock_Volcanic"
    },
    {
      "x": -16,
      "y": 54,
      "z": -5,
      "name": "Rock_Volcanic"
    },
    {
      "x": -16,
      "y": 55,
      "z": -5,
      "name": "Rock_Volcanic"
    },
    {
      "x": -16,
      "y": 56,
      "z": -5,
      "name": "Soil_Volcanic_Gravel"
    },
    {
      "x": -16,
      "y": 17,
      "z": -4,
      "name": "Rock_Volcanic"
    },
    {
      "x": -16,
      "y": 18,
      "z": -4,
      "name": "Rock_Volcanic"
    },
    {
      "x": -16,
      "y": 19,
      "z": -4,
      "name": "Rock_Volcanic"
    },
    {
      "x": -16,
      "y": 20,
      "z": -4,
      "name": "Rock_Volcanic"
    },
    {
      "x": -16,
      "y": 21,
      "z": -4,
      "name": "Rock_Volcanic"
    },
    {
      "x": -16,
      "y": 22,
      "z": -4,
      "name": "Rock_Volcanic"
    },
    {
      "x": -16,
      "y": 23,
      "z": -4,
      "name": "Rock_Volcanic"
    },
    {
      "x": -16,
      "y": 24,
      "z": -4,
      "name": "Soil_Volcanic_Gravel"
    },
    {
      "x": -16,
      "y": 25,
      "z": -4,
      "name": "Rock_Volcanic"
    },
    {
      "x": -16,
      "y": 26,
      "z": -4,
      "name": "Soil_Volcanic_Gravel"
    },
    {
      "x": -16,
      "y": 36,
      "z": -4,
      "name": "Soil_Volcanic_Gravel"
    },
    {
      "x": -16,
      "y": 37,
      "z": -4,
      "name": "Rock_Volcanic"
    },
    {
      "x": -16,
      "y": 38,
      "z": -4,
      "name": "Rock_Volcanic"
    },
    {
      "x": -16,
      "y": 39,
      "z": -4,
      "name": "Rock_Volcanic"
    },
    {
      "x": -16,
      "y": 40,
      "z": -4,
      "name": "Rock_Volcanic"
    },
    {
      "x": -16,
      "y": 41,
      "z": -4,
      "name": "Rock_Volcanic"
    },
    {
      "x": -16,
      "y": 42,
      "z": -4,
      "name": "Rock_Volcanic"
    },
    {
      "x": -16,
      "y": 43,
      "z": -4,
      "name": "Rock_Volcanic"
    },
    {
      "x": -16,
      "y": 44,
      "z": -4,
      "name": "Rock_Volcanic"
    },
    {
      "x": -16,
      "y": 45,
      "z": -4,
      "name": "Rock_Volcanic"
    },
    {
      "x": -16,
      "y": 46,
      "z": -4,
      "name": "Rock_Volcanic"
    },
    {
      "x": -16,
      "y": 47,
      "z": -4,
      "name": "Rock_Volcanic"
    },
    {
      "x": -16,
      "y": 48,
      "z": -4,
      "name": "Rock_Volcanic"
    },
    {
      "x": -16,
      "y": 51,
      "z": -4,
      "name": "Rock_Volcanic"
    },
    {
      "x": -16,
      "y": 52,
      "z": -4,
      "name": "Rock_Volcanic"
    },
    {
      "x": -16,
      "y": 53,
      "z": -4,
      "name": "Rock_Volcanic"
    },
    {
      "x": -16,
      "y": 54,
      "z": -4,
      "name": "Rock_Volcanic"
    },
    {
      "x": -16,
      "y": 55,
      "z": -4,
      "name": "Rock_Volcanic"
    },
    {
      "x": -16,
      "y": 56,
      "z": -4,
      "name": "Rock_Volcanic"
    },
    {
      "x": -16,
      "y": 17,
      "z": -3,
      "name": "Rock_Volcanic"
    },
    {
      "x": -16,
      "y": 18,
      "z": -3,
      "name": "Rock_Volcanic"
    },
    {
      "x": -16,
      "y": 19,
      "z": -3,
      "name": "Rock_Volcanic"
    },
    {
      "x": -16,
      "y": 20,
      "z": -3,
      "name": "Rock_Volcanic"
    },
    {
      "x": -16,
      "y": 21,
      "z": -3,
      "name": "Rock_Volcanic"
    },
    {
      "x": -16,
      "y": 22,
      "z": -3,
      "name": "Rock_Volcanic"
    },
    {
      "x": -16,
      "y": 23,
      "z": -3,
      "name": "Soil_Volcanic_Gravel"
    },
    {
      "x": -16,
      "y": 24,
      "z": -3,
      "name": "Soil_Volcanic_Gravel"
    },
    {
      "x": -16,
      "y": 37,
      "z": -3,
      "name": "Rock_Volcanic"
    },
    {
      "x": -16,
      "y": 38,
      "z": -3,
      "name": "Rock_Volcanic"
    },
    {
      "x": -16,
      "y": 39,
      "z": -3,
      "name": "Rock_Volcanic"
    },
    {
      "x": -16,
      "y": 40,
      "z": -3,
      "name": "Rock_Volcanic"
    },
    {
      "x": -16,
      "y": 41,
      "z": -3,
      "name": "Rock_Volcanic"
    },
    {
      "x": -16,
      "y": 42,
      "z": -3,
      "name": "Rock_Volcanic"
    },
    {
      "x": -16,
      "y": 44,
      "z": -3,
      "name": "Rock_Volcanic"
    },
    {
      "x": -16,
      "y": 45,
      "z": -3,
      "name": "Rock_Volcanic"
    },
    {
      "x": -16,
      "y": 46,
      "z": -3,
      "name": "Rock_Volcanic"
    },
    {
      "x": -16,
      "y": 47,
      "z": -3,
      "name": "Rock_Volcanic"
    },
    {
      "x": -16,
      "y": 48,
      "z": -3,
      "name": "Rock_Volcanic"
    },
    {
      "x": -16,
      "y": 49,
      "z": -3,
      "name": "Rock_Volcanic"
    },
    {
      "x": -16,
      "y": 50,
      "z": -3,
      "name": "Rock_Volcanic"
    },
    {
      "x": -16,
      "y": 51,
      "z": -3,
      "name": "Rock_Volcanic"
    },
    {
      "x": -16,
      "y": 52,
      "z": -3,
      "name": "Rock_Volcanic"
    },
    {
      "x": -16,
      "y": 53,
      "z": -3,
      "name": "Rock_Volcanic"
    },
    {
      "x": -16,
      "y": 54,
      "z": -3,
      "name": "Rock_Volcanic"
    },
    {
      "x": -16,
      "y": 55,
      "z": -3,
      "name": "Soil_Volcanic_Gravel"
    },
    {
      "x": -16,
      "y": 17,
      "z": -2,
      "name": "Rock_Volcanic"
    },
    {
      "x": -16,
      "y": 18,
      "z": -2,
      "name": "Rock_Volcanic"
    },
    {
      "x": -16,
      "y": 19,
      "z": -2,
      "name": "Rock_Volcanic"
    },
    {
      "x": -16,
      "y": 20,
      "z": -2,
      "name": "Rock_Volcanic"
    },
    {
      "x": -16,
      "y": 21,
      "z": -2,
      "name": "Rock_Volcanic"
    },
    {
      "x": -16,
      "y": 22,
      "z": -2,
      "name": "Rock_Volcanic"
    },
    {
      "x": -16,
      "y": 23,
      "z": -2,
      "name": "Rock_Volcanic"
    },
    {
      "x": -16,
      "y": 24,
      "z": -2,
      "name": "Soil_Volcanic_Gravel"
    },
    {
      "x": -16,
      "y": 39,
      "z": -2,
      "name": "Rock_Volcanic"
    },
    {
      "x": -16,
      "y": 47,
      "z": -2,
      "name": "Rock_Volcanic"
    },
    {
      "x": -16,
      "y": 48,
      "z": -2,
      "name": "Rock_Volcanic"
    },
    {
      "x": -16,
      "y": 49,
      "z": -2,
      "name": "Rock_Volcanic"
    },
    {
      "x": -16,
      "y": 50,
      "z": -2,
      "name": "Rock_Volcanic"
    },
    {
      "x": -16,
      "y": 51,
      "z": -2,
      "name": "Rock_Volcanic"
    },
    {
      "x": -16,
      "y": 52,
      "z": -2,
      "name": "Rock_Volcanic"
    },
    {
      "x": -16,
      "y": 53,
      "z": -2,
      "name": "Rock_Volcanic"
    },
    {
      "x": -16,
      "y": 54,
      "z": -2,
      "name": "Rock_Volcanic"
    },
    {
      "x": -16,
      "y": 55,
      "z": -2,
      "name": "Soil_Volcanic_Gravel"
    },
    {
      "x": -16,
      "y": 16,
      "z": -1,
      "name": "Rock_Volcanic"
    },
    {
      "x": -16,
      "y": 17,
      "z": -1,
      "name": "Rock_Volcanic"
    },
    {
      "x": -16,
      "y": 18,
      "z": -1,
      "name": "Rock_Volcanic"
    },
    {
      "x": -16,
      "y": 19,
      "z": -1,
      "name": "Rock_Volcanic"
    },
    {
      "x": -16,
      "y": 20,
      "z": -1,
      "name": "Rock_Volcanic"
    },
    {
      "x": -16,
      "y": 21,
      "z": -1,
      "name": "Rock_Volcanic"
    },
    {
      "x": -16,
      "y": 22,
      "z": -1,
      "name": "Soil_Volcanic_Gravel"
    },
    {
      "x": -16,
      "y": 23,
      "z": -1,
      "name": "Rock_Volcanic"
    },
    {
      "x": -16,
      "y": 24,
      "z": -1,
      "name": "Plant_Moss_Short_Red",
      "support": 15
    },
    {
      "x": -16,
      "y": 48,
      "z": -1,
      "name": "Rock_Volcanic"
    },
    {
      "x": -16,
      "y": 49,
      "z": -1,
      "name": "Rock_Volcanic"
    },
    {
      "x": -16,
      "y": 50,
      "z": -1,
      "name": "Rock_Volcanic"
    },
    {
      "x": -16,
      "y": 51,
      "z": -1,
      "name": "Rock_Volcanic"
    },
    {
      "x": -16,
      "y": 52,
      "z": -1,
      "name": "Rock_Volcanic"
    },
    {
      "x": -16,
      "y": 53,
      "z": -1,
      "name": "Rock_Volcanic"
    },
    {
      "x": -16,
      "y": 54,
      "z": -1,
      "name": "Rock_Volcanic"
    },
    {
      "x": -16,
      "y": 16,
      "z": 0,
      "name": "Rock_Volcanic"
    },
    {
      "x": -16,
      "y": 17,
      "z": 0,
      "name": "Rock_Volcanic"
    },
    {
      "x": -16,
      "y": 18,
      "z": 0,
      "name": "Rock_Volcanic"
    },
    {
      "x": -16,
      "y": 19,
      "z": 0,
      "name": "Rock_Volcanic"
    },
    {
      "x": -16,
      "y": 20,
      "z": 0,
      "name": "Rock_Volcanic"
    },
    {
      "x": -16,
      "y": 21,
      "z": 0,
      "name": "Rock_Volcanic"
    },
    {
      "x": -16,
      "y": 22,
      "z": 0,
      "name": "Rock_Volcanic"
    },
    {
      "x": -16,
      "y": 23,
      "z": 0,
      "name": "Rock_Volcanic"
    },
    {
      "x": -16,
      "y": 49,
      "z": 0,
      "name": "Rock_Volcanic"
    },
    {
      "x": -16,
      "y": 50,
      "z": 0,
      "name": "Rock_Volcanic"
    },
    {
      "x": -16,
      "y": 51,
      "z": 0,
      "name": "Rock_Volcanic"
    },
    {
      "x": -16,
      "y": 52,
      "z": 0,
      "name": "Rock_Volcanic"
    },
    {
      "x": -16,
      "y": 53,
      "z": 0,
      "name": "Rock_Volcanic"
    },
    {
      "x": -16,
      "y": 54,
      "z": 0,
      "name": "Rock_Volcanic"
    },
    {
      "x": -16,
      "y": 16,
      "z": 1,
      "name": "Rock_Volcanic"
    },
    {
      "x": -16,
      "y": 17,
      "z": 1,
      "name": "Rock_Volcanic"
    },
    {
      "x": -16,
      "y": 18,
      "z": 1,
      "name": "Rock_Volcanic"
    },
    {
      "x": -16,
      "y": 19,
      "z": 1,
      "name": "Rock_Volcanic"
    },
    {
      "x": -16,
      "y": 20,
      "z": 1,
      "name": "Rock_Volcanic"
    },
    {
      "x": -16,
      "y": 21,
      "z": 1,
      "name": "Rock_Volcanic"
    },
    {
      "x": -16,
      "y": 22,
      "z": 1,
      "name": "Rock_Volcanic"
    },
    {
      "x": -16,
      "y": 23,
      "z": 1,
      "name": "Soil_Volcanic_Gravel"
    },
    {
      "x": -16,
      "y": 50,
      "z": 1,
      "name": "Rock_Volcanic"
    },
    {
      "x": -16,
      "y": 51,
      "z": 1,
      "name": "Rock_Volcanic"
    },
    {
      "x": -16,
      "y": 52,
      "z": 1,
      "name": "Rock_Volcanic"
    },
    {
      "x": -16,
      "y": 53,
      "z": 1,
      "name": "Rock_Volcanic"
    },
    {
      "x": -16,
      "y": 15,
      "z": 2,
      "name": "Rock_Volcanic"
    },
    {
      "x": -16,
      "y": 16,
      "z": 2,
      "name": "Rock_Volcanic"
    },
    {
      "x": -16,
      "y": 17,
      "z": 2,
      "name": "Rock_Volcanic"
    },
    {
      "x": -16,
      "y": 18,
      "z": 2,
      "name": "Rock_Volcanic"
    },
    {
      "x": -16,
      "y": 19,
      "z": 2,
      "name": "Rock_Volcanic"
    },
    {
      "x": -16,
      "y": 20,
      "z": 2,
      "name": "Rock_Volcanic"
    },
    {
      "x": -16,
      "y": 21,
      "z": 2,
      "name": "Rock_Volcanic"
    },
    {
      "x": -16,
      "y": 22,
      "z": 2,
      "name": "Rock_Volcanic"
    },
    {
      "x": -16,
      "y": 51,
      "z": 2,
      "name": "Rock_Volcanic"
    },
    {
      "x": -16,
      "y": 52,
      "z": 2,
      "name": "Rock_Volcanic"
    },
    {
      "x": -16,
      "y": 53,
      "z": 2,
      "name": "Rock_Volcanic"
    },
    {
      "x": -16,
      "y": 15,
      "z": 3,
      "name": "Rock_Volcanic"
    },
    {
      "x": -16,
      "y": 16,
      "z": 3,
      "name": "Rock_Volcanic"
    },
    {
      "x": -16,
      "y": 17,
      "z": 3,
      "name": "Rock_Volcanic"
    },
    {
      "x": -16,
      "y": 18,
      "z": 3,
      "name": "Rock_Volcanic"
    },
    {
      "x": -16,
      "y": 19,
      "z": 3,
      "name": "Rock_Volcanic"
    },
    {
      "x": -16,
      "y": 20,
      "z": 3,
      "name": "Rock_Volcanic"
    },
    {
      "x": -16,
      "y": 21,
      "z": 3,
      "name": "Rock_Volcanic"
    },
    {
      "x": -16,
      "y": 22,
      "z": 3,
      "name": "Rock_Volcanic"
    },
    {
      "x": -16,
      "y": 15,
      "z": 4,
      "name": "Rock_Volcanic"
    },
    {
      "x": -16,
      "y": 16,
      "z": 4,
      "name": "Rock_Volcanic"
    },
    {
      "x": -16,
      "y": 17,
      "z": 4,
      "name": "Rock_Volcanic"
    },
    {
      "x": -16,
      "y": 18,
      "z": 4,
      "name": "Rock_Volcanic"
    },
    {
      "x": -16,
      "y": 19,
      "z": 4,
      "name": "Rock_Volcanic"
    },
    {
      "x": -16,
      "y": 20,
      "z": 4,
      "name": "Rock_Volcanic"
    },
    {
      "x": -16,
      "y": 21,
      "z": 4,
      "name": "Soil_Volcanic_Gravel"
    },
    {
      "x": -16,
      "y": 16,
      "z": 5,
      "name": "Rock_Volcanic"
    },
    {
      "x": -16,
      "y": 17,
      "z": 5,
      "name": "Rock_Volcanic"
    },
    {
      "x": -16,
      "y": 18,
      "z": 5,
      "name": "Rock_Volcanic"
    },
    {
      "x": -16,
      "y": 19,
      "z": 5,
      "name": "Rock_Volcanic"
    },
    {
      "x": -16,
      "y": 20,
      "z": 5,
      "name": "Rock_Volcanic"
    },
    {
      "x": -16,
      "y": 16,
      "z": 6,
      "name": "Rock_Volcanic"
    },
    {
      "x": -16,
      "y": 17,
      "z": 6,
      "name": "Rock_Volcanic"
    },
    {
      "x": -16,
      "y": 18,
      "z": 6,
      "name": "Rock_Volcanic"
    },
    {
      "x": -16,
      "y": 17,
      "z": 7,
      "name": "Rock_Volcanic"
    },
    {
      "x": -15,
      "y": 39,
      "z": -10,
      "name": "Rock_Volcanic"
    },
    {
      "x": -15,
      "y": 40,
      "z": -10,
      "name": "Rock_Volcanic"
    },
    {
      "x": -15,
      "y": 38,
      "z": -9,
      "name": "Rock_Volcanic"
    },
    {
      "x": -15,
      "y": 39,
      "z": -9,
      "name": "Rock_Volcanic"
    },
    {
      "x": -15,
      "y": 40,
      "z": -9,
      "name": "Rock_Volcanic"
    },
    {
      "x": -15,
      "y": 41,
      "z": -9,
      "name": "Soil_Volcanic_Gravel"
    },
    {
      "x": -15,
      "y": 42,
      "z": -9,
      "name": "Soil_Volcanic_Gravel"
    },
    {
      "x": -15,
      "y": 38,
      "z": -8,
      "name": "Rock_Volcanic"
    },
    {
      "x": -15,
      "y": 39,
      "z": -8,
      "name": "Rock_Volcanic"
    },
    {
      "x": -15,
      "y": 40,
      "z": -8,
      "name": "Rock_Volcanic"
    },
    {
      "x": -15,
      "y": 41,
      "z": -8,
      "name": "Rock_Volcanic"
    },
    {
      "x": -15,
      "y": 42,
      "z": -8,
      "name": "Soil_Volcanic_Gravel"
    },
    {
      "x": -15,
      "y": 43,
      "z": -8,
      "name": "Soil_Volcanic_Gravel"
    },
    {
      "x": -15,
      "y": 55,
      "z": -8,
      "name": "Rock_Volcanic"
    },
    {
      "x": -15,
      "y": 56,
      "z": -8,
      "name": "Rock_Volcanic"
    },
    {
      "x": -15,
      "y": 22,
      "z": -7,
      "name": "Rock_Volcanic"
    },
    {
      "x": -15,
      "y": 23,
      "z": -7,
      "name": "Rock_Volcanic"
    },
    {
      "x": -15,
      "y": 24,
      "z": -7,
      "name": "Rock_Volcanic"
    },
    {
      "x": -15,
      "y": 25,
      "z": -7,
      "name": "Rock_Volcanic"
    },
    {
      "x": -15,
      "y": 37,
      "z": -7,
      "name": "Rock_Volcanic"
    },
    {
      "x": -15,
      "y": 38,
      "z": -7,
      "name": "Soil_Volcanic_Gravel"
    },
    {
      "x": -15,
      "y": 39,
      "z": -7,
      "name": "Rock_Volcanic"
    },
    {
      "x": -15,
      "y": 40,
      "z": -7,
      "name": "Rock_Volcanic"
    },
    {
      "x": -15,
      "y": 41,
      "z": -7,
      "name": "Rock_Volcanic"
    },
    {
      "x": -15,
      "y": 42,
      "z": -7,
      "name": "Soil_Volcanic_Gravel"
    },
    {
      "x": -15,
      "y": 43,
      "z": -7,
      "name": "Rock_Volcanic"
    },
    {
      "x": -15,
      "y": 44,
      "z": -7,
      "name": "Soil_Volcanic_Gravel"
    },
    {
      "x": -15,
      "y": 54,
      "z": -7,
      "name": "Rock_Volcanic"
    },
    {
      "x": -15,
      "y": 55,
      "z": -7,
      "name": "Rock_Volcanic"
    },
    {
      "x": -15,
      "y": 56,
      "z": -7,
      "name": "Rock_Volcanic"
    },
    {
      "x": -15,
      "y": 57,
      "z": -7,
      "name": "Soil_Volcanic_Gravel"
    },
    {
      "x": -15,
      "y": 20,
      "z": -6,
      "name": "Rock_Volcanic"
    },
    {
      "x": -15,
      "y": 21,
      "z": -6,
      "name": "Rock_Volcanic"
    },
    {
      "x": -15,
      "y": 22,
      "z": -6,
      "name": "Rock_Volcanic"
    },
    {
      "x": -15,
      "y": 23,
      "z": -6,
      "name": "Rock_Volcanic"
    },
    {
      "x": -15,
      "y": 24,
      "z": -6,
      "name": "Rock_Volcanic"
    },
    {
      "x": -15,
      "y": 25,
      "z": -6,
      "name": "Soil_Volcanic_Gravel"
    },
    {
      "x": -15,
      "y": 26,
      "z": -6,
      "name": "Rock_Volcanic"
    },
    {
      "x": -15,
      "y": 27,
      "z": -6,
      "name": "Rock_Volcanic"
    },
    {
      "x": -15,
      "y": 36,
      "z": -6,
      "name": "Rock_Volcanic"
    },
    {
      "x": -15,
      "y": 37,
      "z": -6,
      "name": "Rock_Volcanic"
    },
    {
      "x": -15,
      "y": 38,
      "z": -6,
      "name": "Rock_Volcanic"
    },
    {
      "x": -15,
      "y": 39,
      "z": -6,
      "name": "Soil_Volcanic_Gravel"
    },
    {
      "x": -15,
      "y": 40,
      "z": -6,
      "name": "Rock_Volcanic"
    },
    {
      "x": -15,
      "y": 41,
      "z": -6,
      "name": "Rock_Volcanic"
    },
    {
      "x": -15,
      "y": 42,
      "z": -6,
      "name": "Soil_Volcanic_Gravel"
    },
    {
      "x": -15,
      "y": 43,
      "z": -6,
      "name": "Soil_Volcanic_Gravel"
    },
    {
      "x": -15,
      "y": 44,
      "z": -6,
      "name": "Soil_Volcanic_Gravel"
    },
    {
      "x": -15,
      "y": 45,
      "z": -6,
      "name": "Rock_Volcanic"
    },
    {
      "x": -15,
      "y": 52,
      "z": -6,
      "name": "Rock_Volcanic"
    },
    {
      "x": -15,
      "y": 53,
      "z": -6,
      "name": "Rock_Volcanic"
    },
    {
      "x": -15,
      "y": 54,
      "z": -6,
      "name": "Rock_Volcanic"
    },
    {
      "x": -15,
      "y": 55,
      "z": -6,
      "name": "Rock_Volcanic"
    },
    {
      "x": -15,
      "y": 56,
      "z": -6,
      "name": "Soil_Volcanic_Gravel"
    },
    {
      "x": -15,
      "y": 57,
      "z": -6,
      "name": "Soil_Volcanic_Gravel"
    },
    {
      "x": -15,
      "y": 17,
      "z": -5,
      "name": "Rock_Volcanic"
    },
    {
      "x": -15,
      "y": 18,
      "z": -5,
      "name": "Rock_Volcanic"
    },
    {
      "x": -15,
      "y": 19,
      "z": -5,
      "name": "Rock_Volcanic"
    },
    {
      "x": -15,
      "y": 20,
      "z": -5,
      "name": "Rock_Volcanic"
    },
    {
      "x": -15,
      "y": 21,
      "z": -5,
      "name": "Rock_Volcanic"
    },
    {
      "x": -15,
      "y": 22,
      "z": -5,
      "name": "Rock_Volcanic"
    },
    {
      "x": -15,
      "y": 23,
      "z": -5,
      "name": "Rock_Volcanic"
    },
    {
      "x": -15,
      "y": 24,
      "z": -5,
      "name": "Rock_Volcanic"
    },
    {
      "x": -15,
      "y": 25,
      "z": -5,
      "name": "Soil_Volcanic_Gravel"
    },
    {
      "x": -15,
      "y": 26,
      "z": -5,
      "name": "Rock_Volcanic"
    },
    {
      "x": -15,
      "y": 27,
      "z": -5,
      "name": "Rock_Volcanic"
    },
    {
      "x": -15,
      "y": 28,
      "z": -5,
      "name": "Rock_Volcanic"
    },
    {
      "x": -15,
      "y": 35,
      "z": -5,
      "name": "Rock_Volcanic"
    },
    {
      "x": -15,
      "y": 36,
      "z": -5,
      "name": "Soil_Volcanic_Gravel"
    },
    {
      "x": -15,
      "y": 37,
      "z": -5,
      "name": "Soil_Volcanic_Gravel"
    },
    {
      "x": -15,
      "y": 38,
      "z": -5,
      "name": "Rock_Volcanic"
    },
    {
      "x": -15,
      "y": 39,
      "z": -5,
      "name": "Rock_Volcanic"
    },
    {
      "x": -15,
      "y": 40,
      "z": -5,
      "name": "Rock_Volcanic"
    },
    {
      "x": -15,
      "y": 41,
      "z": -5,
      "name": "Rock_Volcanic"
    },
    {
      "x": -15,
      "y": 42,
      "z": -5,
      "name": "Rock_Volcanic"
    },
    {
      "x": -15,
      "y": 43,
      "z": -5,
      "name": "Rock_Volcanic"
    },
    {
      "x": -15,
      "y": 44,
      "z": -5,
      "name": "Rock_Volcanic"
    },
    {
      "x": -15,
      "y": 45,
      "z": -5,
      "name": "Rock_Volcanic"
    },
    {
      "x": -15,
      "y": 46,
      "z": -5,
      "name": "Rock_Volcanic"
    },
    {
      "x": -15,
      "y": 47,
      "z": -5,
      "name": "Rock_Volcanic"
    },
    {
      "x": -15,
      "y": 48,
      "z": -5,
      "name": "Rock_Volcanic"
    },
    {
      "x": -15,
      "y": 49,
      "z": -5,
      "name": "Rock_Volcanic"
    },
    {
      "x": -15,
      "y": 50,
      "z": -5,
      "name": "Rock_Volcanic"
    },
    {
      "x": -15,
      "y": 51,
      "z": -5,
      "name": "Rock_Volcanic"
    },
    {
      "x": -15,
      "y": 52,
      "z": -5,
      "name": "Rock_Volcanic"
    },
    {
      "x": -15,
      "y": 53,
      "z": -5,
      "name": "Rock_Volcanic"
    },
    {
      "x": -15,
      "y": 54,
      "z": -5,
      "name": "Rock_Volcanic"
    },
    {
      "x": -15,
      "y": 55,
      "z": -5,
      "name": "Soil_Volcanic_Gravel"
    },
    {
      "x": -15,
      "y": 56,
      "z": -5,
      "name": "Soil_Volcanic_Gravel"
    },
    {
      "x": -15,
      "y": 57,
      "z": -5,
      "name": "Rock_Volcanic"
    },
    {
      "x": -15,
      "y": 16,
      "z": -4,
      "name": "Rock_Volcanic"
    },
    {
      "x": -15,
      "y": 17,
      "z": -4,
      "name": "Rock_Volcanic"
    },
    {
      "x": -15,
      "y": 18,
      "z": -4,
      "name": "Rock_Volcanic"
    },
    {
      "x": -15,
      "y": 19,
      "z": -4,
      "name": "Rock_Volcanic"
    },
    {
      "x": -15,
      "y": 20,
      "z": -4,
      "name": "Rock_Volcanic"
    },
    {
      "x": -15,
      "y": 21,
      "z": -4,
      "name": "Rock_Volcanic"
    },
    {
      "x": -15,
      "y": 22,
      "z": -4,
      "name": "Rock_Volcanic"
    },
    {
      "x": -15,
      "y": 23,
      "z": -4,
      "name": "Soil_Volcanic_Gravel"
    },
    {
      "x": -15,
      "y": 24,
      "z": -4,
      "name": "Soil_Volcanic_Gravel"
    },
    {
      "x": -15,
      "y": 25,
      "z": -4,
      "name": "Rock_Volcanic"
    },
    {
      "x": -15,
      "y": 26,
      "z": -4,
      "name": "Rock_Volcanic"
    },
    {
      "x": -15,
      "y": 27,
      "z": -4,
      "name": "Rock_Volcanic"
    },
    {
      "x": -15,
      "y": 28,
      "z": -4,
      "name": "Rock_Volcanic"
    },
    {
      "x": -15,
      "y": 29,
      "z": -4,
      "name": "Rock_Volcanic"
    },
    {
      "x": -15,
      "y": 30,
      "z": -4,
      "name": "Rock_Volcanic"
    },
    {
      "x": -15,
      "y": 31,
      "z": -4,
      "name": "Rock_Volcanic"
    },
    {
      "x": -15,
      "y": 32,
      "z": -4,
      "name": "Rock_Volcanic"
    },
    {
      "x": -15,
      "y": 33,
      "z": -4,
      "name": "Rock_Volcanic"
    },
    {
      "x": -15,
      "y": 34,
      "z": -4,
      "name": "Rock_Volcanic"
    },
    {
      "x": -15,
      "y": 35,
      "z": -4,
      "name": "Rock_Volcanic"
    },
    {
      "x": -15,
      "y": 36,
      "z": -4,
      "name": "Rock_Volcanic"
    },
    {
      "x": -15,
      "y": 37,
      "z": -4,
      "name": "Soil_Volcanic_Gravel"
    },
    {
      "x": -15,
      "y": 38,
      "z": -4,
      "name": "Rock_Volcanic"
    },
    {
      "x": -15,
      "y": 39,
      "z": -4,
      "name": "Rock_Volcanic"
    },
    {
      "x": -15,
      "y": 40,
      "z": -4,
      "name": "Rock_Volcanic"
    },
    {
      "x": -15,
      "y": 41,
      "z": -4,
      "name": "Rock_Volcanic"
    },
    {
      "x": -15,
      "y": 42,
      "z": -4,
      "name": "Rock_Volcanic"
    },
    {
      "x": -15,
      "y": 43,
      "z": -4,
      "name": "Rock_Volcanic"
    },
    {
      "x": -15,
      "y": 44,
      "z": -4,
      "name": "Rock_Volcanic"
    },
    {
      "x": -15,
      "y": 45,
      "z": -4,
      "name": "Rock_Volcanic"
    },
    {
      "x": -15,
      "y": 46,
      "z": -4,
      "name": "Rock_Volcanic"
    },
    {
      "x": -15,
      "y": 47,
      "z": -4,
      "name": "Rock_Volcanic"
    },
    {
      "x": -15,
      "y": 48,
      "z": -4,
      "name": "Rock_Volcanic"
    },
    {
      "x": -15,
      "y": 49,
      "z": -4,
      "name": "Rock_Volcanic"
    },
    {
      "x": -15,
      "y": 50,
      "z": -4,
      "name": "Rock_Volcanic"
    },
    {
      "x": -15,
      "y": 51,
      "z": -4,
      "name": "Rock_Volcanic"
    },
    {
      "x": -15,
      "y": 52,
      "z": -4,
      "name": "Rock_Volcanic"
    },
    {
      "x": -15,
      "y": 53,
      "z": -4,
      "name": "Rock_Volcanic"
    },
    {
      "x": -15,
      "y": 54,
      "z": -4,
      "name": "Soil_Volcanic_Gravel"
    },
    {
      "x": -15,
      "y": 55,
      "z": -4,
      "name": "Rock_Volcanic"
    },
    {
      "x": -15,
      "y": 56,
      "z": -4,
      "name": "Soil_Volcanic_Gravel"
    },
    {
      "x": -15,
      "y": 57,
      "z": -4,
      "name": "Rock_Volcanic"
    },
    {
      "x": -15,
      "y": 16,
      "z": -3,
      "name": "Rock_Volcanic"
    },
    {
      "x": -15,
      "y": 17,
      "z": -3,
      "name": "Rock_Volcanic"
    },
    {
      "x": -15,
      "y": 18,
      "z": -3,
      "name": "Rock_Volcanic"
    },
    {
      "x": -15,
      "y": 19,
      "z": -3,
      "name": "Rock_Volcanic"
    },
    {
      "x": -15,
      "y": 20,
      "z": -3,
      "name": "Rock_Volcanic"
    },
    {
      "x": -15,
      "y": 21,
      "z": -3,
      "name": "Rock_Volcanic"
    },
    {
      "x": -15,
      "y": 22,
      "z": -3,
      "name": "Soil_Volcanic_Gravel"
    },
    {
      "x": -15,
      "y": 23,
      "z": -3,
      "name": "Rock_Volcanic"
    },
    {
      "x": -15,
      "y": 24,
      "z": -3,
      "name": "Rock_Volcanic"
    },
    {
      "x": -15,
      "y": 25,
      "z": -3,
      "name": "Soil_Volcanic_Gravel"
    },
    {
      "x": -15,
      "y": 26,
      "z": -3,
      "name": "Soil_Volcanic_Gravel"
    },
    {
      "x": -15,
      "y": 27,
      "z": -3,
      "name": "Soil_Volcanic_Gravel"
    },
    {
      "x": -15,
      "y": 28,
      "z": -3,
      "name": "Rock_Volcanic"
    },
    {
      "x": -15,
      "y": 29,
      "z": -3,
      "name": "Rock_Volcanic"
    },
    {
      "x": -15,
      "y": 30,
      "z": -3,
      "name": "Rock_Volcanic"
    },
    {
      "x": -15,
      "y": 31,
      "z": -3,
      "name": "Rock_Volcanic"
    },
    {
      "x": -15,
      "y": 32,
      "z": -3,
      "name": "Rock_Volcanic"
    },
    {
      "x": -15,
      "y": 33,
      "z": -3,
      "name": "Rock_Volcanic"
    },
    {
      "x": -15,
      "y": 34,
      "z": -3,
      "name": "Rock_Volcanic"
    },
    {
      "x": -15,
      "y": 35,
      "z": -3,
      "name": "Rock_Volcanic"
    },
    {
      "x": -15,
      "y": 36,
      "z": -3,
      "name": "Rock_Volcanic"
    },
    {
      "x": -15,
      "y": 37,
      "z": -3,
      "name": "Rock_Volcanic"
    },
    {
      "x": -15,
      "y": 38,
      "z": -3,
      "name": "Rock_Volcanic"
    },
    {
      "x": -15,
      "y": 39,
      "z": -3,
      "name": "Rock_Volcanic"
    },
    {
      "x": -15,
      "y": 40,
      "z": -3,
      "name": "Rock_Volcanic"
    },
    {
      "x": -15,
      "y": 41,
      "z": -3,
      "name": "Rock_Volcanic"
    },
    {
      "x": -15,
      "y": 42,
      "z": -3,
      "name": "Rock_Volcanic"
    },
    {
      "x": -15,
      "y": 43,
      "z": -3,
      "name": "Rock_Volcanic"
    },
    {
      "x": -15,
      "y": 44,
      "z": -3,
      "name": "Rock_Volcanic"
    },
    {
      "x": -15,
      "y": 45,
      "z": -3,
      "name": "Rock_Volcanic"
    },
    {
      "x": -15,
      "y": 46,
      "z": -3,
      "name": "Rock_Volcanic"
    },
    {
      "x": -15,
      "y": 47,
      "z": -3,
      "name": "Rock_Volcanic"
    },
    {
      "x": -15,
      "y": 48,
      "z": -3,
      "name": "Rock_Volcanic"
    },
    {
      "x": -15,
      "y": 49,
      "z": -3,
      "name": "Rock_Volcanic"
    },
    {
      "x": -15,
      "y": 50,
      "z": -3,
      "name": "Rock_Volcanic"
    },
    {
      "x": -15,
      "y": 51,
      "z": -3,
      "name": "Rock_Volcanic"
    },
    {
      "x": -15,
      "y": 52,
      "z": -3,
      "name": "Rock_Volcanic"
    },
    {
      "x": -15,
      "y": 53,
      "z": -3,
      "name": "Rock_Volcanic"
    },
    {
      "x": -15,
      "y": 54,
      "z": -3,
      "name": "Soil_Volcanic_Gravel"
    },
    {
      "x": -15,
      "y": 55,
      "z": -3,
      "name": "Rock_Volcanic"
    },
    {
      "x": -15,
      "y": 56,
      "z": -3,
      "name": "Soil_Volcanic_Gravel"
    },
    {
      "x": -15,
      "y": 16,
      "z": -2,
      "name": "Rock_Volcanic"
    },
    {
      "x": -15,
      "y": 17,
      "z": -2,
      "name": "Rock_Volcanic"
    },
    {
      "x": -15,
      "y": 18,
      "z": -2,
      "name": "Rock_Volcanic"
    },
    {
      "x": -15,
      "y": 19,
      "z": -2,
      "name": "Rock_Volcanic"
    },
    {
      "x": -15,
      "y": 20,
      "z": -2,
      "name": "Rock_Volcanic"
    },
    {
      "x": -15,
      "y": 21,
      "z": -2,
      "name": "Rock_Volcanic"
    },
    {
      "x": -15,
      "y": 22,
      "z": -2,
      "name": "Rock_Volcanic"
    },
    {
      "x": -15,
      "y": 23,
      "z": -2,
      "name": "Rock_Volcanic"
    },
    {
      "x": -15,
      "y": 24,
      "z": -2,
      "name": "Soil_Volcanic_Gravel"
    },
    {
      "x": -15,
      "y": 25,
      "z": -2,
      "name": "Soil_Volcanic_Gravel"
    },
    {
      "x": -15,
      "y": 26,
      "z": -2,
      "name": "Soil_Volcanic_Gravel"
    },
    {
      "x": -15,
      "y": 27,
      "z": -2,
      "name": "Rock_Volcanic"
    },
    {
      "x": -15,
      "y": 30,
      "z": -2,
      "name": "Rock_Volcanic"
    },
    {
      "x": -15,
      "y": 31,
      "z": -2,
      "name": "Rock_Volcanic"
    },
    {
      "x": -15,
      "y": 32,
      "z": -2,
      "name": "Rock_Volcanic"
    },
    {
      "x": -15,
      "y": 33,
      "z": -2,
      "name": "Rock_Volcanic"
    },
    {
      "x": -15,
      "y": 34,
      "z": -2,
      "name": "Rock_Volcanic"
    },
    {
      "x": -15,
      "y": 35,
      "z": -2,
      "name": "Rock_Volcanic"
    },
    {
      "x": -15,
      "y": 36,
      "z": -2,
      "name": "Rock_Volcanic"
    },
    {
      "x": -15,
      "y": 37,
      "z": -2,
      "name": "Rock_Volcanic"
    },
    {
      "x": -15,
      "y": 38,
      "z": -2,
      "name": "Rock_Volcanic"
    },
    {
      "x": -15,
      "y": 39,
      "z": -2,
      "name": "Rock_Volcanic"
    },
    {
      "x": -15,
      "y": 40,
      "z": -2,
      "name": "Rock_Volcanic"
    },
    {
      "x": -15,
      "y": 41,
      "z": -2,
      "name": "Soil_Volcanic_Gravel"
    },
    {
      "x": -15,
      "y": 42,
      "z": -2,
      "name": "Soil_Volcanic_Gravel"
    },
    {
      "x": -15,
      "y": 43,
      "z": -2,
      "name": "Rock_Volcanic"
    },
    {
      "x": -15,
      "y": 44,
      "z": -2,
      "name": "Rock_Volcanic"
    },
    {
      "x": -15,
      "y": 45,
      "z": -2,
      "name": "Rock_Volcanic"
    },
    {
      "x": -15,
      "y": 46,
      "z": -2,
      "name": "Rock_Volcanic"
    },
    {
      "x": -15,
      "y": 47,
      "z": -2,
      "name": "Rock_Volcanic"
    },
    {
      "x": -15,
      "y": 48,
      "z": -2,
      "name": "Rock_Volcanic"
    },
    {
      "x": -15,
      "y": 49,
      "z": -2,
      "name": "Rock_Volcanic"
    },
    {
      "x": -15,
      "y": 50,
      "z": -2,
      "name": "Rock_Volcanic"
    },
    {
      "x": -15,
      "y": 51,
      "z": -2,
      "name": "Rock_Volcanic"
    },
    {
      "x": -15,
      "y": 52,
      "z": -2,
      "name": "Rock_Volcanic"
    },
    {
      "x": -15,
      "y": 53,
      "z": -2,
      "name": "Rock_Volcanic"
    },
    {
      "x": -15,
      "y": 54,
      "z": -2,
      "name": "Soil_Volcanic_Gravel"
    },
    {
      "x": -15,
      "y": 55,
      "z": -2,
      "name": "Soil_Volcanic_Gravel"
    },
    {
      "x": -15,
      "y": 56,
      "z": -2,
      "name": "Soil_Volcanic_Gravel"
    },
    {
      "x": -15,
      "y": 16,
      "z": -1,
      "name": "Rock_Volcanic"
    },
    {
      "x": -15,
      "y": 17,
      "z": -1,
      "name": "Rock_Volcanic"
    },
    {
      "x": -15,
      "y": 18,
      "z": -1,
      "name": "Rock_Volcanic"
    },
    {
      "x": -15,
      "y": 19,
      "z": -1,
      "name": "Rock_Volcanic"
    },
    {
      "x": -15,
      "y": 20,
      "z": -1,
      "name": "Rock_Volcanic"
    },
    {
      "x": -15,
      "y": 21,
      "z": -1,
      "name": "Rock_Volcanic"
    },
    {
      "x": -15,
      "y": 22,
      "z": -1,
      "name": "Rock_Volcanic"
    },
    {
      "x": -15,
      "y": 23,
      "z": -1,
      "name": "Soil_Volcanic_Gravel"
    },
    {
      "x": -15,
      "y": 24,
      "z": -1,
      "name": "Soil_Volcanic_Gravel"
    },
    {
      "x": -15,
      "y": 25,
      "z": -1,
      "name": "Soil_Volcanic_Gravel"
    },
    {
      "x": -15,
      "y": 38,
      "z": -1,
      "name": "Rock_Volcanic"
    },
    {
      "x": -15,
      "y": 39,
      "z": -1,
      "name": "Rock_Volcanic"
    },
    {
      "x": -15,
      "y": 40,
      "z": -1,
      "name": "Rock_Volcanic"
    },
    {
      "x": -15,
      "y": 46,
      "z": -1,
      "name": "Rock_Volcanic"
    },
    {
      "x": -15,
      "y": 47,
      "z": -1,
      "name": "Rock_Volcanic"
    },
    {
      "x": -15,
      "y": 48,
      "z": -1,
      "name": "Rock_Volcanic"
    },
    {
      "x": -15,
      "y": 49,
      "z": -1,
      "name": "Rock_Volcanic"
    },
    {
      "x": -15,
      "y": 50,
      "z": -1,
      "name": "Rock_Volcanic"
    },
    {
      "x": -15,
      "y": 51,
      "z": -1,
      "name": "Rock_Volcanic"
    },
    {
      "x": -15,
      "y": 52,
      "z": -1,
      "name": "Rock_Volcanic"
    },
    {
      "x": -15,
      "y": 53,
      "z": -1,
      "name": "Rock_Volcanic"
    },
    {
      "x": -15,
      "y": 54,
      "z": -1,
      "name": "Rock_Volcanic"
    },
    {
      "x": -15,
      "y": 55,
      "z": -1,
      "name": "Soil_Volcanic_Gravel"
    },
    {
      "x": -15,
      "y": 15,
      "z": 0,
      "name": "Rock_Volcanic"
    },
    {
      "x": -15,
      "y": 16,
      "z": 0,
      "name": "Rock_Volcanic"
    },
    {
      "x": -15,
      "y": 17,
      "z": 0,
      "name": "Rock_Volcanic"
    },
    {
      "x": -15,
      "y": 18,
      "z": 0,
      "name": "Rock_Volcanic"
    },
    {
      "x": -15,
      "y": 19,
      "z": 0,
      "name": "Rock_Volcanic"
    },
    {
      "x": -15,
      "y": 20,
      "z": 0,
      "name": "Rock_Volcanic"
    },
    {
      "x": -15,
      "y": 21,
      "z": 0,
      "name": "Rock_Volcanic"
    },
    {
      "x": -15,
      "y": 22,
      "z": 0,
      "name": "Soil_Volcanic_Gravel"
    },
    {
      "x": -15,
      "y": 23,
      "z": 0,
      "name": "Soil_Volcanic_Gravel"
    },
    {
      "x": -15,
      "y": 24,
      "z": 0,
      "name": "Soil_Volcanic_Gravel"
    },
    {
      "x": -15,
      "y": 47,
      "z": 0,
      "name": "Rock_Volcanic"
    },
    {
      "x": -15,
      "y": 48,
      "z": 0,
      "name": "Rock_Volcanic"
    },
    {
      "x": -15,
      "y": 49,
      "z": 0,
      "name": "Rock_Volcanic"
    },
    {
      "x": -15,
      "y": 50,
      "z": 0,
      "name": "Rock_Volcanic"
    },
    {
      "x": -15,
      "y": 51,
      "z": 0,
      "name": "Rock_Volcanic"
    },
    {
      "x": -15,
      "y": 52,
      "z": 0,
      "name": "Rock_Volcanic"
    },
    {
      "x": -15,
      "y": 53,
      "z": 0,
      "name": "Rock_Volcanic"
    },
    {
      "x": -15,
      "y": 54,
      "z": 0,
      "name": "Rock_Volcanic"
    },
    {
      "x": -15,
      "y": 15,
      "z": 1,
      "name": "Rock_Volcanic"
    },
    {
      "x": -15,
      "y": 16,
      "z": 1,
      "name": "Rock_Volcanic"
    },
    {
      "x": -15,
      "y": 17,
      "z": 1,
      "name": "Rock_Volcanic"
    },
    {
      "x": -15,
      "y": 18,
      "z": 1,
      "name": "Rock_Volcanic"
    },
    {
      "x": -15,
      "y": 19,
      "z": 1,
      "name": "Rock_Volcanic"
    },
    {
      "x": -15,
      "y": 20,
      "z": 1,
      "name": "Rock_Volcanic"
    },
    {
      "x": -15,
      "y": 21,
      "z": 1,
      "name": "Rock_Volcanic"
    },
    {
      "x": -15,
      "y": 22,
      "z": 1,
      "name": "Rock_Volcanic"
    },
    {
      "x": -15,
      "y": 23,
      "z": 1,
      "name": "Rock_Volcanic"
    },
    {
      "x": -15,
      "y": 24,
      "z": 1,
      "name": "Rock_Volcanic"
    },
    {
      "x": -15,
      "y": 48,
      "z": 1,
      "name": "Rock_Volcanic"
    },
    {
      "x": -15,
      "y": 49,
      "z": 1,
      "name": "Rock_Volcanic"
    },
    {
      "x": -15,
      "y": 50,
      "z": 1,
      "name": "Rock_Volcanic"
    },
    {
      "x": -15,
      "y": 51,
      "z": 1,
      "name": "Rock_Volcanic"
    },
    {
      "x": -15,
      "y": 52,
      "z": 1,
      "name": "Rock_Volcanic"
    },
    {
      "x": -15,
      "y": 53,
      "z": 1,
      "name": "Rock_Volcanic"
    },
    {
      "x": -15,
      "y": 54,
      "z": 1,
      "name": "Rock_Volcanic"
    },
    {
      "x": -15,
      "y": 14,
      "z": 2,
      "name": "Rock_Volcanic"
    },
    {
      "x": -15,
      "y": 15,
      "z": 2,
      "name": "Rock_Volcanic"
    },
    {
      "x": -15,
      "y": 16,
      "z": 2,
      "name": "Rock_Volcanic"
    },
    {
      "x": -15,
      "y": 17,
      "z": 2,
      "name": "Rock_Volcanic"
    },
    {
      "x": -15,
      "y": 18,
      "z": 2,
      "name": "Rock_Volcanic"
    },
    {
      "x": -15,
      "y": 19,
      "z": 2,
      "name": "Rock_Volcanic"
    },
    {
      "x": -15,
      "y": 20,
      "z": 2,
      "name": "Rock_Volcanic"
    },
    {
      "x": -15,
      "y": 21,
      "z": 2,
      "name": "Rock_Volcanic"
    },
    {
      "x": -15,
      "y": 22,
      "z": 2,
      "name": "Rock_Volcanic"
    },
    {
      "x": -15,
      "y": 23,
      "z": 2,
      "name": "Soil_Volcanic_Gravel"
    },
    {
      "x": -15,
      "y": 24,
      "z": 2,
      "name": "Soil_Volcanic_Gravel"
    },
    {
      "x": -15,
      "y": 49,
      "z": 2,
      "name": "Rock_Volcanic"
    },
    {
      "x": -15,
      "y": 50,
      "z": 2,
      "name": "Rock_Volcanic"
    },
    {
      "x": -15,
      "y": 51,
      "z": 2,
      "name": "Rock_Volcanic"
    },
    {
      "x": -15,
      "y": 52,
      "z": 2,
      "name": "Rock_Volcanic"
    },
    {
      "x": -15,
      "y": 53,
      "z": 2,
      "name": "Rock_Volcanic"
    },
    {
      "x": -15,
      "y": 13,
      "z": 3,
      "name": "Rock_Volcanic"
    },
    {
      "x": -15,
      "y": 14,
      "z": 3,
      "name": "Rock_Volcanic"
    },
    {
      "x": -15,
      "y": 15,
      "z": 3,
      "name": "Rock_Volcanic"
    },
    {
      "x": -15,
      "y": 16,
      "z": 3,
      "name": "Rock_Volcanic"
    },
    {
      "x": -15,
      "y": 17,
      "z": 3,
      "name": "Rock_Volcanic"
    },
    {
      "x": -15,
      "y": 18,
      "z": 3,
      "name": "Rock_Volcanic"
    },
    {
      "x": -15,
      "y": 19,
      "z": 3,
      "name": "Rock_Volcanic"
    },
    {
      "x": -15,
      "y": 20,
      "z": 3,
      "name": "Rock_Volcanic"
    },
    {
      "x": -15,
      "y": 21,
      "z": 3,
      "name": "Rock_Volcanic"
    },
    {
      "x": -15,
      "y": 22,
      "z": 3,
      "name": "Rock_Volcanic"
    },
    {
      "x": -15,
      "y": 23,
      "z": 3,
      "name": "Rock_Volcanic"
    },
    {
      "x": -15,
      "y": 12,
      "z": 4,
      "name": "Rock_Volcanic"
    },
    {
      "x": -15,
      "y": 13,
      "z": 4,
      "name": "Rock_Volcanic"
    },
    {
      "x": -15,
      "y": 14,
      "z": 4,
      "name": "Rock_Volcanic"
    },
    {
      "x": -15,
      "y": 15,
      "z": 4,
      "name": "Rock_Volcanic"
    },
    {
      "x": -15,
      "y": 16,
      "z": 4,
      "name": "Rock_Volcanic"
    },
    {
      "x": -15,
      "y": 17,
      "z": 4,
      "name": "Rock_Volcanic"
    },
    {
      "x": -15,
      "y": 18,
      "z": 4,
      "name": "Rock_Volcanic"
    },
    {
      "x": -15,
      "y": 19,
      "z": 4,
      "name": "Rock_Volcanic"
    },
    {
      "x": -15,
      "y": 20,
      "z": 4,
      "name": "Rock_Volcanic"
    },
    {
      "x": -15,
      "y": 21,
      "z": 4,
      "name": "Soil_Volcanic_Gravel"
    },
    {
      "x": -15,
      "y": 22,
      "z": 4,
      "name": "Soil_Volcanic_Gravel"
    },
    {
      "x": -15,
      "y": 23,
      "z": 4,
      "name": "Soil_Volcanic_Gravel"
    },
    {
      "x": -15,
      "y": 7,
      "z": 5,
      "name": "Rock_Volcanic"
    },
    {
      "x": -15,
      "y": 8,
      "z": 5,
      "name": "Rock_Volcanic"
    },
    {
      "x": -15,
      "y": 9,
      "z": 5,
      "name": "Rock_Volcanic"
    },
    {
      "x": -15,
      "y": 10,
      "z": 5,
      "name": "Rock_Volcanic"
    },
    {
      "x": -15,
      "y": 11,
      "z": 5,
      "name": "Rock_Volcanic"
    },
    {
      "x": -15,
      "y": 12,
      "z": 5,
      "name": "Rock_Volcanic"
    },
    {
      "x": -15,
      "y": 13,
      "z": 5,
      "name": "Rock_Volcanic"
    },
    {
      "x": -15,
      "y": 14,
      "z": 5,
      "name": "Rock_Volcanic"
    },
    {
      "x": -15,
      "y": 15,
      "z": 5,
      "name": "Rock_Volcanic"
    },
    {
      "x": -15,
      "y": 16,
      "z": 5,
      "name": "Rock_Volcanic"
    },
    {
      "x": -15,
      "y": 17,
      "z": 5,
      "name": "Rock_Volcanic"
    },
    {
      "x": -15,
      "y": 18,
      "z": 5,
      "name": "Rock_Volcanic"
    },
    {
      "x": -15,
      "y": 19,
      "z": 5,
      "name": "Rock_Volcanic"
    },
    {
      "x": -15,
      "y": 20,
      "z": 5,
      "name": "Rock_Volcanic"
    },
    {
      "x": -15,
      "y": 21,
      "z": 5,
      "name": "Soil_Volcanic_Gravel"
    },
    {
      "x": -15,
      "y": 7,
      "z": 6,
      "name": "Rock_Volcanic"
    },
    {
      "x": -15,
      "y": 8,
      "z": 6,
      "name": "Rock_Volcanic"
    },
    {
      "x": -15,
      "y": 9,
      "z": 6,
      "name": "Rock_Volcanic"
    },
    {
      "x": -15,
      "y": 10,
      "z": 6,
      "name": "Rock_Volcanic"
    },
    {
      "x": -15,
      "y": 11,
      "z": 6,
      "name": "Rock_Volcanic"
    },
    {
      "x": -15,
      "y": 12,
      "z": 6,
      "name": "Rock_Volcanic"
    },
    {
      "x": -15,
      "y": 13,
      "z": 6,
      "name": "Rock_Volcanic"
    },
    {
      "x": -15,
      "y": 14,
      "z": 6,
      "name": "Rock_Volcanic"
    },
    {
      "x": -15,
      "y": 15,
      "z": 6,
      "name": "Rock_Volcanic"
    },
    {
      "x": -15,
      "y": 16,
      "z": 6,
      "name": "Rock_Volcanic"
    },
    {
      "x": -15,
      "y": 17,
      "z": 6,
      "name": "Rock_Volcanic"
    },
    {
      "x": -15,
      "y": 18,
      "z": 6,
      "name": "Rock_Volcanic"
    },
    {
      "x": -15,
      "y": 19,
      "z": 6,
      "name": "Rock_Volcanic"
    },
    {
      "x": -15,
      "y": 20,
      "z": 6,
      "name": "Soil_Volcanic_Gravel"
    },
    {
      "x": -15,
      "y": 14,
      "z": 7,
      "name": "Rock_Volcanic"
    },
    {
      "x": -15,
      "y": 15,
      "z": 7,
      "name": "Rock_Volcanic"
    },
    {
      "x": -15,
      "y": 16,
      "z": 7,
      "name": "Rock_Volcanic"
    },
    {
      "x": -15,
      "y": 17,
      "z": 7,
      "name": "Rock_Volcanic"
    },
    {
      "x": -15,
      "y": 18,
      "z": 7,
      "name": "Rock_Volcanic"
    },
    {
      "x": -15,
      "y": 19,
      "z": 7,
      "name": "Rock_Volcanic"
    },
    {
      "x": -15,
      "y": 15,
      "z": 8,
      "name": "Rock_Volcanic"
    },
    {
      "x": -15,
      "y": 16,
      "z": 8,
      "name": "Rock_Volcanic"
    },
    {
      "x": -15,
      "y": 17,
      "z": 8,
      "name": "Rock_Volcanic"
    },
    {
      "x": -15,
      "y": 18,
      "z": 8,
      "name": "Rock_Volcanic"
    },
    {
      "x": -15,
      "y": 16,
      "z": 9,
      "name": "Rock_Volcanic"
    },
    {
      "x": -15,
      "y": 17,
      "z": 9,
      "name": "Rock_Volcanic"
    },
    {
      "x": -14,
      "y": 39,
      "z": -11,
      "name": "Rock_Volcanic"
    },
    {
      "x": -14,
      "y": 40,
      "z": -11,
      "name": "Rock_Volcanic"
    },
    {
      "x": -14,
      "y": 41,
      "z": -11,
      "name": "Rock_Volcanic"
    },
    {
      "x": -14,
      "y": 38,
      "z": -10,
      "name": "Rock_Volcanic"
    },
    {
      "x": -14,
      "y": 39,
      "z": -10,
      "name": "Rock_Volcanic"
    },
    {
      "x": -14,
      "y": 40,
      "z": -10,
      "name": "Rock_Volcanic"
    },
    {
      "x": -14,
      "y": 41,
      "z": -10,
      "name": "Rock_Volcanic"
    },
    {
      "x": -14,
      "y": 42,
      "z": -10,
      "name": "Rock_Volcanic"
    },
    {
      "x": -14,
      "y": 38,
      "z": -9,
      "name": "Rock_Volcanic"
    },
    {
      "x": -14,
      "y": 39,
      "z": -9,
      "name": "Rock_Volcanic"
    },
    {
      "x": -14,
      "y": 40,
      "z": -9,
      "name": "Rock_Volcanic"
    },
    {
      "x": -14,
      "y": 41,
      "z": -9,
      "name": "Rock_Volcanic"
    },
    {
      "x": -14,
      "y": 42,
      "z": -9,
      "name": "Soil_Volcanic_Gravel"
    },
    {
      "x": -14,
      "y": 54,
      "z": -9,
      "name": "Rock_Volcanic"
    },
    {
      "x": -14,
      "y": 55,
      "z": -9,
      "name": "Rock_Volcanic"
    },
    {
      "x": -14,
      "y": 56,
      "z": -9,
      "name": "Rock_Volcanic"
    },
    {
      "x": -14,
      "y": 23,
      "z": -8,
      "name": "Rock_Volcanic"
    },
    {
      "x": -14,
      "y": 24,
      "z": -8,
      "name": "Rock_Volcanic"
    },
    {
      "x": -14,
      "y": 25,
      "z": -8,
      "name": "Rock_Volcanic"
    },
    {
      "x": -14,
      "y": 37,
      "z": -8,
      "name": "Rock_Volcanic"
    },
    {
      "x": -14,
      "y": 38,
      "z": -8,
      "name": "Rock_Volcanic"
    },
    {
      "x": -14,
      "y": 39,
      "z": -8,
      "name": "Rock_Volcanic"
    },
    {
      "x": -14,
      "y": 40,
      "z": -8,
      "name": "Rock_Volcanic"
    },
    {
      "x": -14,
      "y": 41,
      "z": -8,
      "name": "Soil_Volcanic_Gravel"
    },
    {
      "x": -14,
      "y": 42,
      "z": -8,
      "name": "Soil_Volcanic_Gravel"
    },
    {
      "x": -14,
      "y": 43,
      "z": -8,
      "name": "Soil_Volcanic_Gravel"
    },
    {
      "x": -14,
      "y": 53,
      "z": -8,
      "name": "Rock_Volcanic"
    },
    {
      "x": -14,
      "y": 54,
      "z": -8,
      "name": "Rock_Volcanic"
    },
    {
      "x": -14,
      "y": 55,
      "z": -8,
      "name": "Rock_Volcanic"
    },
    {
      "x": -14,
      "y": 56,
      "z": -8,
      "name": "Soil_Volcanic_Gravel"
    },
    {
      "x": -14,
      "y": 57,
      "z": -8,
      "name": "Rock_Volcanic"
    },
    {
      "x": -14,
      "y": 21,
      "z": -7,
      "name": "Rock_Volcanic"
    },
    {
      "x": -14,
      "y": 22,
      "z": -7,
      "name": "Rock_Volcanic"
    },
    {
      "x": -14,
      "y": 23,
      "z": -7,
      "name": "Rock_Volcanic"
    },
    {
      "x": -14,
      "y": 24,
      "z": -7,
      "name": "Rock_Volcanic"
    },
    {
      "x": -14,
      "y": 25,
      "z": -7,
      "name": "Rock_Volcanic"
    },
    {
      "x": -14,
      "y": 26,
      "z": -7,
      "name": "Rock_Volcanic"
    },
    {
      "x": -14,
      "y": 27,
      "z": -7,
      "name": "Rock_Volcanic"
    },
    {
      "x": -14,
      "y": 36,
      "z": -7,
      "name": "Rock_Volcanic"
    },
    {
      "x": -14,
      "y": 37,
      "z": -7,
      "name": "Rock_Volcanic"
    },
    {
      "x": -14,
      "y": 38,
      "z": -7,
      "name": "Rock_Volcanic"
    },
    {
      "x": -14,
      "y": 39,
      "z": -7,
      "name": "Rock_Volcanic"
    },
    {
      "x": -14,
      "y": 40,
      "z": -7,
      "name": "Rock_Volcanic"
    },
    {
      "x": -14,
      "y": 41,
      "z": -7,
      "name": "Rock_Volcanic"
    },
    {
      "x": -14,
      "y": 42,
      "z": -7,
      "name": "Rock_Volcanic"
    },
    {
      "x": -14,
      "y": 43,
      "z": -7,
      "name": "Soil_Volcanic_Gravel"
    },
    {
      "x": -14,
      "y": 44,
      "z": -7,
      "name": "Soil_Volcanic_Gravel"
    },
    {
      "x": -14,
      "y": 45,
      "z": -7,
      "name": "Rock_Volcanic"
    },
    {
      "x": -14,
      "y": 52,
      "z": -7,
      "name": "Rock_Volcanic"
    },
    {
      "x": -14,
      "y": 53,
      "z": -7,
      "name": "Rock_Volcanic"
    },
    {
      "x": -14,
      "y": 54,
      "z": -7,
      "name": "Rock_Volcanic"
    },
    {
      "x": -14,
      "y": 55,
      "z": -7,
      "name": "Rock_Volcanic"
    },
    {
      "x": -14,
      "y": 56,
      "z": -7,
      "name": "Soil_Volcanic_Gravel"
    },
    {
      "x": -14,
      "y": 57,
      "z": -7,
      "name": "Rock_Volcanic"
    },
    {
      "x": -14,
      "y": 58,
      "z": -7,
      "name": "Soil_Volcanic_Gravel"
    },
    {
      "x": -14,
      "y": 19,
      "z": -6,
      "name": "Rock_Volcanic"
    },
    {
      "x": -14,
      "y": 20,
      "z": -6,
      "name": "Rock_Volcanic"
    },
    {
      "x": -14,
      "y": 21,
      "z": -6,
      "name": "Rock_Volcanic"
    },
    {
      "x": -14,
      "y": 22,
      "z": -6,
      "name": "Rock_Volcanic"
    },
    {
      "x": -14,
      "y": 23,
      "z": -6,
      "name": "Rock_Volcanic"
    },
    {
      "x": -14,
      "y": 24,
      "z": -6,
      "name": "Rock_Volcanic"
    },
    {
      "x": -14,
      "y": 25,
      "z": -6,
      "name": "Rock_Volcanic"
    },
    {
      "x": -14,
      "y": 26,
      "z": -6,
      "name": "Rock_Volcanic"
    },
    {
      "x": -14,
      "y": 27,
      "z": -6,
      "name": "Rock_Volcanic"
    },
    {
      "x": -14,
      "y": 28,
      "z": -6,
      "name": "Rock_Volcanic"
    },
    {
      "x": -14,
      "y": 35,
      "z": -6,
      "name": "Rock_Volcanic"
    },
    {
      "x": -14,
      "y": 36,
      "z": -6,
      "name": "Soil_Volcanic_Gravel"
    },
    {
      "x": -14,
      "y": 37,
      "z": -6,
      "name": "Rock_Volcanic"
    },
    {
      "x": -14,
      "y": 38,
      "z": -6,
      "name": "Rock_Volcanic"
    },
    {
      "x": -14,
      "y": 39,
      "z": -6,
      "name": "Rock_Volcanic"
    },
    {
      "x": -14,
      "y": 40,
      "z": -6,
      "name": "Rock_Volcanic"
    },
    {
      "x": -14,
      "y": 41,
      "z": -6,
      "name": "Rock_Volcanic"
    },
    {
      "x": -14,
      "y": 42,
      "z": -6,
      "name": "Rock_Volcanic"
    },
    {
      "x": -14,
      "y": 43,
      "z": -6,
      "name": "Soil_Volcanic_Gravel"
    },
    {
      "x": -14,
      "y": 44,
      "z": -6,
      "name": "Rock_Volcanic"
    },
    {
      "x": -14,
      "y": 45,
      "z": -6,
      "name": "Rock_Volcanic"
    },
    {
      "x": -14,
      "y": 46,
      "z": -6,
      "name": "Rock_Volcanic"
    },
    {
      "x": -14,
      "y": 47,
      "z": -6,
      "name": "Rock_Volcanic"
    },
    {
      "x": -14,
      "y": 48,
      "z": -6,
      "name": "Rock_Volcanic"
    },
    {
      "x": -14,
      "y": 49,
      "z": -6,
      "name": "Rock_Volcanic"
    },
    {
      "x": -14,
      "y": 50,
      "z": -6,
      "name": "Rock_Volcanic"
    },
    {
      "x": -14,
      "y": 51,
      "z": -6,
      "name": "Rock_Volcanic"
    },
    {
      "x": -14,
      "y": 52,
      "z": -6,
      "name": "Rock_Volcanic"
    },
    {
      "x": -14,
      "y": 53,
      "z": -6,
      "name": "Rock_Volcanic"
    },
    {
      "x": -14,
      "y": 54,
      "z": -6,
      "name": "Rock_Volcanic"
    },
    {
      "x": -14,
      "y": 55,
      "z": -6,
      "name": "Rock_Volcanic"
    },
    {
      "x": -14,
      "y": 56,
      "z": -6,
      "name": "Rock_Volcanic"
    },
    {
      "x": -14,
      "y": 57,
      "z": -6,
      "name": "Rock_Volcanic"
    },
    {
      "x": -14,
      "y": 58,
      "z": -6,
      "name": "Rock_Volcanic"
    },
    {
      "x": -14,
      "y": 59,
      "z": -6,
      "name": "Soil_Volcanic_Gravel"
    },
    {
      "x": -14,
      "y": 15,
      "z": -5,
      "name": "Rock_Volcanic"
    },
    {
      "x": -14,
      "y": 16,
      "z": -5,
      "name": "Rock_Volcanic"
    },
    {
      "x": -14,
      "y": 17,
      "z": -5,
      "name": "Rock_Volcanic"
    },
    {
      "x": -14,
      "y": 18,
      "z": -5,
      "name": "Rock_Volcanic"
    },
    {
      "x": -14,
      "y": 19,
      "z": -5,
      "name": "Rock_Volcanic"
    },
    {
      "x": -14,
      "y": 20,
      "z": -5,
      "name": "Rock_Volcanic"
    },
    {
      "x": -14,
      "y": 21,
      "z": -5,
      "name": "Rock_Volcanic"
    },
    {
      "x": -14,
      "y": 22,
      "z": -5,
      "name": "Rock_Volcanic"
    },
    {
      "x": -14,
      "y": 23,
      "z": -5,
      "name": "Rock_Volcanic"
    },
    {
      "x": -14,
      "y": 24,
      "z": -5,
      "name": "Rock_Volcanic"
    },
    {
      "x": -14,
      "y": 25,
      "z": -5,
      "name": "Rock_Volcanic"
    },
    {
      "x": -14,
      "y": 26,
      "z": -5,
      "name": "Rock_Volcanic"
    },
    {
      "x": -14,
      "y": 27,
      "z": -5,
      "name": "Rock_Volcanic"
    },
    {
      "x": -14,
      "y": 28,
      "z": -5,
      "name": "Rock_Volcanic"
    },
    {
      "x": -14,
      "y": 29,
      "z": -5,
      "name": "Rock_Volcanic"
    },
    {
      "x": -14,
      "y": 30,
      "z": -5,
      "name": "Rock_Volcanic"
    },
    {
      "x": -14,
      "y": 31,
      "z": -5,
      "name": "Rock_Volcanic"
    },
    {
      "x": -14,
      "y": 33,
      "z": -5,
      "name": "Rock_Volcanic"
    },
    {
      "x": -14,
      "y": 34,
      "z": -5,
      "name": "Rock_Volcanic"
    },
    {
      "x": -14,
      "y": 35,
      "z": -5,
      "name": "Rock_Volcanic"
    },
    {
      "x": -14,
      "y": 36,
      "z": -5,
      "name": "Rock_Volcanic"
    },
    {
      "x": -14,
      "y": 37,
      "z": -5,
      "name": "Soil_Volcanic_Gravel"
    },
    {
      "x": -14,
      "y": 38,
      "z": -5,
      "name": "Rock_Volcanic"
    },
    {
      "x": -14,
      "y": 39,
      "z": -5,
      "name": "Rock_Volcanic"
    },
    {
      "x": -14,
      "y": 40,
      "z": -5,
      "name": "Rock_Volcanic"
    },
    {
      "x": -14,
      "y": 41,
      "z": -5,
      "name": "Rock_Volcanic"
    },
    {
      "x": -14,
      "y": 42,
      "z": -5,
      "name": "Rock_Volcanic"
    },
    {
      "x": -14,
      "y": 43,
      "z": -5,
      "name": "Rock_Volcanic"
    },
    {
      "x": -14,
      "y": 44,
      "z": -5,
      "name": "Rock_Volcanic"
    },
    {
      "x": -14,
      "y": 45,
      "z": -5,
      "name": "Rock_Volcanic"
    },
    {
      "x": -14,
      "y": 46,
      "z": -5,
      "name": "Rock_Volcanic"
    },
    {
      "x": -14,
      "y": 47,
      "z": -5,
      "name": "Rock_Volcanic"
    },
    {
      "x": -14,
      "y": 48,
      "z": -5,
      "name": "Rock_Volcanic"
    },
    {
      "x": -14,
      "y": 49,
      "z": -5,
      "name": "Rock_Volcanic"
    },
    {
      "x": -14,
      "y": 50,
      "z": -5,
      "name": "Rock_Volcanic"
    },
    {
      "x": -14,
      "y": 51,
      "z": -5,
      "name": "Rock_Volcanic"
    },
    {
      "x": -14,
      "y": 52,
      "z": -5,
      "name": "Rock_Volcanic"
    },
    {
      "x": -14,
      "y": 53,
      "z": -5,
      "name": "Rock_Volcanic"
    },
    {
      "x": -14,
      "y": 54,
      "z": -5,
      "name": "Rock_Volcanic"
    },
    {
      "x": -14,
      "y": 55,
      "z": -5,
      "name": "Soil_Volcanic_Gravel"
    },
    {
      "x": -14,
      "y": 56,
      "z": -5,
      "name": "Rock_Volcanic"
    },
    {
      "x": -14,
      "y": 57,
      "z": -5,
      "name": "Soil_Volcanic_Gravel"
    },
    {
      "x": -14,
      "y": 58,
      "z": -5,
      "name": "Soil_Volcanic_Gravel"
    },
    {
      "x": -14,
      "y": 59,
      "z": -5,
      "name": "Soil_Volcanic_Gravel"
    },
    {
      "x": -14,
      "y": 15,
      "z": -4,
      "name": "Rock_Volcanic"
    },
    {
      "x": -14,
      "y": 16,
      "z": -4,
      "name": "Rock_Volcanic"
    },
    {
      "x": -14,
      "y": 17,
      "z": -4,
      "name": "Rock_Volcanic"
    },
    {
      "x": -14,
      "y": 18,
      "z": -4,
      "name": "Rock_Volcanic"
    },
    {
      "x": -14,
      "y": 19,
      "z": -4,
      "name": "Rock_Volcanic"
    },
    {
      "x": -14,
      "y": 20,
      "z": -4,
      "name": "Rock_Volcanic"
    },
    {
      "x": -14,
      "y": 21,
      "z": -4,
      "name": "Rock_Volcanic"
    },
    {
      "x": -14,
      "y": 22,
      "z": -4,
      "name": "Rock_Volcanic"
    },
    {
      "x": -14,
      "y": 23,
      "z": -4,
      "name": "Rock_Volcanic"
    },
    {
      "x": -14,
      "y": 24,
      "z": -4,
      "name": "Soil_Volcanic_Gravel"
    },
    {
      "x": -14,
      "y": 25,
      "z": -4,
      "name": "Soil_Volcanic_Gravel"
    },
    {
      "x": -14,
      "y": 26,
      "z": -4,
      "name": "Rock_Volcanic"
    },
    {
      "x": -14,
      "y": 27,
      "z": -4,
      "name": "Rock_Volcanic"
    },
    {
      "x": -14,
      "y": 28,
      "z": -4,
      "name": "Rock_Volcanic"
    },
    {
      "x": -14,
      "y": 29,
      "z": -4,
      "name": "Rock_Volcanic"
    },
    {
      "x": -14,
      "y": 30,
      "z": -4,
      "name": "Rock_Volcanic"
    },
    {
      "x": -14,
      "y": 31,
      "z": -4,
      "name": "Rock_Volcanic"
    },
    {
      "x": -14,
      "y": 32,
      "z": -4,
      "name": "Rock_Volcanic"
    },
    {
      "x": -14,
      "y": 33,
      "z": -4,
      "name": "Rock_Volcanic"
    },
    {
      "x": -14,
      "y": 34,
      "z": -4,
      "name": "Rock_Volcanic"
    },
    {
      "x": -14,
      "y": 35,
      "z": -4,
      "name": "Rock_Volcanic"
    },
    {
      "x": -14,
      "y": 36,
      "z": -4,
      "name": "Rock_Volcanic"
    },
    {
      "x": -14,
      "y": 37,
      "z": -4,
      "name": "Rock_Volcanic"
    },
    {
      "x": -14,
      "y": 38,
      "z": -4,
      "name": "Rock_Volcanic"
    },
    {
      "x": -14,
      "y": 39,
      "z": -4,
      "name": "Rock_Volcanic"
    },
    {
      "x": -14,
      "y": 40,
      "z": -4,
      "name": "Rock_Volcanic"
    },
    {
      "x": -14,
      "y": 41,
      "z": -4,
      "name": "Rock_Volcanic"
    },
    {
      "x": -14,
      "y": 42,
      "z": -4,
      "name": "Rock_Volcanic"
    },
    {
      "x": -14,
      "y": 43,
      "z": -4,
      "name": "Rock_Volcanic"
    },
    {
      "x": -14,
      "y": 44,
      "z": -4,
      "name": "Rock_Volcanic"
    },
    {
      "x": -14,
      "y": 45,
      "z": -4,
      "name": "Rock_Volcanic"
    },
    {
      "x": -14,
      "y": 46,
      "z": -4,
      "name": "Rock_Volcanic"
    },
    {
      "x": -14,
      "y": 47,
      "z": -4,
      "name": "Rock_Volcanic"
    },
    {
      "x": -14,
      "y": 48,
      "z": -4,
      "name": "Rock_Volcanic"
    },
    {
      "x": -14,
      "y": 49,
      "z": -4,
      "name": "Rock_Volcanic"
    },
    {
      "x": -14,
      "y": 50,
      "z": -4,
      "name": "Rock_Volcanic"
    },
    {
      "x": -14,
      "y": 51,
      "z": -4,
      "name": "Rock_Volcanic"
    },
    {
      "x": -14,
      "y": 52,
      "z": -4,
      "name": "Rock_Volcanic"
    },
    {
      "x": -14,
      "y": 53,
      "z": -4,
      "name": "Rock_Volcanic"
    },
    {
      "x": -14,
      "y": 54,
      "z": -4,
      "name": "Rock_Volcanic"
    },
    {
      "x": -14,
      "y": 55,
      "z": -4,
      "name": "Soil_Volcanic_Gravel"
    },
    {
      "x": -14,
      "y": 56,
      "z": -4,
      "name": "Soil_Volcanic_Gravel"
    },
    {
      "x": -14,
      "y": 57,
      "z": -4,
      "name": "Soil_Volcanic_Gravel"
    },
    {
      "x": -14,
      "y": 58,
      "z": -4,
      "name": "Soil_Volcanic_Gravel"
    },
    {
      "x": -14,
      "y": 15,
      "z": -3,
      "name": "Rock_Volcanic"
    },
    {
      "x": -14,
      "y": 16,
      "z": -3,
      "name": "Rock_Volcanic"
    },
    {
      "x": -14,
      "y": 17,
      "z": -3,
      "name": "Rock_Volcanic"
    },
    {
      "x": -14,
      "y": 18,
      "z": -3,
      "name": "Rock_Volcanic"
    },
    {
      "x": -14,
      "y": 19,
      "z": -3,
      "name": "Rock_Volcanic"
    },
    {
      "x": -14,
      "y": 20,
      "z": -3,
      "name": "Rock_Volcanic"
    },
    {
      "x": -14,
      "y": 21,
      "z": -3,
      "name": "Rock_Volcanic"
    },
    {
      "x": -14,
      "y": 22,
      "z": -3,
      "name": "Rock_Volcanic"
    },
    {
      "x": -14,
      "y": 23,
      "z": -3,
      "name": "Rock_Volcanic"
    },
    {
      "x": -14,
      "y": 24,
      "z": -3,
      "name": "Soil_Volcanic_Gravel"
    },
    {
      "x": -14,
      "y": 25,
      "z": -3,
      "name": "Soil_Volcanic_Gravel"
    },
    {
      "x": -14,
      "y": 26,
      "z": -3,
      "name": "Soil_Volcanic_Gravel"
    },
    {
      "x": -14,
      "y": 27,
      "z": -3,
      "name": "Rock_Volcanic"
    },
    {
      "x": -14,
      "y": 28,
      "z": -3,
      "name": "Rock_Volcanic"
    },
    {
      "x": -14,
      "y": 29,
      "z": -3,
      "name": "Rock_Volcanic"
    },
    {
      "x": -14,
      "y": 30,
      "z": -3,
      "name": "Rock_Volcanic"
    },
    {
      "x": -14,
      "y": 31,
      "z": -3,
      "name": "Rock_Volcanic"
    },
    {
      "x": -14,
      "y": 32,
      "z": -3,
      "name": "Rock_Volcanic"
    },
    {
      "x": -14,
      "y": 33,
      "z": -3,
      "name": "Rock_Volcanic"
    },
    {
      "x": -14,
      "y": 34,
      "z": -3,
      "name": "Rock_Volcanic"
    },
    {
      "x": -14,
      "y": 35,
      "z": -3,
      "name": "Rock_Volcanic"
    },
    {
      "x": -14,
      "y": 36,
      "z": -3,
      "name": "Rock_Volcanic"
    },
    {
      "x": -14,
      "y": 37,
      "z": -3,
      "name": "Rock_Volcanic"
    },
    {
      "x": -14,
      "y": 38,
      "z": -3,
      "name": "Rock_Volcanic"
    },
    {
      "x": -14,
      "y": 39,
      "z": -3,
      "name": "Rock_Volcanic"
    },
    {
      "x": -14,
      "y": 40,
      "z": -3,
      "name": "Rock_Volcanic"
    },
    {
      "x": -14,
      "y": 41,
      "z": -3,
      "name": "Rock_Volcanic"
    },
    {
      "x": -14,
      "y": 42,
      "z": -3,
      "name": "Soil_Volcanic_Gravel"
    },
    {
      "x": -14,
      "y": 43,
      "z": -3,
      "name": "Rock_Volcanic"
    },
    {
      "x": -14,
      "y": 44,
      "z": -3,
      "name": "Rock_Volcanic"
    },
    {
      "x": -14,
      "y": 45,
      "z": -3,
      "name": "Rock_Volcanic"
    },
    {
      "x": -14,
      "y": 46,
      "z": -3,
      "name": "Rock_Volcanic"
    },
    {
      "x": -14,
      "y": 47,
      "z": -3,
      "name": "Rock_Volcanic"
    },
    {
      "x": -14,
      "y": 48,
      "z": -3,
      "name": "Rock_Volcanic"
    },
    {
      "x": -14,
      "y": 49,
      "z": -3,
      "name": "Rock_Volcanic"
    },
    {
      "x": -14,
      "y": 50,
      "z": -3,
      "name": "Rock_Volcanic"
    },
    {
      "x": -14,
      "y": 51,
      "z": -3,
      "name": "Rock_Volcanic"
    },
    {
      "x": -14,
      "y": 52,
      "z": -3,
      "name": "Rock_Volcanic"
    },
    {
      "x": -14,
      "y": 53,
      "z": -3,
      "name": "Rock_Volcanic"
    },
    {
      "x": -14,
      "y": 54,
      "z": -3,
      "name": "Rock_Volcanic"
    },
    {
      "x": -14,
      "y": 55,
      "z": -3,
      "name": "Soil_Volcanic_Gravel"
    },
    {
      "x": -14,
      "y": 56,
      "z": -3,
      "name": "Rock_Volcanic"
    },
    {
      "x": -14,
      "y": 57,
      "z": -3,
      "name": "Soil_Volcanic_Gravel"
    },
    {
      "x": -14,
      "y": 15,
      "z": -2,
      "name": "Rock_Volcanic"
    },
    {
      "x": -14,
      "y": 16,
      "z": -2,
      "name": "Rock_Volcanic"
    },
    {
      "x": -14,
      "y": 17,
      "z": -2,
      "name": "Rock_Volcanic"
    },
    {
      "x": -14,
      "y": 18,
      "z": -2,
      "name": "Rock_Volcanic"
    },
    {
      "x": -14,
      "y": 19,
      "z": -2,
      "name": "Rock_Volcanic"
    },
    {
      "x": -14,
      "y": 20,
      "z": -2,
      "name": "Rock_Volcanic"
    },
    {
      "x": -14,
      "y": 21,
      "z": -2,
      "name": "Rock_Volcanic"
    },
    {
      "x": -14,
      "y": 22,
      "z": -2,
      "name": "Soil_Volcanic_Gravel"
    },
    {
      "x": -14,
      "y": 23,
      "z": -2,
      "name": "Soil_Volcanic_Gravel"
    },
    {
      "x": -14,
      "y": 24,
      "z": -2,
      "name": "Soil_Volcanic_Gravel"
    },
    {
      "x": -14,
      "y": 25,
      "z": -2,
      "name": "Soil_Volcanic_Gravel"
    },
    {
      "x": -14,
      "y": 26,
      "z": -2,
      "name": "Soil_Volcanic_Gravel"
    },
    {
      "x": -14,
      "y": 27,
      "z": -2,
      "name": "Soil_Volcanic_Gravel"
    },
    {
      "x": -14,
      "y": 28,
      "z": -2,
      "name": "Rock_Volcanic"
    },
    {
      "x": -14,
      "y": 29,
      "z": -2,
      "name": "Rock_Volcanic"
    },
    {
      "x": -14,
      "y": 30,
      "z": -2,
      "name": "Rock_Volcanic"
    },
    {
      "x": -14,
      "y": 31,
      "z": -2,
      "name": "Rock_Volcanic"
    },
    {
      "x": -14,
      "y": 32,
      "z": -2,
      "name": "Rock_Volcanic"
    },
    {
      "x": -14,
      "y": 33,
      "z": -2,
      "name": "Rock_Volcanic"
    },
    {
      "x": -14,
      "y": 34,
      "z": -2,
      "name": "Rock_Volcanic"
    },
    {
      "x": -14,
      "y": 35,
      "z": -2,
      "name": "Rock_Volcanic"
    },
    {
      "x": -14,
      "y": 36,
      "z": -2,
      "name": "Rock_Volcanic"
    },
    {
      "x": -14,
      "y": 37,
      "z": -2,
      "name": "Rock_Volcanic"
    },
    {
      "x": -14,
      "y": 38,
      "z": -2,
      "name": "Rock_Volcanic"
    },
    {
      "x": -14,
      "y": 39,
      "z": -2,
      "name": "Rock_Volcanic"
    },
    {
      "x": -14,
      "y": 40,
      "z": -2,
      "name": "Rock_Volcanic"
    },
    {
      "x": -14,
      "y": 41,
      "z": -2,
      "name": "Rock_Volcanic"
    },
    {
      "x": -14,
      "y": 42,
      "z": -2,
      "name": "Rock_Volcanic"
    },
    {
      "x": -14,
      "y": 43,
      "z": -2,
      "name": "Soil_Volcanic_Gravel"
    },
    {
      "x": -14,
      "y": 44,
      "z": -2,
      "name": "Rock_Volcanic"
    },
    {
      "x": -14,
      "y": 45,
      "z": -2,
      "name": "Rock_Volcanic"
    },
    {
      "x": -14,
      "y": 46,
      "z": -2,
      "name": "Rock_Volcanic"
    },
    {
      "x": -14,
      "y": 47,
      "z": -2,
      "name": "Rock_Volcanic"
    },
    {
      "x": -14,
      "y": 48,
      "z": -2,
      "name": "Rock_Volcanic"
    },
    {
      "x": -14,
      "y": 49,
      "z": -2,
      "name": "Rock_Volcanic"
    },
    {
      "x": -14,
      "y": 50,
      "z": -2,
      "name": "Rock_Volcanic"
    },
    {
      "x": -14,
      "y": 51,
      "z": -2,
      "name": "Rock_Volcanic"
    },
    {
      "x": -14,
      "y": 52,
      "z": -2,
      "name": "Rock_Volcanic"
    },
    {
      "x": -14,
      "y": 53,
      "z": -2,
      "name": "Rock_Volcanic"
    },
    {
      "x": -14,
      "y": 54,
      "z": -2,
      "name": "Soil_Volcanic_Gravel"
    },
    {
      "x": -14,
      "y": 55,
      "z": -2,
      "name": "Soil_Volcanic_Gravel"
    },
    {
      "x": -14,
      "y": 56,
      "z": -2,
      "name": "Soil_Volcanic_Gravel"
    },
    {
      "x": -14,
      "y": 15,
      "z": -1,
      "name": "Rock_Volcanic"
    },
    {
      "x": -14,
      "y": 16,
      "z": -1,
      "name": "Rock_Volcanic"
    },
    {
      "x": -14,
      "y": 17,
      "z": -1,
      "name": "Rock_Volcanic"
    },
    {
      "x": -14,
      "y": 18,
      "z": -1,
      "name": "Rock_Volcanic"
    },
    {
      "x": -14,
      "y": 19,
      "z": -1,
      "name": "Rock_Volcanic"
    },
    {
      "x": -14,
      "y": 20,
      "z": -1,
      "name": "Rock_Volcanic"
    },
    {
      "x": -14,
      "y": 21,
      "z": -1,
      "name": "Rock_Volcanic"
    },
    {
      "x": -14,
      "y": 22,
      "z": -1,
      "name": "Rock_Volcanic"
    },
    {
      "x": -14,
      "y": 23,
      "z": -1,
      "name": "Soil_Volcanic_Gravel"
    },
    {
      "x": -14,
      "y": 24,
      "z": -1,
      "name": "Rock_Volcanic"
    },
    {
      "x": -14,
      "y": 25,
      "z": -1,
      "name": "Soil_Volcanic_Gravel"
    },
    {
      "x": -14,
      "y": 26,
      "z": -1,
      "name": "Soil_Volcanic_Gravel"
    },
    {
      "x": -14,
      "y": 27,
      "z": -1,
      "name": "Rock_Volcanic"
    },
    {
      "x": -14,
      "y": 28,
      "z": -1,
      "name": "Rock_Volcanic"
    },
    {
      "x": -14,
      "y": 29,
      "z": -1,
      "name": "Rock_Volcanic"
    },
    {
      "x": -14,
      "y": 30,
      "z": -1,
      "name": "Rock_Volcanic"
    },
    {
      "x": -14,
      "y": 31,
      "z": -1,
      "name": "Rock_Volcanic"
    },
    {
      "x": -14,
      "y": 32,
      "z": -1,
      "name": "Rock_Volcanic"
    },
    {
      "x": -14,
      "y": 33,
      "z": -1,
      "name": "Rock_Volcanic"
    },
    {
      "x": -14,
      "y": 34,
      "z": -1,
      "name": "Rock_Volcanic"
    },
    {
      "x": -14,
      "y": 35,
      "z": -1,
      "name": "Rock_Volcanic"
    },
    {
      "x": -14,
      "y": 36,
      "z": -1,
      "name": "Rock_Volcanic"
    },
    {
      "x": -14,
      "y": 37,
      "z": -1,
      "name": "Rock_Volcanic"
    },
    {
      "x": -14,
      "y": 38,
      "z": -1,
      "name": "Rock_Volcanic"
    },
    {
      "x": -14,
      "y": 39,
      "z": -1,
      "name": "Rock_Volcanic"
    },
    {
      "x": -14,
      "y": 40,
      "z": -1,
      "name": "Soil_Volcanic_Gravel"
    },
    {
      "x": -14,
      "y": 41,
      "z": -1,
      "name": "Rock_Volcanic"
    },
    {
      "x": -14,
      "y": 42,
      "z": -1,
      "name": "Soil_Volcanic_Gravel"
    },
    {
      "x": -14,
      "y": 43,
      "z": -1,
      "name": "Rock_Volcanic"
    },
    {
      "x": -14,
      "y": 44,
      "z": -1,
      "name": "Rock_Volcanic"
    },
    {
      "x": -14,
      "y": 45,
      "z": -1,
      "name": "Rock_Volcanic"
    },
    {
      "x": -14,
      "y": 46,
      "z": -1,
      "name": "Rock_Volcanic"
    },
    {
      "x": -14,
      "y": 47,
      "z": -1,
      "name": "Rock_Volcanic"
    },
    {
      "x": -14,
      "y": 48,
      "z": -1,
      "name": "Rock_Volcanic"
    },
    {
      "x": -14,
      "y": 49,
      "z": -1,
      "name": "Rock_Volcanic"
    },
    {
      "x": -14,
      "y": 50,
      "z": -1,
      "name": "Rock_Volcanic"
    },
    {
      "x": -14,
      "y": 51,
      "z": -1,
      "name": "Rock_Volcanic"
    },
    {
      "x": -14,
      "y": 52,
      "z": -1,
      "name": "Rock_Volcanic"
    },
    {
      "x": -14,
      "y": 53,
      "z": -1,
      "name": "Rock_Volcanic"
    },
    {
      "x": -14,
      "y": 54,
      "z": -1,
      "name": "Soil_Volcanic_Gravel"
    },
    {
      "x": -14,
      "y": 55,
      "z": -1,
      "name": "Soil_Volcanic_Gravel"
    },
    {
      "x": -14,
      "y": 56,
      "z": -1,
      "name": "Soil_Volcanic_Gravel"
    },
    {
      "x": -14,
      "y": 14,
      "z": 0,
      "name": "Rock_Volcanic"
    },
    {
      "x": -14,
      "y": 15,
      "z": 0,
      "name": "Rock_Volcanic"
    },
    {
      "x": -14,
      "y": 16,
      "z": 0,
      "name": "Rock_Volcanic"
    },
    {
      "x": -14,
      "y": 17,
      "z": 0,
      "name": "Rock_Volcanic"
    },
    {
      "x": -14,
      "y": 18,
      "z": 0,
      "name": "Rock_Volcanic"
    },
    {
      "x": -14,
      "y": 19,
      "z": 0,
      "name": "Rock_Volcanic"
    },
    {
      "x": -14,
      "y": 20,
      "z": 0,
      "name": "Rock_Volcanic"
    },
    {
      "x": -14,
      "y": 21,
      "z": 0,
      "name": "Soil_Volcanic_Gravel"
    },
    {
      "x": -14,
      "y": 22,
      "z": 0,
      "name": "Soil_Volcanic_Gravel"
    },
    {
      "x": -14,
      "y": 23,
      "z": 0,
      "name": "Soil_Volcanic_Gravel"
    },
    {
      "x": -14,
      "y": 24,
      "z": 0,
      "name": "Soil_Volcanic_Gravel"
    },
    {
      "x": -14,
      "y": 25,
      "z": 0,
      "name": "Soil_Volcanic_Gravel"
    },
    {
      "x": -14,
      "y": 26,
      "z": 0,
      "name": "Soil_Volcanic_Gravel"
    },
    {
      "x": -14,
      "y": 38,
      "z": 0,
      "name": "Rock_Volcanic"
    },
    {
      "x": -14,
      "y": 39,
      "z": 0,
      "name": "Rock_Volcanic"
    },
    {
      "x": -14,
      "y": 40,
      "z": 0,
      "name": "Soil_Volcanic_Gravel"
    },
    {
      "x": -14,
      "y": 46,
      "z": 0,
      "name": "Rock_Volcanic"
    },
    {
      "x": -14,
      "y": 47,
      "z": 0,
      "name": "Rock_Volcanic"
    },
    {
      "x": -14,
      "y": 48,
      "z": 0,
      "name": "Rock_Volcanic"
    },
    {
      "x": -14,
      "y": 49,
      "z": 0,
      "name": "Rock_Volcanic"
    },
    {
      "x": -14,
      "y": 50,
      "z": 0,
      "name": "Rock_Volcanic"
    },
    {
      "x": -14,
      "y": 51,
      "z": 0,
      "name": "Rock_Volcanic"
    },
    {
      "x": -14,
      "y": 52,
      "z": 0,
      "name": "Rock_Volcanic"
    },
    {
      "x": -14,
      "y": 53,
      "z": 0,
      "name": "Rock_Volcanic"
    },
    {
      "x": -14,
      "y": 54,
      "z": 0,
      "name": "Soil_Volcanic_Gravel"
    },
    {
      "x": -14,
      "y": 55,
      "z": 0,
      "name": "Soil_Volcanic_Gravel"
    },
    {
      "x": -14,
      "y": 14,
      "z": 1,
      "name": "Rock_Volcanic"
    },
    {
      "x": -14,
      "y": 15,
      "z": 1,
      "name": "Rock_Volcanic"
    },
    {
      "x": -14,
      "y": 16,
      "z": 1,
      "name": "Rock_Volcanic"
    },
    {
      "x": -14,
      "y": 17,
      "z": 1,
      "name": "Rock_Volcanic"
    },
    {
      "x": -14,
      "y": 18,
      "z": 1,
      "name": "Rock_Volcanic"
    },
    {
      "x": -14,
      "y": 19,
      "z": 1,
      "name": "Rock_Volcanic"
    },
    {
      "x": -14,
      "y": 20,
      "z": 1,
      "name": "Rock_Volcanic"
    },
    {
      "x": -14,
      "y": 21,
      "z": 1,
      "name": "Soil_Volcanic_Gravel"
    },
    {
      "x": -14,
      "y": 22,
      "z": 1,
      "name": "Soil_Volcanic_Gravel"
    },
    {
      "x": -14,
      "y": 23,
      "z": 1,
      "name": "Soil_Volcanic_Gravel"
    },
    {
      "x": -14,
      "y": 24,
      "z": 1,
      "name": "Soil_Volcanic_Gravel"
    },
    {
      "x": -14,
      "y": 25,
      "z": 1,
      "name": "Soil_Volcanic_Gravel"
    },
    {
      "x": -14,
      "y": 39,
      "z": 1,
      "name": "Rock_Volcanic"
    },
    {
      "x": -14,
      "y": 47,
      "z": 1,
      "name": "Rock_Volcanic"
    },
    {
      "x": -14,
      "y": 48,
      "z": 1,
      "name": "Rock_Volcanic"
    },
    {
      "x": -14,
      "y": 49,
      "z": 1,
      "name": "Rock_Volcanic"
    },
    {
      "x": -14,
      "y": 50,
      "z": 1,
      "name": "Rock_Volcanic"
    },
    {
      "x": -14,
      "y": 51,
      "z": 1,
      "name": "Rock_Volcanic"
    },
    {
      "x": -14,
      "y": 52,
      "z": 1,
      "name": "Rock_Volcanic"
    },
    {
      "x": -14,
      "y": 53,
      "z": 1,
      "name": "Rock_Volcanic"
    },
    {
      "x": -14,
      "y": 54,
      "z": 1,
      "name": "Rock_Volcanic"
    },
    {
      "x": -14,
      "y": 55,
      "z": 1,
      "name": "Soil_Volcanic_Gravel"
    },
    {
      "x": -14,
      "y": 12,
      "z": 2,
      "name": "Rock_Volcanic"
    },
    {
      "x": -14,
      "y": 13,
      "z": 2,
      "name": "Rock_Volcanic"
    },
    {
      "x": -14,
      "y": 14,
      "z": 2,
      "name": "Rock_Volcanic"
    },
    {
      "x": -14,
      "y": 15,
      "z": 2,
      "name": "Rock_Volcanic"
    },
    {
      "x": -14,
      "y": 16,
      "z": 2,
      "name": "Rock_Volcanic"
    },
    {
      "x": -14,
      "y": 17,
      "z": 2,
      "name": "Rock_Volcanic"
    },
    {
      "x": -14,
      "y": 18,
      "z": 2,
      "name": "Rock_Volcanic"
    },
    {
      "x": -14,
      "y": 19,
      "z": 2,
      "name": "Rock_Volcanic"
    },
    {
      "x": -14,
      "y": 20,
      "z": 2,
      "name": "Rock_Volcanic"
    },
    {
      "x": -14,
      "y": 21,
      "z": 2,
      "name": "Rock_Volcanic"
    },
    {
      "x": -14,
      "y": 22,
      "z": 2,
      "name": "Soil_Volcanic_Gravel"
    },
    {
      "x": -14,
      "y": 23,
      "z": 2,
      "name": "Soil_Volcanic_Gravel"
    },
    {
      "x": -14,
      "y": 24,
      "z": 2,
      "name": "Soil_Volcanic_Gravel"
    },
    {
      "x": -14,
      "y": 25,
      "z": 2,
      "name": "Soil_Volcanic_Gravel"
    },
    {
      "x": -14,
      "y": 48,
      "z": 2,
      "name": "Rock_Volcanic"
    },
    {
      "x": -14,
      "y": 49,
      "z": 2,
      "name": "Rock_Volcanic"
    },
    {
      "x": -14,
      "y": 50,
      "z": 2,
      "name": "Rock_Volcanic"
    },
    {
      "x": -14,
      "y": 51,
      "z": 2,
      "name": "Rock_Volcanic"
    },
    {
      "x": -14,
      "y": 52,
      "z": 2,
      "name": "Rock_Volcanic"
    },
    {
      "x": -14,
      "y": 53,
      "z": 2,
      "name": "Rock_Volcanic"
    },
    {
      "x": -14,
      "y": 54,
      "z": 2,
      "name": "Soil_Volcanic_Gravel"
    },
    {
      "x": -14,
      "y": 7,
      "z": 3,
      "name": "Rock_Volcanic"
    },
    {
      "x": -14,
      "y": 8,
      "z": 3,
      "name": "Rock_Volcanic"
    },
    {
      "x": -14,
      "y": 9,
      "z": 3,
      "name": "Rock_Volcanic"
    },
    {
      "x": -14,
      "y": 10,
      "z": 3,
      "name": "Rock_Volcanic"
    },
    {
      "x": -14,
      "y": 11,
      "z": 3,
      "name": "Rock_Volcanic"
    },
    {
      "x": -14,
      "y": 12,
      "z": 3,
      "name": "Rock_Volcanic"
    },
    {
      "x": -14,
      "y": 13,
      "z": 3,
      "name": "Rock_Volcanic"
    },
    {
      "x": -14,
      "y": 14,
      "z": 3,
      "name": "Rock_Volcanic"
    },
    {
      "x": -14,
      "y": 15,
      "z": 3,
      "name": "Rock_Volcanic"
    },
    {
      "x": -14,
      "y": 16,
      "z": 3,
      "name": "Rock_Volcanic"
    },
    {
      "x": -14,
      "y": 17,
      "z": 3,
      "name": "Rock_Volcanic"
    },
    {
      "x": -14,
      "y": 18,
      "z": 3,
      "name": "Rock_Volcanic"
    },
    {
      "x": -14,
      "y": 19,
      "z": 3,
      "name": "Rock_Volcanic"
    },
    {
      "x": -14,
      "y": 20,
      "z": 3,
      "name": "Rock_Volcanic"
    },
    {
      "x": -14,
      "y": 21,
      "z": 3,
      "name": "Soil_Volcanic_Gravel"
    },
    {
      "x": -14,
      "y": 22,
      "z": 3,
      "name": "Soil_Volcanic_Gravel"
    },
    {
      "x": -14,
      "y": 23,
      "z": 3,
      "name": "Soil_Volcanic_Gravel"
    },
    {
      "x": -14,
      "y": 24,
      "z": 3,
      "name": "Soil_Volcanic_Gravel"
    },
    {
      "x": -14,
      "y": 25,
      "z": 3,
      "name": "Soil_Volcanic_Gravel"
    },
    {
      "x": -14,
      "y": 50,
      "z": 3,
      "name": "Rock_Volcanic"
    },
    {
      "x": -14,
      "y": 51,
      "z": 3,
      "name": "Rock_Volcanic"
    },
    {
      "x": -14,
      "y": 52,
      "z": 3,
      "name": "Rock_Volcanic"
    },
    {
      "x": -14,
      "y": 53,
      "z": 3,
      "name": "Rock_Volcanic"
    },
    {
      "x": -14,
      "y": 6,
      "z": 4,
      "name": "Rock_Volcanic"
    },
    {
      "x": -14,
      "y": 7,
      "z": 4,
      "name": "Rock_Volcanic"
    },
    {
      "x": -14,
      "y": 8,
      "z": 4,
      "name": "Rock_Volcanic"
    },
    {
      "x": -14,
      "y": 9,
      "z": 4,
      "name": "Rock_Volcanic"
    },
    {
      "x": -14,
      "y": 10,
      "z": 4,
      "name": "Rock_Volcanic"
    },
    {
      "x": -14,
      "y": 11,
      "z": 4,
      "name": "Rock_Volcanic"
    },
    {
      "x": -14,
      "y": 12,
      "z": 4,
      "name": "Rock_Volcanic"
    },
    {
      "x": -14,
      "y": 13,
      "z": 4,
      "name": "Rock_Volcanic"
    },
    {
      "x": -14,
      "y": 14,
      "z": 4,
      "name": "Rock_Volcanic"
    },
    {
      "x": -14,
      "y": 15,
      "z": 4,
      "name": "Rock_Volcanic"
    },
    {
      "x": -14,
      "y": 16,
      "z": 4,
      "name": "Rock_Volcanic"
    },
    {
      "x": -14,
      "y": 17,
      "z": 4,
      "name": "Rock_Volcanic"
    },
    {
      "x": -14,
      "y": 18,
      "z": 4,
      "name": "Rock_Volcanic"
    },
    {
      "x": -14,
      "y": 19,
      "z": 4,
      "name": "Rock_Volcanic"
    },
    {
      "x": -14,
      "y": 20,
      "z": 4,
      "name": "Rock_Volcanic"
    },
    {
      "x": -14,
      "y": 21,
      "z": 4,
      "name": "Rock_Volcanic"
    },
    {
      "x": -14,
      "y": 22,
      "z": 4,
      "name": "Soil_Volcanic_Gravel"
    },
    {
      "x": -14,
      "y": 23,
      "z": 4,
      "name": "Soil_Volcanic_Gravel"
    },
    {
      "x": -14,
      "y": 24,
      "z": 4,
      "name": "Soil_Volcanic_Gravel"
    },
    {
      "x": -14,
      "y": 5,
      "z": 5,
      "name": "Rock_Volcanic"
    },
    {
      "x": -14,
      "y": 6,
      "z": 5,
      "name": "Rock_Volcanic"
    },
    {
      "x": -14,
      "y": 7,
      "z": 5,
      "name": "Rock_Volcanic"
    },
    {
      "x": -14,
      "y": 8,
      "z": 5,
      "name": "Rock_Volcanic"
    },
    {
      "x": -14,
      "y": 9,
      "z": 5,
      "name": "Rock_Volcanic"
    },
    {
      "x": -14,
      "y": 10,
      "z": 5,
      "name": "Rock_Volcanic"
    },
    {
      "x": -14,
      "y": 11,
      "z": 5,
      "name": "Rock_Volcanic"
    },
    {
      "x": -14,
      "y": 12,
      "z": 5,
      "name": "Rock_Volcanic"
    },
    {
      "x": -14,
      "y": 13,
      "z": 5,
      "name": "Rock_Volcanic"
    },
    {
      "x": -14,
      "y": 14,
      "z": 5,
      "name": "Rock_Volcanic"
    },
    {
      "x": -14,
      "y": 15,
      "z": 5,
      "name": "Rock_Volcanic"
    },
    {
      "x": -14,
      "y": 16,
      "z": 5,
      "name": "Rock_Volcanic"
    },
    {
      "x": -14,
      "y": 17,
      "z": 5,
      "name": "Rock_Volcanic"
    },
    {
      "x": -14,
      "y": 18,
      "z": 5,
      "name": "Rock_Volcanic"
    },
    {
      "x": -14,
      "y": 19,
      "z": 5,
      "name": "Rock_Volcanic"
    },
    {
      "x": -14,
      "y": 20,
      "z": 5,
      "name": "Soil_Volcanic_Gravel"
    },
    {
      "x": -14,
      "y": 21,
      "z": 5,
      "name": "Rock_Volcanic"
    },
    {
      "x": -14,
      "y": 22,
      "z": 5,
      "name": "Soil_Volcanic_Gravel"
    },
    {
      "x": -14,
      "y": 4,
      "z": 6,
      "name": "Rock_Volcanic"
    },
    {
      "x": -14,
      "y": 5,
      "z": 6,
      "name": "Rock_Volcanic"
    },
    {
      "x": -14,
      "y": 6,
      "z": 6,
      "name": "Rock_Volcanic"
    },
    {
      "x": -14,
      "y": 7,
      "z": 6,
      "name": "Rock_Volcanic"
    },
    {
      "x": -14,
      "y": 8,
      "z": 6,
      "name": "Rock_Volcanic"
    },
    {
      "x": -14,
      "y": 9,
      "z": 6,
      "name": "Rock_Volcanic"
    },
    {
      "x": -14,
      "y": 10,
      "z": 6,
      "name": "Rock_Volcanic"
    },
    {
      "x": -14,
      "y": 11,
      "z": 6,
      "name": "Rock_Volcanic"
    },
    {
      "x": -14,
      "y": 12,
      "z": 6,
      "name": "Rock_Volcanic"
    },
    {
      "x": -14,
      "y": 13,
      "z": 6,
      "name": "Rock_Volcanic"
    },
    {
      "x": -14,
      "y": 14,
      "z": 6,
      "name": "Rock_Volcanic"
    },
    {
      "x": -14,
      "y": 15,
      "z": 6,
      "name": "Rock_Volcanic"
    },
    {
      "x": -14,
      "y": 16,
      "z": 6,
      "name": "Rock_Volcanic"
    },
    {
      "x": -14,
      "y": 17,
      "z": 6,
      "name": "Rock_Volcanic"
    },
    {
      "x": -14,
      "y": 18,
      "z": 6,
      "name": "Rock_Volcanic"
    },
    {
      "x": -14,
      "y": 19,
      "z": 6,
      "name": "Soil_Volcanic_Gravel"
    },
    {
      "x": -14,
      "y": 20,
      "z": 6,
      "name": "Soil_Volcanic_Gravel"
    },
    {
      "x": -14,
      "y": 21,
      "z": 6,
      "name": "Rock_Volcanic"
    },
    {
      "x": -14,
      "y": 4,
      "z": 7,
      "name": "Rock_Volcanic"
    },
    {
      "x": -14,
      "y": 5,
      "z": 7,
      "name": "Rock_Volcanic"
    },
    {
      "x": -14,
      "y": 6,
      "z": 7,
      "name": "Rock_Volcanic"
    },
    {
      "x": -14,
      "y": 7,
      "z": 7,
      "name": "Rock_Volcanic"
    },
    {
      "x": -14,
      "y": 8,
      "z": 7,
      "name": "Rock_Volcanic"
    },
    {
      "x": -14,
      "y": 9,
      "z": 7,
      "name": "Rock_Volcanic"
    },
    {
      "x": -14,
      "y": 10,
      "z": 7,
      "name": "Rock_Volcanic"
    },
    {
      "x": -14,
      "y": 11,
      "z": 7,
      "name": "Rock_Volcanic"
    },
    {
      "x": -14,
      "y": 12,
      "z": 7,
      "name": "Rock_Volcanic"
    },
    {
      "x": -14,
      "y": 13,
      "z": 7,
      "name": "Rock_Volcanic"
    },
    {
      "x": -14,
      "y": 14,
      "z": 7,
      "name": "Rock_Volcanic"
    },
    {
      "x": -14,
      "y": 15,
      "z": 7,
      "name": "Rock_Volcanic"
    },
    {
      "x": -14,
      "y": 16,
      "z": 7,
      "name": "Rock_Volcanic"
    },
    {
      "x": -14,
      "y": 17,
      "z": 7,
      "name": "Rock_Volcanic"
    },
    {
      "x": -14,
      "y": 18,
      "z": 7,
      "name": "Rock_Volcanic"
    },
    {
      "x": -14,
      "y": 19,
      "z": 7,
      "name": "Soil_Volcanic_Gravel"
    },
    {
      "x": -14,
      "y": 20,
      "z": 7,
      "name": "Rock_Volcanic"
    },
    {
      "x": -14,
      "y": 13,
      "z": 8,
      "name": "Rock_Volcanic"
    },
    {
      "x": -14,
      "y": 14,
      "z": 8,
      "name": "Rock_Volcanic"
    },
    {
      "x": -14,
      "y": 15,
      "z": 8,
      "name": "Rock_Volcanic"
    },
    {
      "x": -14,
      "y": 16,
      "z": 8,
      "name": "Rock_Volcanic"
    },
    {
      "x": -14,
      "y": 17,
      "z": 8,
      "name": "Rock_Volcanic"
    },
    {
      "x": -14,
      "y": 18,
      "z": 8,
      "name": "Soil_Volcanic_Gravel"
    },
    {
      "x": -14,
      "y": 19,
      "z": 8,
      "name": "Rock_Volcanic"
    },
    {
      "x": -14,
      "y": 15,
      "z": 9,
      "name": "Rock_Volcanic"
    },
    {
      "x": -14,
      "y": 16,
      "z": 9,
      "name": "Rock_Volcanic"
    },
    {
      "x": -14,
      "y": 17,
      "z": 9,
      "name": "Rock_Volcanic"
    },
    {
      "x": -14,
      "y": 18,
      "z": 9,
      "name": "Rock_Volcanic"
    },
    {
      "x": -14,
      "y": 17,
      "z": 10,
      "name": "Rock_Volcanic"
    },
    {
      "x": -14,
      "y": 18,
      "z": 10,
      "name": "Rock_Volcanic"
    },
    {
      "x": -13,
      "y": 40,
      "z": -12,
      "name": "Rock_Volcanic"
    },
    {
      "x": -13,
      "y": 41,
      "z": -12,
      "name": "Rock_Volcanic"
    },
    {
      "x": -13,
      "y": 38,
      "z": -11,
      "name": "Rock_Volcanic"
    },
    {
      "x": -13,
      "y": 39,
      "z": -11,
      "name": "Rock_Volcanic"
    },
    {
      "x": -13,
      "y": 40,
      "z": -11,
      "name": "Rock_Volcanic"
    },
    {
      "x": -13,
      "y": 41,
      "z": -11,
      "name": "Rock_Volcanic"
    },
    {
      "x": -13,
      "y": 42,
      "z": -11,
      "name": "Rock_Volcanic"
    },
    {
      "x": -13,
      "y": 37,
      "z": -10,
      "name": "Rock_Volcanic"
    },
    {
      "x": -13,
      "y": 38,
      "z": -10,
      "name": "Rock_Volcanic"
    },
    {
      "x": -13,
      "y": 39,
      "z": -10,
      "name": "Rock_Volcanic"
    },
    {
      "x": -13,
      "y": 40,
      "z": -10,
      "name": "Rock_Volcanic"
    },
    {
      "x": -13,
      "y": 41,
      "z": -10,
      "name": "Rock_Volcanic"
    },
    {
      "x": -13,
      "y": 42,
      "z": -10,
      "name": "Soil_Volcanic_Gravel"
    },
    {
