{
  "version": 8,
  "blockIdVersion": 11,
  "anchorX": -1,
  "anchorY": 50,
  "anchorZ": 0,
  "blocks": [
    {
      "x": -10,
      "y": 74,
      "z": -8,
      "name": "Plant_Leaves_Jungle",
      "support": 15
    },
    {
      "x": -10,
      "y": 74,
      "z": -7,
      "name": "Plant_Leaves_Jungle",
      "support": 15
    },
    {
      "x": -10,
      "y": 80,
      "z": -3,
      "name": "Plant_Leaves_Jungle",
      "support": 15
    },
    {
      "x": -10,
      "y": 80,
      "z": -2,
      "name": "Plant_Leaves_Jungle",
      "support": 15
    },
    {
      "x": -10,
      "y": 4,
      "z": -1,
      "name": "Empty"
    },
    {
      "x": -10,
      "y": 3,
      "z": 0,
      "name": "Empty"
    },
    {
      "x": -10,
      "y": 4,
      "z": 0,
      "name": "Empty"
    },
    {
      "x": -10,
      "y": 5,
      "z": 0,
      "name": "Empty"
    },
    {
      "x": -10,
      "y": 81,
      "z": 0,
      "name": "Plant_Leaves_Palm",
      "support": 15
    },
    {
      "x": -10,
      "y": 4,
      "z": 1,
      "name": "Empty"
    },
    {
      "x": -10,
      "y": 5,
      "z": 1,
      "name": "Empty"
    },
    {
      "x": -9,
      "y": 74,
      "z": -9,
      "name": "Plant_Leaves_Jungle",
      "support": 15
    },
    {
      "x": -9,
      "y": 75,
      "z": -9,
      "name": "Plant_Leaves_Jungle",
      "support": 15
    },
    {
      "x": -9,
      "y": 74,
      "z": -8,
      "name": "Plant_Leaves_Jungle",
      "support": 15
    },
    {
      "x": -9,
      "y": 75,
      "z": -8,
      "name": "Plant_Leaves_Jungle",
      "support": 15
    },
    {
      "x": -9,
      "y": 74,
      "z": -7,
      "name": "Plant_Leaves_Jungle",
      "support": 15
    },
    {
      "x": -9,
      "y": 74,
      "z": -6,
      "name": "Plant_Leaves_Jungle",
      "support": 15
    },
    {
      "x": -9,
      "y": 80,
      "z": -3,
      "name": "Plant_Leaves_Jungle",
      "support": 15
    },
    {
      "x": -9,
      "y": 3,
      "z": -2,
      "name": "Empty"
    },
    {
      "x": -9,
      "y": 4,
      "z": -2,
      "name": "Empty"
    },
    {
      "x": -9,
      "y": 5,
      "z": -2,
      "name": "Empty"
    },
    {
      "x": -9,
      "y": 80,
      "z": -2,
      "name": "Plant_Leaves_Jungle",
      "support": 15
    },
    {
      "x": -9,
      "y": 81,
      "z": -2,
      "name": "Plant_Leaves_Jungle",
      "support": 15
    },
    {
      "x": -9,
      "y": 3,
      "z": -1,
      "name": "Empty"
    },
    {
      "x": -9,
      "y": 4,
      "z": -1,
      "name": "Empty"
    },
    {
      "x": -9,
      "y": 5,
      "z": -1,
      "name": "Empty"
    },
    {
      "x": -9,
      "y": 80,
      "z": -1,
      "name": "Plant_Leaves_Jungle",
      "support": 15
    },
    {
      "x": -9,
      "y": 81,
      "z": -1,
      "name": "Plant_Leaves_Palm",
      "support": 15
    },
    {
      "x": -9,
      "y": 3,
      "z": 0,
      "name": "Empty"
    },
    {
      "x": -9,
      "y": 4,
      "z": 0,
      "name": "Empty"
    },
    {
      "x": -9,
      "y": 5,
      "z": 0,
      "name": "Empty"
    },
    {
      "x": -9,
      "y": 6,
      "z": 0,
      "name": "Empty"
    },
    {
      "x": -9,
      "y": 7,
      "z": 0,
      "name": "Empty"
    },
    {
      "x": -9,
      "y": 80,
      "z": 0,
      "name": "Plant_Leaves_Palm",
      "support": 15
    },
    {
      "x": -9,
      "y": 81,
      "z": 0,
      "name": "Plant_Leaves_Palm",
      "support": 15
    },
    {
      "x": -9,
      "y": 82,
      "z": 0,
      "name": "Plant_Leaves_Palm",
      "support": 15
    },
    {
      "x": -9,
      "y": 3,
      "z": 1,
      "name": "Empty"
    },
    {
      "x": -9,
      "y": 4,
      "z": 1,
      "name": "Empty"
    },
    {
      "x": -9,
      "y": 5,
      "z": 1,
      "name": "Empty"
    },
    {
      "x": -9,
      "y": 6,
      "z": 1,
      "name": "Empty"
    },
    {
      "x": -9,
      "y": 7,
      "z": 1,
      "name": "Empty"
    },
    {
      "x": -9,
      "y": 80,
      "z": 1,
      "name": "Plant_Leaves_Jungle",
      "support": 15
    },
    {
      "x": -9,
      "y": 81,
      "z": 1,
      "name": "Plant_Leaves_Palm",
      "support": 15
    },
    {
      "x": -9,
      "y": 4,
      "z": 2,
      "name": "Empty"
    },
    {
      "x": -9,
      "y": 5,
      "z": 2,
      "name": "Empty"
    },
    {
      "x": -9,
      "y": 6,
      "z": 2,
      "name": "Empty"
    },
    {
      "x": -9,
      "y": 80,
      "z": 2,
      "name": "Plant_Leaves_Jungle",
      "support": 15
    },
    {
      "x": -9,
      "y": 79,
      "z": 4,
      "name": "Plant_Leaves_Jungle",
      "support": 15
    },
    {
      "x": -8,
      "y": 74,
      "z": -10,
      "name": "Plant_Leaves_Jungle",
      "support": 15
    },
    {
      "x": -8,
      "y": 74,
      "z": -9,
      "name": "Plant_Leaves_Jungle",
      "support": 15
    },
    {
      "x": -8,
      "y": 75,
      "z": -9,
      "name": "Plant_Leaves_Jungle",
      "support": 15
    },
    {
      "x": -8,
      "y": 74,
      "z": -8,
      "name": "Plant_Leaves_Jungle",
      "support": 15
    },
    {
      "x": -8,
      "y": 75,
      "z": -8,
      "name": "Plant_Leaves_Jungle",
      "support": 15
    },
    {
      "x": -8,
      "y": 74,
      "z": -7,
      "name": "Plant_Leaves_Jungle",
      "support": 15
    },
    {
      "x": -8,
      "y": 75,
      "z": -7,
      "name": "Plant_Leaves_Jungle",
      "support": 15
    },
    {
      "x": -8,
      "y": 74,
      "z": -6,
      "name": "Plant_Leaves_Jungle",
      "support": 15
    },
    {
      "x": -8,
      "y": 75,
      "z": -6,
      "name": "Plant_Leaves_Jungle",
      "support": 15
    },
    {
      "x": -8,
      "y": -5,
      "z": -5,
      "name": "Rock_Magma_Cooled"
    },
    {
      "x": -8,
      "y": -4,
      "z": -5,
      "name": "Rock_Magma_Cooled"
    },
    {
      "x": -8,
      "y": -3,
      "z": -5,
      "name": "Rock_Magma_Cooled"
    },
    {
      "x": -8,
      "y": 74,
      "z": -5,
      "name": "Plant_Leaves_Jungle",
      "support": 15
    },
    {
      "x": -8,
      "y": 80,
      "z": -5,
      "name": "Plant_Leaves_Jungle",
      "support": 15
    },
    {
      "x": -8,
      "y": -5,
      "z": -4,
      "name": "Rock_Magma_Cooled"
    },
    {
      "x": -8,
      "y": -4,
      "z": -4,
      "name": "Rock_Magma_Cooled"
    },
    {
      "x": -8,
      "y": -3,
      "z": -4,
      "name": "Rock_Magma_Cooled"
    },
    {
      "x": -8,
      "y": 80,
      "z": -4,
      "name": "Plant_Leaves_Jungle",
      "support": 15
    },
    {
      "x": -8,
      "y": 81,
      "z": -4,
      "name": "Plant_Leaves_Jungle",
      "support": 15
    },
    {
      "x": -8,
      "y": -5,
      "z": -3,
      "name": "Rock_Magma_Cooled"
    },
    {
      "x": -8,
      "y": -4,
      "z": -3,
      "name": "Rock_Magma_Cooled"
    },
    {
      "x": -8,
      "y": -3,
      "z": -3,
      "name": "Rock_Magma_Cooled"
    },
    {
      "x": -8,
      "y": 81,
      "z": -3,
      "name": "Plant_Leaves_Jungle",
      "support": 15
    },
    {
      "x": -8,
      "y": -6,
      "z": -2,
      "name": "Rock_Magma_Cooled"
    },
    {
      "x": -8,
      "y": -5,
      "z": -2,
      "name": "Rock_Magma_Cooled"
    },
    {
      "x": -8,
      "y": -4,
      "z": -2,
      "name": "Rock_Magma_Cooled"
    },
    {
      "x": -8,
      "y": 3,
      "z": -2,
      "name": "Empty"
    },
    {
      "x": -8,
      "y": 4,
      "z": -2,
      "name": "Empty"
    },
    {
      "x": -8,
      "y": 5,
      "z": -2,
      "name": "Empty"
    },
    {
      "x": -8,
      "y": 6,
      "z": -2,
      "name": "Empty"
    },
    {
      "x": -8,
      "y": 81,
      "z": -2,
      "name": "Plant_Leaves_Jungle",
      "support": 15
    },
    {
      "x": -8,
      "y": -6,
      "z": -1,
      "name": "Rock_Magma_Cooled"
    },
    {
      "x": -8,
      "y": -5,
      "z": -1,
      "name": "Rock_Magma_Cooled"
    },
    {
      "x": -8,
      "y": -4,
      "z": -1,
      "name": "Rock_Magma_Cooled"
    },
    {
      "x": -8,
      "y": 3,
      "z": -1,
      "name": "Empty"
    },
    {
      "x": -8,
      "y": 4,
      "z": -1,
      "name": "Empty"
    },
    {
      "x": -8,
      "y": 5,
      "z": -1,
      "name": "Empty"
    },
    {
      "x": -8,
      "y": 6,
      "z": -1,
      "name": "Empty"
    },
    {
      "x": -8,
      "y": 7,
      "z": -1,
      "name": "Empty"
    },
    {
      "x": -8,
      "y": 80,
      "z": -1,
      "name": "Plant_Leaves_Jungle",
      "support": 15
    },
    {
      "x": -8,
      "y": 81,
      "z": -1,
      "name": "Plant_Leaves_Jungle",
      "support": 15
    },
    {
      "x": -8,
      "y": 82,
      "z": -1,
      "name": "Plant_Leaves_Jungle",
      "support": 15
    },
    {
      "x": -8,
      "y": -6,
      "z": 0,
      "name": "Rock_Magma_Cooled"
    },
    {
      "x": -8,
      "y": -5,
      "z": 0,
      "name": "Rock_Magma_Cooled"
    },
    {
      "x": -8,
      "y": 3,
      "z": 0,
      "name": "Empty"
    },
    {
      "x": -8,
      "y": 4,
      "z": 0,
      "name": "Empty"
    },
    {
      "x": -8,
      "y": 5,
      "z": 0,
      "name": "Empty"
    },
    {
      "x": -8,
      "y": 6,
      "z": 0,
      "name": "Empty"
    },
    {
      "x": -8,
      "y": 7,
      "z": 0,
      "name": "Empty"
    },
    {
      "x": -8,
      "y": 75,
      "z": 0,
      "name": "Plant_Leaves_Palm_Oasis",
      "support": 15
    },
    {
      "x": -8,
      "y": 76,
      "z": 0,
      "name": "Wood_Jungle_Branch_Long",
      "support": 15
    },
    {
      "x": -8,
      "y": 77,
      "z": 0,
      "name": "Wood_Jungle_Branch_Long",
      "support": 15
    },
    {
      "x": -8,
      "y": 78,
      "z": 0,
      "name": "Wood_Jungle_Branch_Long",
      "support": 15
    },
    {
      "x": -8,
      "y": 79,
      "z": 0,
      "name": "Wood_Jungle_Branch_Long",
      "support": 15
    },
    {
      "x": -8,
      "y": 80,
      "z": 0,
      "name": "Wood_Jungle_Trunk",
      "support": 15
    },
    {
      "x": -8,
      "y": 81,
      "z": 0,
      "name": "Plant_Leaves_Jungle",
      "support": 15
    },
    {
      "x": -8,
      "y": 82,
      "z": 0,
      "name": "Plant_Leaves_Jungle",
      "support": 15
    },
    {
      "x": -8,
      "y": 3,
      "z": 1,
      "name": "Empty"
    },
    {
      "x": -8,
      "y": 4,
      "z": 1,
      "name": "Empty"
    },
    {
      "x": -8,
      "y": 5,
      "z": 1,
      "name": "Empty"
    },
    {
      "x": -8,
      "y": 6,
      "z": 1,
      "name": "Empty"
    },
    {
      "x": -8,
      "y": 7,
      "z": 1,
      "name": "Empty"
    },
    {
      "x": -8,
      "y": 81,
      "z": 1,
      "name": "Plant_Leaves_Jungle",
      "support": 15
    },
    {
      "x": -8,
      "y": 3,
      "z": 2,
      "name": "Empty"
    },
    {
      "x": -8,
      "y": 4,
      "z": 2,
      "name": "Empty"
    },
    {
      "x": -8,
      "y": 5,
      "z": 2,
      "name": "Empty"
    },
    {
      "x": -8,
      "y": 6,
      "z": 2,
      "name": "Empty"
    },
    {
      "x": -8,
      "y": 7,
      "z": 2,
      "name": "Empty"
    },
    {
      "x": -8,
      "y": 80,
      "z": 2,
      "name": "Plant_Leaves_Jungle",
      "support": 15
    },
    {
      "x": -8,
      "y": 81,
      "z": 2,
      "name": "Plant_Leaves_Jungle",
      "support": 15
    },
    {
      "x": -8,
      "y": 80,
      "z": 3,
      "name": "Plant_Leaves_Jungle",
      "support": 15
    },
    {
      "x": -8,
      "y": 79,
      "z": 4,
      "name": "Plant_Leaves_Jungle",
      "support": 15
    },
    {
      "x": -8,
      "y": 80,
      "z": 4,
      "name": "Plant_Leaves_Jungle",
      "support": 15
    },
    {
      "x": -8,
      "y": 79,
      "z": 5,
      "name": "Plant_Leaves_Jungle",
      "support": 15
    },
    {
      "x": -7,
      "y": 74,
      "z": -10,
      "name": "Plant_Leaves_Jungle",
      "support": 15
    },
    {
      "x": -7,
      "y": 74,
      "z": -9,
      "name": "Plant_Leaves_Jungle",
      "support": 15
    },
    {
      "x": -7,
      "y": 75,
      "z": -9,
      "name": "Plant_Leaves_Jungle",
      "support": 15
    },
    {
      "x": -7,
      "y": 60,
      "z": -8,
      "name": "Plant_Leaves_Palm_Oasis",
      "support": 15
    },
    {
      "x": -7,
      "y": 61,
      "z": -8,
      "name": "Wood_Jungle_Branch_Long",
      "support": 15
    },
    {
      "x": -7,
      "y": 62,
      "z": -8,
      "name": "Wood_Jungle_Branch_Long",
      "support": 15
    },
    {
      "x": -7,
      "y": 63,
      "z": -8,
      "name": "Wood_Jungle_Branch_Long",
      "support": 15
    },
    {
      "x": -7,
      "y": 64,
      "z": -8,
      "name": "Wood_Jungle_Branch_Long",
      "support": 15
    },
    {
      "x": -7,
      "y": 65,
      "z": -8,
      "name": "Wood_Jungle_Branch_Long",
      "support": 15
    },
    {
      "x": -7,
      "y": 66,
      "z": -8,
      "name": "Wood_Jungle_Branch_Long",
      "support": 15
    },
    {
      "x": -7,
      "y": 67,
      "z": -8,
      "name": "Wood_Jungle_Branch_Long",
      "support": 15
    },
    {
      "x": -7,
      "y": 68,
      "z": -8,
      "name": "Wood_Jungle_Branch_Long",
      "support": 15
    },
    {
      "x": -7,
      "y": 69,
      "z": -8,
      "name": "Wood_Jungle_Branch_Long",
      "support": 15
    },
    {
      "x": -7,
      "y": 70,
      "z": -8,
      "name": "Wood_Jungle_Branch_Long",
      "support": 15
    },
    {
      "x": -7,
      "y": 71,
      "z": -8,
      "name": "Wood_Jungle_Branch_Long",
      "support": 15
    },
    {
      "x": -7,
      "y": 72,
      "z": -8,
      "name": "Wood_Jungle_Branch_Long",
      "support": 15
    },
    {
      "x": -7,
      "y": 73,
      "z": -8,
      "name": "Wood_Jungle_Trunk",
      "support": 15
    },
    {
      "x": -7,
      "y": 74,
      "z": -8,
      "name": "Wood_Jungle_Trunk",
      "support": 15
    },
    {
      "x": -7,
      "y": 75,
      "z": -8,
      "name": "Plant_Leaves_Jungle",
      "support": 15
    },
    {
      "x": -7,
      "y": 73,
      "z": -7,
      "name": "Wood_Jungle_Trunk",
      "support": 15
    },
    {
      "x": -7,
      "y": 74,
      "z": -7,
      "name": "Plant_Leaves_Jungle",
      "support": 15
    },
    {
      "x": -7,
      "y": 75,
      "z": -7,
      "name": "Plant_Leaves_Jungle",
      "support": 15
    },
    {
      "x": -7,
      "y": -5,
      "z": -6,
      "name": "Rock_Magma_Cooled"
    },
    {
      "x": -7,
      "y": -4,
      "z": -6,
      "name": "Rock_Magma_Cooled"
    },
    {
      "x": -7,
      "y": -3,
      "z": -6,
      "name": "Rock_Magma_Cooled"
    },
    {
      "x": -7,
      "y": 74,
      "z": -6,
      "name": "Plant_Leaves_Jungle",
      "support": 15
    },
    {
      "x": -7,
      "y": 80,
      "z": -6,
      "name": "Plant_Leaves_Jungle",
      "support": 15
    },
    {
      "x": -7,
      "y": -6,
      "z": -5,
      "name": "Rock_Magma_Cooled"
    },
    {
      "x": -7,
      "y": -5,
      "z": -5,
      "name": "Rock_Magma_Cooled"
    },
    {
      "x": -7,
      "y": -4,
      "z": -5,
      "name": "Rock_Magma_Cooled"
    },
    {
      "x": -7,
      "y": -3,
      "z": -5,
      "name": "Rock_Magma_Cooled"
    },
    {
      "x": -7,
      "y": -2,
      "z": -5,
      "name": "Rock_Magma_Cooled"
    },
    {
      "x": -7,
      "y": 73,
      "z": -5,
      "name": "Plant_Leaves_Jungle",
      "support": 15
    },
    {
      "x": -7,
      "y": 74,
      "z": -5,
      "name": "Plant_Leaves_Jungle",
      "support": 15
    },
    {
      "x": -7,
      "y": 80,
      "z": -5,
      "name": "Plant_Leaves_Jungle",
      "support": 15
    },
    {
      "x": -7,
      "y": -6,
      "z": -4,
      "name": "Rock_Magma_Cooled"
    },
    {
      "x": -7,
      "y": -5,
      "z": -4,
      "name": "Rock_Magma_Cooled"
    },
    {
      "x": -7,
      "y": -4,
      "z": -4,
      "name": "Rock_Magma_Cooled"
    },
    {
      "x": -7,
      "y": -3,
      "z": -4,
      "name": "Rock_Magma_Cooled"
    },
    {
      "x": -7,
      "y": -2,
      "z": -4,
      "name": "Rock_Magma_Cooled"
    },
    {
      "x": -7,
      "y": 73,
      "z": -4,
      "name": "Plant_Leaves_Jungle",
      "support": 15
    },
    {
      "x": -7,
      "y": 74,
      "z": -4,
      "name": "Plant_Leaves_Jungle",
      "support": 15
    },
    {
      "x": -7,
      "y": 80,
      "z": -4,
      "name": "Wood_Jungle_Branch_Long",
      "support": 15,
      "rotation": 4
    },
    {
      "x": -7,
      "y": 81,
      "z": -4,
      "name": "Plant_Leaves_Jungle",
      "support": 15
    },
    {
      "x": -7,
      "y": -6,
      "z": -3,
      "name": "Rock_Magma_Cooled"
    },
    {
      "x": -7,
      "y": -5,
      "z": -3,
      "name": "Rock_Magma_Cooled"
    },
    {
      "x": -7,
      "y": -4,
      "z": -3,
      "name": "Rock_Magma_Cooled"
    },
    {
      "x": -7,
      "y": -3,
      "z": -3,
      "name": "Rock_Magma_Cooled"
    },
    {
      "x": -7,
      "y": -2,
      "z": -3,
      "name": "Rock_Magma_Cooled"
    },
    {
      "x": -7,
      "y": 80,
      "z": -3,
      "name": "Wood_Jungle_Branch_Long",
      "support": 15,
      "rotation": 4
    },
    {
      "x": -7,
      "y": 81,
      "z": -3,
      "name": "Plant_Leaves_Jungle",
      "support": 15
    },
    {
      "x": -7,
      "y": -7,
      "z": -2,
      "name": "Rock_Magma_Cooled"
    },
    {
      "x": -7,
      "y": -6,
      "z": -2,
      "name": "Rock_Magma_Cooled"
    },
    {
      "x": -7,
      "y": -5,
      "z": -2,
      "name": "Rock_Magma_Cooled"
    },
    {
      "x": -7,
      "y": -4,
      "z": -2,
      "name": "Rock_Magma_Cooled"
    },
    {
      "x": -7,
      "y": -3,
      "z": -2,
      "name": "Rock_Magma_Cooled"
    },
    {
      "x": -7,
      "y": -2,
      "z": -2,
      "name": "Rock_Magma_Cooled"
    },
    {
      "x": -7,
      "y": 3,
      "z": -2,
      "name": "Empty"
    },
    {
      "x": -7,
      "y": 4,
      "z": -2,
      "name": "Empty"
    },
    {
      "x": -7,
      "y": 5,
      "z": -2,
      "name": "Empty"
    },
    {
      "x": -7,
      "y": 80,
      "z": -2,
      "name": "Wood_Jungle_Branch_Long",
      "support": 15,
      "rotation": 4
    },
    {
      "x": -7,
      "y": 81,
      "z": -2,
      "name": "Plant_Leaves_Jungle",
      "support": 15
    },
    {
      "x": -7,
      "y": 82,
      "z": -2,
      "name": "Plant_Leaves_Jungle",
      "support": 15
    },
    {
      "x": -7,
      "y": -7,
      "z": -1,
      "name": "Rock_Magma_Cooled"
    },
    {
      "x": -7,
      "y": -6,
      "z": -1,
      "name": "Rock_Magma_Cooled"
    },
    {
      "x": -7,
      "y": -5,
      "z": -1,
      "name": "Rock_Magma_Cooled"
    },
    {
      "x": -7,
      "y": -4,
      "z": -1,
      "name": "Rock_Magma_Cooled"
    },
    {
      "x": -7,
      "y": -3,
      "z": -1,
      "name": "Rock_Basalt"
    },
    {
      "x": -7,
      "y": -2,
      "z": -1,
      "name": "Rock_Basalt"
    },
    {
      "x": -7,
      "y": 3,
      "z": -1,
      "name": "Empty"
    },
    {
      "x": -7,
      "y": 4,
      "z": -1,
      "name": "Empty"
    },
    {
      "x": -7,
      "y": 5,
      "z": -1,
      "name": "Empty"
    },
    {
      "x": -7,
      "y": 6,
      "z": -1,
      "name": "Empty"
    },
    {
      "x": -7,
      "y": 7,
      "z": -1,
      "name": "Empty"
    },
    {
      "x": -7,
      "y": 80,
      "z": -1,
      "name": "Wood_Jungle_Branch_Long",
      "support": 15,
      "rotation": 4
    },
    {
      "x": -7,
      "y": 81,
      "z": -1,
      "name": "Plant_Leaves_Jungle",
      "support": 15
    },
    {
      "x": -7,
      "y": 82,
      "z": -1,
      "name": "Plant_Leaves_Jungle",
      "support": 15
    },
    {
      "x": -7,
      "y": -7,
      "z": 0,
      "name": "Rock_Magma_Cooled"
    },
    {
      "x": -7,
      "y": -6,
      "z": 0,
      "name": "Rock_Magma_Cooled"
    },
    {
      "x": -7,
      "y": -5,
      "z": 0,
      "name": "Rock_Magma_Cooled"
    },
    {
      "x": -7,
      "y": -4,
      "z": 0,
      "name": "Rock_Magma_Cooled"
    },
    {
      "x": -7,
      "y": -3,
      "z": 0,
      "name": "Rock_Magma_Cooled"
    },
    {
      "x": -7,
      "y": 3,
      "z": 0,
      "name": "Empty"
    },
    {
      "x": -7,
      "y": 4,
      "z": 0,
      "name": "Empty"
    },
    {
      "x": -7,
      "y": 5,
      "z": 0,
      "name": "Empty"
    },
    {
      "x": -7,
      "y": 6,
      "z": 0,
      "name": "Empty"
    },
    {
      "x": -7,
      "y": 7,
      "z": 0,
      "name": "Empty"
    },
    {
      "x": -7,
      "y": 80,
      "z": 0,
      "name": "Wood_Jungle_Trunk",
      "support": 15
    },
    {
      "x": -7,
      "y": 81,
      "z": 0,
      "name": "Plant_Leaves_Jungle",
      "support": 15
    },
    {
      "x": -7,
      "y": -6,
      "z": 1,
      "name": "Rock_Magma_Cooled"
    },
    {
      "x": -7,
      "y": -5,
      "z": 1,
      "name": "Rock_Magma_Cooled"
    },
    {
      "x": -7,
      "y": -4,
      "z": 1,
      "name": "Rock_Magma_Cooled"
    },
    {
      "x": -7,
      "y": 3,
      "z": 1,
      "name": "Empty"
    },
    {
      "x": -7,
      "y": 4,
      "z": 1,
      "name": "Empty"
    },
    {
      "x": -7,
      "y": 5,
      "z": 1,
      "name": "Empty"
    },
    {
      "x": -7,
      "y": 6,
      "z": 1,
      "name": "Empty"
    },
    {
      "x": -7,
      "y": 7,
      "z": 1,
      "name": "Empty"
    },
    {
      "x": -7,
      "y": 78,
      "z": 1,
      "name": "Wood_Jungle_Branch_Corner",
      "support": 15,
      "rotation": 3
    },
    {
      "x": -7,
      "y": 79,
      "z": 1,
      "name": "Wood_Jungle_Branch_Corner",
      "support": 15,
      "rotation": 8
    },
    {
      "x": -7,
      "y": 81,
      "z": 1,
      "name": "Plant_Leaves_Jungle",
      "support": 15
    },
    {
      "x": -7,
      "y": -5,
      "z": 2,
      "name": "Rock_Magma_Cooled"
    },
    {
      "x": -7,
      "y": -4,
      "z": 2,
      "name": "Rock_Magma_Cooled"
    },
    {
      "x": -7,
      "y": 3,
      "z": 2,
      "name": "Empty"
    },
    {
      "x": -7,
      "y": 4,
      "z": 2,
      "name": "Empty"
    },
    {
      "x": -7,
      "y": 5,
      "z": 2,
      "name": "Empty"
    },
    {
      "x": -7,
      "y": 6,
      "z": 2,
      "name": "Empty"
    },
    {
      "x": -7,
      "y": 7,
      "z": 2,
      "name": "Empty"
    },
    {
      "x": -7,
      "y": 79,
      "z": 2,
      "name": "Wood_Jungle_Branch_Long",
      "support": 15,
      "rotation": 4
    },
    {
      "x": -7,
      "y": 81,
      "z": 2,
      "name": "Plant_Leaves_Jungle",
      "support": 15
    },
    {
      "x": -7,
      "y": -5,
      "z": 3,
      "name": "Rock_Magma_Cooled"
    },
    {
      "x": -7,
      "y": -4,
      "z": 3,
      "name": "Rock_Magma_Cooled"
    },
    {
      "x": -7,
      "y": 79,
      "z": 3,
      "name": "Wood_Jungle_Branch_Long",
      "support": 15,
      "rotation": 4
    },
    {
      "x": -7,
      "y": 80,
      "z": 3,
      "name": "Plant_Leaves_Jungle",
      "support": 15
    },
    {
      "x": -7,
      "y": -5,
      "z": 4,
      "name": "Rock_Magma_Cooled"
    },
    {
      "x": -7,
      "y": -4,
      "z": 4,
      "name": "Rock_Magma_Cooled"
    },
    {
      "x": -7,
      "y": 79,
      "z": 4,
      "name": "Wood_Jungle_Branch_Long",
      "support": 15,
      "rotation": 4
    },
    {
      "x": -7,
      "y": 80,
      "z": 4,
      "name": "Plant_Leaves_Jungle",
      "support": 15
    },
    {
      "x": -7,
      "y": 79,
      "z": 5,
      "name": "Plant_Leaves_Jungle",
      "support": 15
    },
    {
      "x": -7,
      "y": 79,
      "z": 6,
      "name": "Plant_Leaves_Jungle",
      "support": 15
    },
    {
      "x": -6,
      "y": 74,
      "z": -11,
      "name": "Plant_Leaves_Jungle",
      "support": 15
    },
    {
      "x": -6,
      "y": 74,
      "z": -10,
      "name": "Plant_Leaves_Jungle",
      "support": 15
    },
    {
      "x": -6,
      "y": 75,
      "z": -10,
      "name": "Plant_Leaves_Jungle",
      "support": 15
    },
    {
      "x": -6,
      "y": 74,
      "z": -9,
      "name": "Plant_Leaves_Jungle",
      "support": 15
    },
    {
      "x": -6,
      "y": 75,
      "z": -9,
      "name": "Plant_Leaves_Jungle",
      "support": 15
    },
    {
      "x": -6,
      "y": 73,
      "z": -8,
      "name": "Plant_Leaves_Jungle",
      "support": 15
    },
    {
      "x": -6,
      "y": 74,
      "z": -8,
      "name": "Plant_Leaves_Jungle",
      "support": 15
    },
    {
      "x": -6,
      "y": 75,
      "z": -8,
      "name": "Plant_Leaves_Jungle",
      "support": 15
    },
    {
      "x": -6,
      "y": -5,
      "z": -7,
      "name": "Rock_Magma_Cooled"
    },
    {
      "x": -6,
      "y": -4,
      "z": -7,
      "name": "Rock_Magma_Cooled"
    },
    {
      "x": -6,
      "y": -3,
      "z": -7,
      "name": "Rock_Magma_Cooled"
    },
    {
      "x": -6,
      "y": 73,
      "z": -7,
      "name": "Wood_Jungle_Trunk",
      "support": 15
    },
    {
      "x": -6,
      "y": 74,
      "z": -7,
      "name": "Plant_Leaves_Jungle",
      "support": 15
    },
    {
      "x": -6,
      "y": 75,
      "z": -7,
      "name": "Plant_Leaves_Jungle",
      "support": 15
    },
    {
      "x": -6,
      "y": -6,
      "z": -6,
      "name": "Rock_Magma_Cooled"
    },
    {
      "x": -6,
      "y": -5,
      "z": -6,
      "name": "Rock_Magma_Cooled"
    },
    {
      "x": -6,
      "y": -4,
      "z": -6,
      "name": "Rock_Magma_Cooled"
    },
    {
      "x": -6,
      "y": -3,
      "z": -6,
      "name": "Rock_Magma_Cooled"
    },
    {
      "x": -6,
      "y": -2,
      "z": -6,
      "name": "Rock_Magma_Cooled"
    },
    {
      "x": -6,
      "y": 73,
      "z": -6,
      "name": "Wood_Jungle_Trunk",
      "support": 15
    },
    {
      "x": -6,
      "y": 74,
      "z": -6,
      "name": "Plant_Leaves_Jungle",
      "support": 15
    },
    {
      "x": -6,
      "y": -7,
      "z": -5,
      "name": "Rock_Magma_Cooled"
    },
    {
      "x": -6,
      "y": -6,
      "z": -5,
      "name": "Rock_Magma_Cooled"
    },
    {
      "x": -6,
      "y": -5,
      "z": -5,
      "name": "Rock_Magma_Cooled"
    },
    {
      "x": -6,
      "y": -4,
      "z": -5,
      "name": "Rock_Magma_Cooled"
    },
    {
      "x": -6,
      "y": -3,
      "z": -5,
      "name": "Rock_Magma_Cooled"
    },
    {
      "x": -6,
      "y": -2,
      "z": -5,
      "name": "Rock_Magma_Cooled"
    },
    {
      "x": -6,
      "y": -1,
      "z": -5,
      "name": "Rock_Magma_Cooled"
    },
    {
      "x": -6,
      "y": 73,
      "z": -5,
      "name": "Plant_Leaves_Jungle",
      "support": 15
    },
    {
      "x": -6,
      "y": 74,
      "z": -5,
      "name": "Plant_Leaves_Jungle",
      "support": 15
    },
    {
      "x": -6,
      "y": 81,
      "z": -5,
      "name": "Plant_Leaves_Jungle",
      "support": 15
    },
    {
      "x": -6,
      "y": -7,
      "z": -4,
      "name": "Rock_Magma_Cooled"
    },
    {
      "x": -6,
      "y": -6,
      "z": -4,
      "name": "Rock_Magma_Cooled"
    },
    {
      "x": -6,
      "y": -5,
      "z": -4,
      "name": "Rock_Magma_Cooled"
    },
    {
      "x": -6,
      "y": -4,
      "z": -4,
      "name": "Rock_Magma_Cooled"
    },
    {
      "x": -6,
      "y": -3,
      "z": -4,
      "name": "Rock_Magma_Cooled"
    },
    {
      "x": -6,
      "y": -2,
      "z": -4,
      "name": "Rock_Magma_Cooled"
    },
    {
      "x": -6,
      "y": -1,
      "z": -4,
      "name": "Rock_Magma_Cooled"
    },
    {
      "x": -6,
      "y": 73,
      "z": -4,
      "name": "Plant_Leaves_Jungle",
      "support": 15
    },
    {
      "x": -6,
      "y": 74,
      "z": -4,
      "name": "Plant_Leaves_Jungle",
      "support": 15
    },
    {
      "x": -6,
      "y": 81,
      "z": -4,
      "name": "Plant_Leaves_Jungle",
      "support": 15
    },
    {
      "x": -6,
      "y": -7,
      "z": -3,
      "name": "Rock_Magma_Cooled"
    },
    {
      "x": -6,
      "y": -6,
      "z": -3,
      "name": "Rock_Magma_Cooled"
    },
    {
      "x": -6,
      "y": -5,
      "z": -3,
      "name": "Rock_Magma_Cooled"
    },
    {
      "x": -6,
      "y": -4,
      "z": -3,
      "name": "Rock_Magma_Cooled"
    },
    {
      "x": -6,
      "y": -3,
      "z": -3,
      "name": "Rock_Basalt"
    },
    {
      "x": -6,
      "y": -2,
      "z": -3,
      "name": "Rock_Magma_Cooled"
    },
    {
      "x": -6,
      "y": -1,
      "z": -3,
      "name": "Rock_Magma_Cooled"
    },
    {
      "x": -6,
      "y": 73,
      "z": -3,
      "name": "Plant_Leaves_Jungle",
      "support": 15
    },
    {
      "x": -6,
      "y": 81,
      "z": -3,
      "name": "Plant_Leaves_Jungle",
      "support": 15
    },
    {
      "x": -6,
      "y": -8,
      "z": -2,
      "name": "Rock_Magma_Cooled"
    },
    {
      "x": -6,
      "y": -7,
      "z": -2,
      "name": "Rock_Magma_Cooled"
    },
    {
      "x": -6,
      "y": -6,
      "z": -2,
      "name": "Rock_Magma_Cooled"
    },
    {
      "x": -6,
      "y": -5,
      "z": -2,
      "name": "Rock_Magma_Cooled"
    },
    {
      "x": -6,
      "y": -4,
      "z": -2,
      "name": "Rock_Magma_Cooled"
    },
    {
      "x": -6,
      "y": -3,
      "z": -2,
      "name": "Rock_Magma_Cooled"
    },
    {
      "x": -6,
      "y": -2,
      "z": -2,
      "name": "Rock_Basalt"
    },
    {
      "x": -6,
      "y": -1,
      "z": -2,
      "name": "Rock_Basalt"
    },
    {
      "x": -6,
      "y": 3,
      "z": -2,
      "name": "Empty"
    },
    {
      "x": -6,
      "y": 4,
      "z": -2,
      "name": "Empty"
    },
    {
      "x": -6,
      "y": 5,
      "z": -2,
      "name": "Empty"
    },
    {
      "x": -6,
      "y": 71,
      "z": -2,
      "name": "Plant_Leaves_Jungle",
      "support": 15
    },
    {
      "x": -6,
      "y": 80,
      "z": -2,
      "name": "Plant_Leaves_Jungle",
      "support": 15
    },
    {
      "x": -6,
      "y": -8,
      "z": -1,
      "name": "Rock_Magma_Cooled"
    },
    {
      "x": -6,
      "y": -7,
      "z": -1,
      "name": "Rock_Magma_Cooled"
    },
    {
      "x": -6,
      "y": -6,
      "z": -1,
      "name": "Rock_Magma_Cooled"
    },
    {
      "x": -6,
      "y": -5,
      "z": -1,
      "name": "Rock_Magma_Cooled"
    },
    {
      "x": -6,
      "y": -4,
      "z": -1,
      "name": "Rock_Magma_Cooled"
    },
    {
      "x": -6,
      "y": -3,
      "z": -1,
      "name": "Rock_Magma_Cooled"
    },
    {
      "x": -6,
      "y": -2,
      "z": -1,
      "name": "Rock_Basalt"
    },
    {
      "x": -6,
      "y": -1,
      "z": -1,
      "name": "Rock_Basalt"
    },
    {
      "x": -6,
      "y": 0,
      "z": -1,
      "name": "Rock_Basalt"
    },
    {
      "x": -6,
      "y": 3,
      "z": -1,
      "name": "Empty"
    },
    {
      "x": -6,
      "y": 4,
      "z": -1,
      "name": "Empty"
    },
    {
      "x": -6,
      "y": 5,
      "z": -1,
      "name": "Empty"
    },
    {
      "x": -6,
      "y": 6,
      "z": -1,
      "name": "Empty"
    },
    {
      "x": -6,
      "y": 80,
      "z": -1,
      "name": "Plant_Leaves_Jungle",
      "support": 15
    },
    {
      "x": -6,
      "y": 81,
      "z": -1,
      "name": "Plant_Leaves_Jungle",
      "support": 15
    },
    {
      "x": -6,
      "y": 82,
      "z": -1,
      "name": "Plant_Leaves_Jungle",
      "support": 15
    },
    {
      "x": -6,
      "y": -8,
      "z": 0,
      "name": "Rock_Magma_Cooled"
    },
    {
      "x": -6,
      "y": -7,
      "z": 0,
      "name": "Rock_Magma_Cooled"
    },
    {
      "x": -6,
      "y": -6,
      "z": 0,
      "name": "Rock_Magma_Cooled"
    },
    {
      "x": -6,
      "y": -5,
      "z": 0,
      "name": "Rock_Magma_Cooled"
    },
    {
      "x": -6,
      "y": -4,
      "z": 0,
      "name": "Rock_Magma_Cooled"
    },
    {
      "x": -6,
      "y": -3,
      "z": 0,
      "name": "Rock_Magma_Cooled"
    },
    {
      "x": -6,
      "y": -2,
      "z": 0,
      "name": "Rock_Magma_Cooled"
    },
    {
      "x": -6,
      "y": -1,
      "z": 0,
      "name": "Rock_Magma_Cooled"
    },
    {
      "x": -6,
      "y": 0,
      "z": 0,
      "name": "Rock_Basalt"
    },
    {
      "x": -6,
      "y": 3,
      "z": 0,
      "name": "Empty"
    },
    {
      "x": -6,
      "y": 4,
      "z": 0,
      "name": "Empty"
    },
    {
      "x": -6,
      "y": 5,
      "z": 0,
      "name": "Empty"
    },
    {
      "x": -6,
      "y": 6,
      "z": 0,
      "name": "Empty"
    },
    {
      "x": -6,
      "y": 7,
      "z": 0,
      "name": "Empty"
    },
    {
      "x": -6,
      "y": 79,
      "z": 0,
      "name": "Wood_Jungle_Trunk",
      "support": 15
    },
    {
      "x": -6,
      "y": 80,
      "z": 0,
      "name": "Wood_Jungle_Trunk",
      "support": 15
    },
    {
      "x": -6,
      "y": 81,
      "z": 0,
      "name": "Plant_Leaves_Jungle",
      "support": 15
    },
    {
      "x": -6,
      "y": -7,
      "z": 1,
      "name": "Rock_Magma_Cooled"
    },
    {
      "x": -6,
      "y": -6,
      "z": 1,
      "name": "Rock_Magma_Cooled"
    },
    {
      "x": -6,
      "y": -5,
      "z": 1,
      "name": "Rock_Magma_Cooled"
    },
    {
      "x": -6,
      "y": -4,
      "z": 1,
      "name": "Rock_Magma_Cooled"
    },
    {
      "x": -6,
      "y": -3,
      "z": 1,
      "name": "Rock_Magma_Cooled"
    },
    {
      "x": -6,
      "y": -2,
      "z": 1,
      "name": "Rock_Magma_Cooled"
    },
    {
      "x": -6,
      "y": -1,
      "z": 1,
      "name": "Rock_Magma_Cooled"
    },
    {
      "x": -6,
      "y": 3,
      "z": 1,
      "name": "Empty"
    },
    {
      "x": -6,
      "y": 4,
      "z": 1,
      "name": "Empty"
    },
    {
      "x": -6,
      "y": 5,
      "z": 1,
      "name": "Empty"
    },
    {
      "x": -6,
      "y": 6,
      "z": 1,
      "name": "Empty"
    },
    {
      "x": -6,
      "y": 78,
      "z": 1,
      "name": "Wood_Jungle_Branch_Long",
      "support": 15,
      "rotation": 5
    },
    {
      "x": -6,
      "y": 80,
      "z": 1,
      "name": "Plant_Leaves_Jungle",
      "support": 15
    },
    {
      "x": -6,
      "y": 81,
      "z": 1,
      "name": "Plant_Leaves_Jungle",
      "support": 15
    },
    {
      "x": -6,
      "y": -6,
      "z": 2,
      "name": "Rock_Magma_Cooled"
    },
    {
      "x": -6,
      "y": -5,
      "z": 2,
      "name": "Rock_Magma_Cooled"
    },
    {
      "x": -6,
      "y": -4,
      "z": 2,
      "name": "Rock_Magma_Cooled"
    },
    {
      "x": -6,
      "y": -3,
      "z": 2,
      "name": "Rock_Magma_Cooled"
    },
    {
      "x": -6,
      "y": -2,
      "z": 2,
      "name": "Rock_Magma_Cooled"
    },
    {
      "x": -6,
      "y": -1,
      "z": 2,
      "name": "Rock_Magma_Cooled"
    },
    {
      "x": -6,
      "y": 4,
      "z": 2,
      "name": "Empty"
    },
    {
      "x": -6,
      "y": 5,
      "z": 2,
      "name": "Empty"
    },
    {
      "x": -6,
      "y": 6,
      "z": 2,
      "name": "Empty"
    },
    {
      "x": -6,
      "y": 80,
      "z": 2,
      "name": "Plant_Leaves_Jungle",
      "support": 15
    },
    {
      "x": -6,
      "y": 81,
      "z": 2,
      "name": "Plant_Leaves_Jungle",
      "support": 15
    },
    {
      "x": -6,
      "y": -6,
      "z": 3,
      "name": "Rock_Magma_Cooled"
    },
    {
      "x": -6,
      "y": -5,
      "z": 3,
      "name": "Rock_Magma_Cooled"
    },
    {
      "x": -6,
      "y": -4,
      "z": 3,
      "name": "Rock_Magma_Cooled"
    },
    {
      "x": -6,
      "y": -3,
      "z": 3,
      "name": "Rock_Magma_Cooled"
    },
    {
      "x": -6,
      "y": -2,
      "z": 3,
      "name": "Rock_Magma_Cooled"
    },
    {
      "x": -6,
      "y": 80,
      "z": 3,
      "name": "Plant_Leaves_Jungle",
      "support": 15
    },
    {
      "x": -6,
      "y": 81,
      "z": 3,
      "name": "Plant_Leaves_Jungle",
      "support": 15
    },
    {
      "x": -6,
      "y": -5,
      "z": 4,
      "name": "Rock_Magma_Cooled"
    },
    {
      "x": -6,
      "y": -4,
      "z": 4,
      "name": "Rock_Magma_Cooled"
    },
    {
      "x": -6,
      "y": -3,
      "z": 4,
      "name": "Rock_Magma_Cooled"
    },
    {
      "x": -6,
      "y": -2,
      "z": 4,
      "name": "Rock_Magma_Cooled"
    },
    {
      "x": -6,
      "y": 80,
      "z": 4,
      "name": "Plant_Leaves_Jungle",
      "support": 15
    },
    {
      "x": -6,
      "y": -4,
      "z": 5,
      "name": "Rock_Magma_Cooled"
    },
    {
      "x": -6,
      "y": -3,
      "z": 5,
      "name": "Rock_Magma_Cooled"
    },
    {
      "x": -6,
      "y": 80,
      "z": 5,
      "name": "Plant_Leaves_Jungle",
      "support": 15
    },
    {
      "x": -6,
      "y": 80,
      "z": 6,
      "name": "Plant_Leaves_Jungle",
      "support": 15
    },
    {
      "x": -6,
      "y": 80,
      "z": 8,
      "name": "Plant_Leaves_Jungle",
      "support": 15
    },
    {
      "x": -5,
      "y": 74,
      "z": -10,
      "name": "Plant_Leaves_Jungle",
      "support": 15
    },
    {
      "x": -5,
      "y": 74,
      "z": -9,
      "name": "Plant_Leaves_Jungle",
      "support": 15
    },
    {
      "x": -5,
      "y": 75,
      "z": -9,
      "name": "Plant_Leaves_Jungle",
      "support": 15
    },
    {
      "x": -5,
      "y": -5,
      "z": -8,
      "name": "Rock_Magma_Cooled"
    },
    {
      "x": -5,
      "y": -4,
      "z": -8,
      "name": "Rock_Basalt"
    },
    {
      "x": -5,
      "y": -3,
      "z": -8,
      "name": "Rock_Basalt"
    },
    {
      "x": -5,
      "y": 74,
      "z": -8,
      "name": "Plant_Leaves_Jungle",
      "support": 15
    },
    {
      "x": -5,
      "y": -6,
      "z": -7,
      "name": "Rock_Magma_Cooled"
    },
    {
      "x": -5,
      "y": -5,
      "z": -7,
      "name": "Rock_Magma_Cooled"
    },
    {
      "x": -5,
      "y": -4,
      "z": -7,
      "name": "Rock_Magma_Cooled"
    },
    {
      "x": -5,
      "y": -3,
      "z": -7,
      "name": "Rock_Basalt"
    },
    {
      "x": -5,
      "y": -2,
      "z": -7,
      "name": "Rock_Magma_Cooled"
    },
    {
      "x": -5,
      "y": 73,
      "z": -7,
      "name": "Plant_Leaves_Jungle",
      "support": 15
    },
    {
      "x": -5,
      "y": 74,
      "z": -7,
      "name": "Plant_Leaves_Jungle",
      "support": 15
    },
    {
      "x": -5,
      "y": -6,
      "z": -6,
      "name": "Rock_Magma_Cooled"
    },
    {
      "x": -5,
      "y": -5,
      "z": -6,
      "name": "Rock_Magma_Cooled"
    },
    {
      "x": -5,
      "y": -4,
      "z": -6,
      "name": "Rock_Magma_Cooled"
    },
    {
      "x": -5,
      "y": -3,
      "z": -6,
      "name": "Rock_Magma_Cooled"
    },
    {
      "x": -5,
      "y": -2,
      "z": -6,
      "name": "Rock_Magma_Cooled"
    },
    {
      "x": -5,
      "y": 72,
      "z": -6,
      "name": "Wood_Jungle_Trunk",
      "support": 15
    },
    {
      "x": -5,
      "y": 73,
      "z": -6,
      "name": "Wood_Jungle_Trunk",
      "support": 15
    },
    {
      "x": -5,
      "y": 74,
      "z": -6,
      "name": "Plant_Leaves_Jungle",
      "support": 15
    },
    {
      "x": -5,
      "y": 78,
      "z": -6,
      "name": "Plant_Leaves_Jungle",
      "support": 15
    },
    {
      "x": -5,
      "y": -7,
      "z": -5,
      "name": "Rock_Magma_Cooled"
    },
    {
      "x": -5,
      "y": -6,
      "z": -5,
      "name": "Rock_Magma_Cooled"
    },
    {
      "x": -5,
      "y": -5,
      "z": -5,
      "name": "Rock_Magma_Cooled"
    },
    {
      "x": -5,
      "y": -4,
      "z": -5,
      "name": "Rock_Basalt"
    },
    {
      "x": -5,
      "y": -3,
      "z": -5,
      "name": "Rock_Magma_Cooled"
    },
    {
      "x": -5,
      "y": -2,
      "z": -5,
      "name": "Rock_Magma_Cooled"
    },
    {
      "x": -5,
      "y": -1,
      "z": -5,
      "name": "Rock_Magma_Cooled"
    },
    {
      "x": -5,
      "y": 72,
      "z": -5,
      "name": "Wood_Jungle_Trunk",
      "support": 15
    },
    {
      "x": -5,
      "y": 73,
      "z": -5,
      "name": "Wood_Jungle_Trunk",
      "support": 15
    },
    {
      "x": -5,
      "y": 74,
      "z": -5,
      "name": "Plant_Leaves_Jungle",
      "support": 15
    },
    {
      "x": -5,
      "y": 79,
      "z": -5,
      "name": "Plant_Leaves_Jungle",
      "support": 15
    },
    {
      "x": -5,
      "y": -7,
      "z": -4,
      "name": "Rock_Magma_Cooled"
    },
    {
      "x": -5,
      "y": -6,
      "z": -4,
      "name": "Rock_Magma_Cooled"
    },
    {
      "x": -5,
      "y": -5,
      "z": -4,
      "name": "Rock_Magma_Cooled"
    },
    {
      "x": -5,
      "y": -4,
      "z": -4,
      "name": "Rock_Basalt"
    },
    {
      "x": -5,
      "y": -3,
      "z": -4,
      "name": "Rock_Basalt"
    },
    {
      "x": -5,
      "y": -2,
      "z": -4,
      "name": "Rock_Magma_Cooled"
    },
    {
      "x": -5,
      "y": -1,
      "z": -4,
      "name": "Rock_Magma_Cooled"
    },
    {
      "x": -5,
      "y": 0,
      "z": -4,
      "name": "Rock_Magma_Cooled"
    },
    {
      "x": -5,
      "y": 73,
      "z": -4,
      "name": "Plant_Leaves_Jungle",
      "support": 15
    },
    {
      "x": -5,
      "y": 79,
      "z": -4,
      "name": "Plant_Leaves_Jungle",
      "support": 15
    },
    {
      "x": -5,
      "y": 80,
      "z": -4,
      "name": "Plant_Leaves_Jungle",
      "support": 15
    },
    {
      "x": -5,
      "y": -7,
      "z": -3,
      "name": "Rock_Magma_Cooled"
    },
    {
      "x": -5,
      "y": -6,
      "z": -3,
      "name": "Rock_Magma_Cooled"
    },
    {
      "x": -5,
      "y": -5,
      "z": -3,
      "name": "Rock_Magma_Cooled"
    },
    {
      "x": -5,
      "y": -4,
      "z": -3,
      "name": "Rock_Basalt"
    },
    {
      "x": -5,
      "y": -3,
      "z": -3,
      "name": "Rock_Basalt"
    },
    {
      "x": -5,
      "y": -2,
      "z": -3,
      "name": "Rock_Basalt"
    },
    {
      "x": -5,
      "y": -1,
      "z": -3,
      "name": "Rock_Magma_Cooled"
    },
    {
      "x": -5,
      "y": 0,
      "z": -3,
      "name": "Rock_Basalt"
    },
    {
      "x": -5,
      "y": 1,
      "z": -3,
      "name": "Rock_Basalt"
    },
    {
      "x": -5,
      "y": 18,
      "z": -3,
      "name": "Wood_Jungle_Trunk",
      "support": 15
    },
    {
      "x": -5,
      "y": 19,
      "z": -3,
      "name": "Wood_Jungle_Trunk_Full",
      "support": 15
    },
    {
      "x": -5,
      "y": 22,
      "z": -3,
      "name": "Empty"
    },
    {
      "x": -5,
      "y": 23,
      "z": -3,
      "name": "Empty"
    },
    {
      "x": -5,
      "y": 24,
      "z": -3,
      "name": "Empty"
    },
    {
      "x": -5,
      "y": 72,
      "z": -3,
      "name": "Plant_Leaves_Jungle",
      "support": 15
    },
    {
      "x": -5,
      "y": 73,
      "z": -3,
      "name": "Plant_Leaves_Jungle",
      "support": 15
    },
    {
      "x": -5,
      "y": 74,
      "z": -3,
      "name": "Plant_Leaves_Jungle",
      "support": 15
    },
    {
      "x": -5,
      "y": 79,
      "z": -3,
      "name": "Plant_Leaves_Jungle",
      "support": 15
    },
    {
      "x": -5,
      "y": 81,
      "z": -3,
      "name": "Plant_Leaves_Jungle",
      "support": 15
    },
    {
      "x": -5,
      "y": -8,
      "z": -2,
      "name": "Rock_Magma_Cooled"
    },
    {
      "x": -5,
      "y": -7,
      "z": -2,
      "name": "Rock_Magma_Cooled"
    },
    {
      "x": -5,
      "y": -6,
      "z": -2,
      "name": "Rock_Magma_Cooled"
    },
    {
      "x": -5,
      "y": -5,
      "z": -2,
      "name": "Rock_Magma_Cooled"
    },
    {
      "x": -5,
      "y": -4,
      "z": -2,
      "name": "Rock_Basalt"
    },
    {
      "x": -5,
      "y": -3,
      "z": -2,
      "name": "Rock_Basalt"
    },
    {
      "x": -5,
      "y": -2,
      "z": -2,
      "name": "Rock_Basalt"
    },
    {
      "x": -5,
      "y": -1,
      "z": -2,
      "name": "Rock_Basalt"
    },
    {
      "x": -5,
      "y": 0,
      "z": -2,
      "name": "Rock_Basalt"
    },
    {
      "x": -5,
      "y": 1,
      "z": -2,
      "name": "Rock_Basalt"
    },
    {
      "x": -5,
      "y": 19,
      "z": -2,
      "name": "Wood_Jungle_Trunk",
      "support": 15
    },
    {
      "x": -5,
      "y": 20,
      "z": -2,
      "name": "Wood_Jungle_Trunk",
      "support": 15
    },
    {
      "x": -5,
      "y": 21,
      "z": -2,
      "name": "Wood_Jungle_Trunk_Full",
      "support": 15
    },
    {
      "x": -5,
      "y": 22,
      "z": -2,
      "name": "Empty"
    },
    {
      "x": -5,
      "y": 23,
      "z": -2,
      "name": "Empty"
    },
    {
      "x": -5,
      "y": 24,
      "z": -2,
      "name": "Empty"
    },
    {
      "x": -5,
      "y": 71,
      "z": -2,
      "name": "Plant_Leaves_Jungle",
      "support": 15
    },
    {
      "x": -5,
      "y": 79,
      "z": -2,
      "name": "Plant_Leaves_Jungle",
      "support": 15
    },
    {
      "x": -5,
      "y": 80,
      "z": -2,
      "name": "Plant_Leaves_Jungle",
      "support": 15
    },
    {
      "x": -5,
      "y": 81,
      "z": -2,
      "name": "Plant_Leaves_Jungle",
      "support": 15
    },
    {
      "x": -5,
      "y": 82,
      "z": -2,
      "name": "Plant_Leaves_Jungle",
      "support": 15
    },
    {
      "x": -5,
      "y": -8,
      "z": -1,
      "name": "Rock_Magma_Cooled"
    },
    {
      "x": -5,
      "y": -7,
      "z": -1,
      "name": "Rock_Magma_Cooled"
    },
    {
      "x": -5,
      "y": -6,
      "z": -1,
      "name": "Rock_Magma_Cooled"
    },
    {
      "x": -5,
      "y": -5,
      "z": -1,
      "name": "Rock_Basalt"
    },
    {
      "x": -5,
      "y": -4,
      "z": -1,
      "name": "Rock_Basalt"
    },
    {
      "x": -5,
      "y": -3,
      "z": -1,
      "name": "Rock_Magma_Cooled"
    },
    {
      "x": -5,
      "y": -2,
      "z": -1,
      "name": "Rock_Basalt"
    },
    {
      "x": -5,
      "y": -1,
      "z": -1,
      "name": "Rock_Basalt"
    },
    {
      "x": -5,
      "y": 0,
      "z": -1,
      "name": "Rock_Basalt"
    },
    {
      "x": -5,
      "y": 1,
      "z": -1,
      "name": "Rock_Basalt"
    },
    {
      "x": -5,
      "y": 2,
      "z": -1,
      "name": "Rock_Basalt"
    },
    {
      "x": -5,
      "y": 3,
      "z": -1,
      "name": "Empty"
    },
    {
      "x": -5,
      "y": 4,
      "z": -1,
      "name": "Empty"
    },
    {
      "x": -5,
      "y": 5,
      "z": -1,
      "name": "Empty"
    },
    {
      "x": -5,
      "y": 11,
      "z": -1,
      "name": "Soil_Dirt_Burnt"
    },
    {
      "x": -5,
      "y": 12,
      "z": -1,
      "name": "Soil_Dirt_Burnt"
    },
    {
      "x": -5,
      "y": 13,
      "z": -1,
      "name": "Soil_Dirt_Burnt"
    },
    {
      "x": -5,
      "y": 20,
      "z": -1,
      "name": "Wood_Jungle_Trunk",
      "support": 15
    },
    {
      "x": -5,
      "y": 21,
      "z": -1,
      "name": "Wood_Jungle_Trunk",
      "support": 15
    },
    {
      "x": -5,
      "y": 22,
      "z": -1,
      "name": "Wood_Jungle_Trunk",
      "support": 15
    },
    {
      "x": -5,
      "y": 23,
      "z": -1,
      "name": "Wood_Jungle_Trunk_Full",
      "support": 15
    },
    {
      "x": -5,
      "y": 24,
      "z": -1,
      "name": "Empty"
    },
    {
      "x": -5,
      "y": 25,
      "z": -1,
      "name": "Empty"
    },
    {
      "x": -5,
      "y": 26,
      "z": -1,
      "name": "Empty"
    },
    {
      "x": -5,
      "y": 27,
      "z": -1,
      "name": "Empty"
    },
    {
      "x": -5,
      "y": 80,
      "z": -1,
      "name": "Plant_Leaves_Jungle",
      "support": 15
    },
    {
      "x": -5,
      "y": 81,
      "z": -1,
      "name": "Plant_Leaves_Jungle",
      "support": 15
    },
    {
      "x": -5,
      "y": -8,
      "z": 0,
      "name": "Rock_Magma_Cooled"
    },
    {
      "x": -5,
      "y": -7,
      "z": 0,
      "name": "Rock_Magma_Cooled"
    },
    {
      "x": -5,
      "y": -6,
      "z": 0,
      "name": "Rock_Magma_Cooled"
    },
    {
      "x": -5,
      "y": -5,
      "z": 0,
      "name": "Rock_Basalt"
    },
    {
      "x": -5,
      "y": -4,
      "z": 0,
      "name": "Rock_Magma_Cooled"
    },
    {
      "x": -5,
      "y": -3,
      "z": 0,
      "name": "Rock_Magma_Cooled"
    },
    {
      "x": -5,
      "y": -2,
      "z": 0,
      "name": "Rock_Magma_Cooled"
    },
    {
      "x": -5,
      "y": -1,
      "z": 0,
      "name": "Rock_Basalt"
    },
    {
      "x": -5,
      "y": 0,
      "z": 0,
      "name": "Rock_Basalt"
    },
    {
      "x": -5,
      "y": 1,
      "z": 0,
      "name": "Rock_Basalt"
    },
    {
      "x": -5,
      "y": 2,
      "z": 0,
      "name": "Rock_Basalt"
    },
    {
      "x": -5,
      "y": 3,
      "z": 0,
      "name": "Empty"
    },
    {
      "x": -5,
      "y": 4,
      "z": 0,
      "name": "Empty"
    },
    {
      "x": -5,
      "y": 5,
      "z": 0,
      "name": "Empty"
    },
    {
      "x": -5,
      "y": 6,
      "z": 0,
      "name": "Empty"
    },
    {
      "x": -5,
      "y": 10,
      "z": 0,
      "name": "Soil_Dirt_Burnt"
    },
    {
      "x": -5,
      "y": 11,
      "z": 0,
      "name": "Soil_Dirt_Burnt"
    },
    {
      "x": -5,
      "y": 12,
      "z": 0,
      "name": "Soil_Dirt_Burnt"
    },
    {
      "x": -5,
      "y": 13,
      "z": 0,
      "name": "Soil_Dirt_Burnt"
    },
    {
      "x": -5,
      "y": 14,
      "z": 0,
      "name": "Soil_Dirt_Burnt"
    },
    {
      "x": -5,
      "y": 23,
      "z": 0,
      "name": "Wood_Jungle_Trunk",
      "support": 15
    },
    {
      "x": -5,
      "y": 24,
      "z": 0,
      "name": "Wood_Jungle_Trunk",
      "support": 15
    },
    {
      "x": -5,
      "y": 25,
      "z": 0,
      "name": "Wood_Jungle_Trunk_Full",
      "support": 15
    },
    {
      "x": -5,
      "y": 26,
      "z": 0,
      "name": "Empty"
    },
    {
      "x": -5,
      "y": 27,
      "z": 0,
      "name": "Empty"
    },
    {
      "x": -5,
      "y": 28,
      "z": 0,
      "name": "Empty"
    },
    {
      "x": -5,
      "y": 29,
      "z": 0,
      "name": "Empty"
    },
    {
      "x": -5,
      "y": 30,
      "z": 0,
      "name": "Empty"
    },
    {
      "x": -5,
      "y": 55,
      "z": 0,
      "name": "Plant_Crop_Mushroom_Block_Green"
    },
    {
      "x": -5,
      "y": 78,
      "z": 0,
      "name": "Wood_Jungle_Trunk",
      "support": 15
    },
    {
      "x": -5,
      "y": 79,
      "z": 0,
      "name": "Wood_Jungle_Trunk",
      "support": 15
    },
    {
      "x": -5,
      "y": 80,
      "z": 0,
      "name": "Wood_Jungle_Trunk",
      "support": 15
    },
    {
      "x": -5,
      "y": 81,
      "z": 0,
      "name": "Plant_Leaves_Jungle",
      "support": 15
    },
    {
      "x": -5,
      "y": 82,
      "z": 0,
      "name": "Plant_Leaves_Jungle",
      "support": 15
    },
    {
      "x": -5,
      "y": -8,
      "z": 1,
      "name": "Rock_Magma_Cooled"
    },
    {
      "x": -5,
      "y": -7,
      "z": 1,
      "name": "Rock_Magma_Cooled"
    },
    {
      "x": -5,
      "y": -6,
      "z": 1,
      "name": "Rock_Magma_Cooled"
    },
    {
      "x": -5,
      "y": -5,
      "z": 1,
      "name": "Rock_Magma_Cooled"
    },
    {
      "x": -5,
      "y": -4,
      "z": 1,
      "name": "Rock_Magma_Cooled"
    },
    {
      "x": -5,
      "y": -3,
      "z": 1,
      "name": "Rock_Magma_Cooled"
    },
    {
      "x": -5,
      "y": -2,
      "z": 1,
      "name": "Rock_Magma_Cooled"
    },
    {
      "x": -5,
      "y": -1,
      "z": 1,
      "name": "Rock_Magma_Cooled"
    },
    {
      "x": -5,
      "y": 0,
      "z": 1,
      "name": "Rock_Magma_Cooled"
    },
    {
      "x": -5,
      "y": 1,
      "z": 1,
      "name": "Rock_Basalt"
    },
    {
      "x": -5,
      "y": 2,
      "z": 1,
      "name": "Rock_Basalt"
    },
    {
      "x": -5,
      "y": 3,
      "z": 1,
      "name": "Empty"
    },
    {
      "x": -5,
      "y": 4,
      "z": 1,
      "name": "Empty"
    },
    {
      "x": -5,
      "y": 5,
      "z": 1,
      "name": "Empty"
    },
    {
      "x": -5,
      "y": 6,
      "z": 1,
      "name": "Empty"
    },
    {
      "x": -5,
      "y": 11,
      "z": 1,
      "name": "Soil_Dirt_Burnt"
    },
    {
      "x": -5,
      "y": 12,
      "z": 1,
      "name": "Soil_Dirt_Burnt"
    },
    {
      "x": -5,
      "y": 13,
      "z": 1,
      "name": "Soil_Dirt_Burnt"
    },
    {
      "x": -5,
      "y": 14,
      "z": 1,
      "name": "Soil_Dirt_Burnt"
    },
    {
      "x": -5,
      "y": 15,
      "z": 1,
      "name": "Soil_Dirt_Burnt"
    },
    {
      "x": -5,
      "y": 16,
      "z": 1,
      "name": "Soil_Dirt_Burnt"
    },
    {
      "x": -5,
      "y": 24,
      "z": 1,
      "name": "Wood_Jungle_Trunk_Full",
      "support": 15
    },
    {
      "x": -5,
      "y": 27,
      "z": 1,
      "name": "Empty"
    },
    {
      "x": -5,
      "y": 28,
      "z": 1,
      "name": "Empty"
    },
    {
      "x": -5,
      "y": 29,
      "z": 1,
      "name": "Empty"
    },
    {
      "x": -5,
      "y": 55,
      "z": 1,
      "name": "Plant_Crop_Mushroom_Block_Green"
    },
    {
      "x": -5,
      "y": 78,
      "z": 1,
      "name": "Wood_Jungle_Branch_Long",
      "support": 15,
      "rotation": 5
    },
    {
      "x": -5,
      "y": 79,
      "z": 1,
      "name": "Wood_Jungle_Trunk",
      "support": 15
    },
    {
      "x": -5,
      "y": 80,
      "z": 1,
      "name": "Plant_Leaves_Jungle",
      "support": 15
    },
    {
      "x": -5,
      "y": 81,
      "z": 1,
      "name": "Plant_Leaves_Jungle",
      "support": 15
    },
    {
      "x": -5,
      "y": -7,
      "z": 2,
      "name": "Rock_Magma_Cooled"
    },
    {
      "x": -5,
      "y": -6,
      "z": 2,
      "name": "Rock_Magma_Cooled"
    },
    {
      "x": -5,
      "y": -5,
      "z": 2,
      "name": "Rock_Magma_Cooled"
    },
    {
      "x": -5,
      "y": -4,
      "z": 2,
      "name": "Rock_Magma_Cooled"
    },
    {
      "x": -5,
      "y": -3,
      "z": 2,
      "name": "Rock_Magma_Cooled"
    },
    {
      "x": -5,
      "y": -2,
      "z": 2,
      "name": "Rock_Magma_Cooled"
    },
    {
      "x": -5,
      "y": -1,
      "z": 2,
      "name": "Rock_Magma_Cooled"
    },
    {
      "x": -5,
      "y": 0,
      "z": 2,
      "name": "Rock_Magma_Cooled"
    },
    {
      "x": -5,
      "y": 1,
      "z": 2,
      "name": "Rock_Magma_Cooled"
    },
    {
      "x": -5,
      "y": 2,
      "z": 2,
      "name": "Rock_Basalt"
    },
    {
      "x": -5,
      "y": 12,
      "z": 2,
      "name": "Soil_Dirt_Burnt"
    },
    {
      "x": -5,
      "y": 13,
      "z": 2,
      "name": "Soil_Dirt_Burnt"
    },
    {
      "x": -5,
      "y": 14,
      "z": 2,
      "name": "Soil_Dirt_Burnt"
    },
    {
      "x": -5,
      "y": 15,
      "z": 2,
      "name": "Soil_Dirt_Burnt"
    },
    {
      "x": -5,
      "y": 16,
      "z": 2,
      "name": "Soil_Dirt_Burnt"
    },
    {
      "x": -5,
      "y": 17,
      "z": 2,
      "name": "Soil_Dirt_Burnt"
    },
    {
      "x": -5,
      "y": 55,
      "z": 2,
      "name": "Plant_Crop_Mushroom_Block_Green"
    },
    {
      "x": -5,
      "y": 80,
      "z": 2,
      "name": "Plant_Leaves_Jungle",
      "support": 15
    },
    {
      "x": -5,
      "y": -7,
      "z": 3,
      "name": "Rock_Magma_Cooled"
    },
    {
      "x": -5,
      "y": -6,
      "z": 3,
      "name": "Rock_Magma_Cooled"
    },
    {
      "x": -5,
      "y": -5,
      "z": 3,
      "name": "Rock_Magma_Cooled"
    },
    {
      "x": -5,
      "y": -4,
      "z": 3,
      "name": "Rock_Magma_Cooled"
    },
    {
      "x": -5,
      "y": -3,
      "z": 3,
      "name": "Rock_Magma_Cooled"
    },
    {
      "x": -5,
      "y": -2,
      "z": 3,
      "name": "Rock_Magma_Cooled"
    },
    {
      "x": -5,
      "y": -1,
      "z": 3,
      "name": "Rock_Magma_Cooled"
    },
    {
      "x": -5,
      "y": 0,
      "z": 3,
      "name": "Rock_Magma_Cooled"
    },
    {
      "x": -5,
      "y": 1,
      "z": 3,
      "name": "Rock_Magma_Cooled"
    },
    {
      "x": -5,
      "y": 13,
      "z": 3,
      "name": "Soil_Dirt_Burnt"
    },
    {
      "x": -5,
      "y": 14,
      "z": 3,
      "name": "Soil_Dirt_Burnt"
    },
    {
      "x": -5,
      "y": 15,
      "z": 3,
      "name": "Soil_Dirt_Burnt"
    },
    {
      "x": -5,
      "y": 16,
      "z": 3,
      "name": "Soil_Dirt_Burnt"
    },
    {
      "x": -5,
      "y": 81,
      "z": 3,
      "name": "Plant_Leaves_Jungle",
      "support": 15
    },
    {
      "x": -5,
      "y": -6,
      "z": 4,
      "name": "Rock_Magma_Cooled"
    },
    {
      "x": -5,
      "y": -5,
      "z": 4,
      "name": "Rock_Magma_Cooled"
    },
    {
      "x": -5,
      "y": -4,
      "z": 4,
      "name": "Rock_Magma_Cooled"
    },
    {
      "x": -5,
      "y": -3,
      "z": 4,
      "name": "Rock_Magma_Cooled"
    },
    {
      "x": -5,
      "y": -2,
      "z": 4,
      "name": "Rock_Magma_Cooled"
    },
    {
      "x": -5,
      "y": -1,
      "z": 4,
      "name": "Rock_Magma_Cooled"
    },
    {
      "x": -5,
      "y": 0,
      "z": 4,
      "name": "Rock_Magma_Cooled"
    },
    {
      "x": -5,
      "y": 81,
      "z": 4,
      "name": "Plant_Leaves_Jungle",
      "support": 15
    },
    {
      "x": -5,
      "y": -5,
      "z": 5,
      "name": "Rock_Magma_Cooled"
    },
    {
      "x": -5,
      "y": -4,
      "z": 5,
      "name": "Rock_Magma_Cooled"
    },
    {
      "x": -5,
      "y": -3,
      "z": 5,
      "name": "Rock_Magma_Cooled"
    },
    {
      "x": -5,
      "y": -2,
      "z": 5,
      "name": "Rock_Magma_Cooled"
    },
    {
      "x": -5,
      "y": 80,
      "z": 5,
      "name": "Plant_Leaves_Jungle",
      "support": 15
    },
    {
      "x": -5,
      "y": 81,
      "z": 5,
      "name": "Plant_Leaves_Jungle",
      "support": 15
    },
    {
      "x": -5,
      "y": -4,
      "z": 6,
      "name": "Rock_Magma_Cooled"
    },
    {
      "x": -5,
      "y": -3,
      "z": 6,
      "name": "Rock_Magma_Cooled"
    },
    {
      "x": -5,
      "y": 80,
      "z": 6,
      "name": "Plant_Leaves_Jungle",
      "support": 15
    },
    {
      "x": -5,
      "y": 81,
      "z": 6,
      "name": "Plant_Leaves_Jungle",
      "support": 15
    },
    {
      "x": -5,
      "y": 80,
      "z": 7,
      "name": "Plant_Leaves_Jungle",
      "support": 15
    },
    {
      "x": -5,
      "y": 81,
      "z": 7,
      "name": "Plant_Leaves_Jungle",
      "support": 15
    },
    {
      "x": -5,
      "y": 80,
      "z": 8,
      "name": "Plant_Leaves_Jungle",
      "support": 15
    },
    {
      "x": -4,
      "y": 74,
      "z": -9,
      "name": "Plant_Leaves_Jungle",
      "support": 15
    },
    {
      "x": -4,
      "y": -6,
      "z": -8,
      "name": "Rock_Magma_Cooled"
    },
    {
      "x": -4,
      "y": -5,
      "z": -8,
      "name": "Rock_Magma_Cooled"
    },
    {
      "x": -4,
      "y": -4,
      "z": -8,
      "name": "Rock_Magma_Cooled"
    },
    {
      "x": -4,
      "y": -3,
      "z": -8,
      "name": "Rock_Basalt"
    },
    {
      "x": -4,
      "y": -2,
      "z": -8,
      "name": "Rock_Basalt"
    },
    {
      "x": -4,
      "y": 74,
      "z": -8,
      "name": "Plant_Leaves_Jungle",
      "support": 15
    },
    {
      "x": -4,
      "y": -7,
      "z": -7,
      "name": "Rock_Magma_Cooled"
    },
    {
      "x": -4,
      "y": -6,
      "z": -7,
      "name": "Rock_Magma_Cooled"
    },
    {
      "x": -4,
      "y": -5,
      "z": -7,
      "name": "Rock_Magma_Cooled"
    },
    {
      "x": -4,
      "y": -4,
      "z": -7,
      "name": "Rock_Magma_Cooled"
    },
    {
      "x": -4,
      "y": -3,
      "z": -7,
      "name": "Rock_Basalt"
    },
    {
      "x": -4,
      "y": -2,
      "z": -7,
      "name": "Rock_Magma_Cooled"
    },
    {
      "x": -4,
      "y": -1,
      "z": -7,
      "name": "Rock_Basalt"
    },
    {
      "x": -4,
      "y": 73,
      "z": -7,
      "name": "Plant_Leaves_Jungle",
      "support": 15
    },
    {
      "x": -4,
      "y": 74,
      "z": -7,
      "name": "Plant_Leaves_Jungle",
      "support": 15
    },
    {
      "x": -4,
      "y": -7,
      "z": -6,
      "name": "Rock_Magma_Cooled"
    },
    {
      "x": -4,
      "y": -6,
      "z": -6,
      "name": "Rock_Magma_Cooled"
    },
    {
      "x": -4,
      "y": -5,
      "z": -6,
      "name": "Rock_Magma_Cooled"
    },
    {
      "x": -4,
      "y": -4,
      "z": -6,
      "name": "Rock_Basalt"
    },
    {
      "x": -4,
      "y": -3,
      "z": -6,
      "name": "Rock_Magma_Cooled"
    },
    {
      "x": -4,
      "y": -2,
      "z": -6,
      "name": "Rock_Magma_Cooled"
    },
    {
      "x": -4,
      "y": -1,
      "z": -6,
      "name": "Rock_Magma_Cooled"
    },
    {
      "x": -4,
      "y": 7,
      "z": -6,
      "name": "Soil_Dirt_Burnt"
    },
    {
      "x": -4,
      "y": 8,
      "z": -6,
      "name": "Soil_Dirt_Burnt"
    },
    {
      "x": -4,
      "y": 9,
      "z": -6,
      "name": "Soil_Dirt_Burnt"
    },
    {
      "x": -4,
      "y": 73,
      "z": -6,
      "name": "Plant_Leaves_Jungle",
      "support": 15
    },
    {
      "x": -4,
      "y": 74,
      "z": -6,
      "name": "Plant_Leaves_Jungle",
      "support": 15
    },
    {
      "x": -4,
      "y": 78,
      "z": -6,
      "name": "Plant_Leaves_Jungle",
      "support": 15
    },
    {
      "x": -4,
      "y": 79,
      "z": -6,
      "name": "Plant_Leaves_Jungle",
      "support": 15
    },
    {
      "x": -4,
      "y": -7,
      "z": -5,
      "name": "Rock_Magma_Cooled"
    },
    {
      "x": -4,
      "y": -6,
      "z": -5,
      "name": "Rock_Magma_Cooled"
    },
    {
      "x": -4,
      "y": -5,
      "z": -5,
      "name": "Rock_Magma_Cooled"
    },
    {
      "x": -4,
      "y": -4,
      "z": -5,
      "name": "Rock_Basalt"
    },
    {
      "x": -4,
      "y": -3,
      "z": -5,
      "name": "Rock_Basalt"
    },
    {
      "x": -4,
      "y": -2,
      "z": -5,
      "name": "Rock_Magma_Cooled"
    },
    {
      "x": -4,
      "y": -1,
      "z": -5,
      "name": "Rock_Magma_Cooled"
    },
    {
      "x": -4,
      "y": 0,
      "z": -5,
      "name": "Rock_Magma_Cooled"
    },
    {
      "x": -4,
      "y": 6,
      "z": -5,
      "name": "Soil_Dirt_Burnt"
    },
    {
      "x": -4,
      "y": 7,
      "z": -5,
      "name": "Soil_Dirt_Burnt"
    },
    {
      "x": -4,
      "y": 8,
      "z": -5,
      "name": "Soil_Dirt_Burnt"
    },
    {
      "x": -4,
      "y": 9,
      "z": -5,
      "name": "Soil_Dirt_Burnt"
    },
    {
      "x": -4,
      "y": 10,
      "z": -5,
      "name": "Soil_Dirt_Burnt"
    },
    {
      "x": -4,
      "y": 72,
      "z": -5,
      "name": "Wood_Jungle_Trunk",
      "support": 15
    },
    {
      "x": -4,
      "y": 73,
      "z": -5,
      "name": "Plant_Leaves_Jungle",
      "support": 15
    },
    {
      "x": -4,
      "y": 74,
      "z": -5,
      "name": "Plant_Leaves_Jungle",
      "support": 15
    },
    {
      "x": -4,
      "y": 78,
      "z": -5,
      "name": "Plant_Leaves_Jungle",
      "support": 15
    },
    {
      "x": -4,
      "y": 79,
      "z": -5,
      "name": "Plant_Leaves_Jungle",
      "support": 15
    },
    {
      "x": -4,
      "y": -7,
      "z": -4,
      "name": "Rock_Magma_Cooled"
    },
    {
      "x": -4,
      "y": -6,
      "z": -4,
      "name": "Rock_Magma_Cooled"
    },
    {
      "x": -4,
      "y": -5,
      "z": -4,
      "name": "Rock_Basalt"
    },
    {
      "x": -4,
      "y": -4,
      "z": -4,
      "name": "Rock_Basalt"
    },
    {
      "x": -4,
      "y": -3,
      "z": -4,
      "name": "Rock_Basalt"
    },
    {
      "x": -4,
      "y": -2,
      "z": -4,
      "name": "Rock_Basalt"
    },
    {
      "x": -4,
      "y": -1,
      "z": -4,
      "name": "Rock_Magma_Cooled"
    },
    {
      "x": -4,
      "y": 0,
      "z": -4,
      "name": "Rock_Basalt"
    },
    {
      "x": -4,
      "y": 1,
      "z": -4,
      "name": "Rock_Basalt"
    },
    {
      "x": -4,
      "y": 2,
      "z": -4,
      "name": "Rock_Basalt"
    },
    {
      "x": -4,
      "y": 6,
      "z": -4,
      "name": "Soil_Dirt_Burnt"
    },
    {
      "x": -4,
      "y": 7,
      "z": -4,
      "name": "Soil_Dirt_Burnt"
    },
    {
      "x": -4,
      "y": 8,
      "z": -4,
      "name": "Soil_Dirt_Burnt"
    },
    {
      "x": -4,
      "y": 9,
      "z": -4,
      "name": "Soil_Dirt_Burnt"
    },
    {
      "x": -4,
      "y": 10,
      "z": -4,
      "name": "Soil_Dirt_Burnt"
    },
    {
      "x": -4,
      "y": 17,
      "z": -4,
      "name": "Wood_Jungle_Trunk",
      "support": 15
    },
    {
      "x": -4,
      "y": 18,
      "z": -4,
      "name": "Wood_Jungle_Trunk_Full",
      "support": 15
    },
    {
      "x": -4,
      "y": 67,
      "z": -4,
      "name": "Plant_Leaves_Palm_Oasis",
      "support": 15
    },
    {
      "x": -4,
      "y": 68,
      "z": -4,
      "name": "Wood_Jungle_Branch_Long",
      "support": 15
    },
    {
      "x": -4,
      "y": 69,
      "z": -4,
      "name": "Wood_Jungle_Branch_Long",
      "support": 15
    },
    {
      "x": -4,
      "y": 70,
      "z": -4,
      "name": "Wood_Jungle_Branch_Long",
      "support": 15
    },
    {
      "x": -4,
      "y": 71,
      "z": -4,
      "name": "Wood_Jungle_Branch_Long",
      "support": 15
    },
    {
      "x": -4,
      "y": 72,
      "z": -4,
      "name": "Wood_Jungle_Trunk",
      "support": 15
    },
    {
      "x": -4,
      "y": 73,
      "z": -4,
      "name": "Plant_Leaves_Jungle",
      "support": 15
    },
    {
      "x": -4,
      "y": 74,
      "z": -4,
      "name": "Plant_Leaves_Jungle",
      "support": 15
    },
    {
      "x": -4,
      "y": 78,
      "z": -4,
      "name": "Wood_Jungle_Branch_Long",
      "support": 15,
      "rotation": 4
    },
    {
      "x": -4,
      "y": 79,
      "z": -4,
      "name": "Plant_Leaves_Jungle",
      "support": 15
    },
    {
      "x": -4,
      "y": 80,
      "z": -4,
      "name": "Plant_Leaves_Jungle",
      "support": 15
    },
    {
      "x": -4,
      "y": -7,
      "z": -3,
      "name": "Rock_Magma_Cooled"
    },
    {
      "x": -4,
      "y": -6,
      "z": -3,
      "name": "Rock_Magma_Cooled"
    },
    {
      "x": -4,
      "y": -5,
      "z": -3,
      "name": "Rock_Magma_Cooled"
    },
    {
      "x": -4,
      "y": -4,
      "z": -3,
      "name": "Rock_Basalt"
    },
    {
      "x": -4,
      "y": -3,
      "z": -3,
      "name": "Rock_Basalt"
    },
    {
      "x": -4,
      "y": -2,
      "z": -3,
      "name": "Rock_Basalt"
    },
    {
      "x": -4,
      "y": -1,
      "z": -3,
      "name": "Rock_Basalt"
    },
    {
      "x": -4,
      "y": 0,
      "z": -3,
      "name": "Rock_Basalt"
    },
    {
      "x": -4,
      "y": 1,
      "z": -3,
      "name": "Rock_Basalt"
    },
    {
      "x": -4,
      "y": 2,
      "z": -3,
      "name": "Rock_Basalt"
    },
    {
      "x": -4,
      "y": 3,
      "z": -3,
      "name": "Rock_Basalt"
    },
    {
      "x": -4,
      "y": 8,
      "z": -3,
      "name": "Soil_Dirt_Burnt"
    },
    {
      "x": -4,
      "y": 9,
      "z": -3,
      "name": "Soil_Dirt_Burnt"
    },
    {
      "x": -4,
      "y": 10,
      "z": -3,
      "name": "Soil_Dirt_Burnt"
    },
    {
      "x": -4,
      "y": 11,
      "z": -3,
      "name": "Wood_Jungle_Trunk_Full",
      "support": 15
    },
    {
      "x": -4,
      "y": 14,
      "z": -3,
      "name": "Empty"
    },
    {
      "x": -4,
      "y": 15,
      "z": -3,
      "name": "Empty"
    },
    {
      "x": -4,
      "y": 17,
      "z": -3,
      "name": "Wood_Jungle_Trunk",
      "support": 15
    },
    {
      "x": -4,
      "y": 18,
      "z": -3,
      "name": "Wood_Jungle_Trunk",
      "support": 15
    },
    {
      "x": -4,
      "y": 19,
      "z": -3,
      "name": "Wood_Jungle_Trunk",
      "support": 15
    },
    {
      "x": -4,
      "y": 20,
      "z": -3,
      "name": "Wood_Jungle_Trunk_Full",
      "support": 15
    },
    {
      "x": -4,
      "y": 21,
      "z": -3,
      "name": "Empty"
    },
    {
      "x": -4,
      "y": 22,
      "z": -3,
      "name": "Empty"
    },
    {
      "x": -4,
      "y": 23,
      "z": -3,
      "name": "Empty"
    },
    {
      "x": -4,
      "y": 24,
      "z": -3,
      "name": "Empty"
    },
    {
      "x": -4,
      "y": 25,
      "z": -3,
      "name": "Empty"
    },
    {
      "x": -4,
      "y": 39,
      "z": -3,
      "name": "Wood_Jungle_Trunk",
      "support": 15
    },
    {
      "x": -4,
      "y": 40,
      "z": -3,
      "name": "Wood_Jungle_Trunk",
      "support": 15
    },
    {
      "x": -4,
      "y": 41,
      "z": -3,
      "name": "Wood_Jungle_Trunk",
      "support": 15
    },
    {
      "x": -4,
      "y": 42,
      "z": -3,
      "name": "Wood_Jungle_Trunk_Full",
      "support": 15
    },
    {
      "x": -4,
      "y": 72,
      "z": -3,
      "name": "Plant_Leaves_Jungle",
      "support": 15
    },
    {
      "x": -4,
      "y": 73,
      "z": -3,
      "name": "Plant_Leaves_Jungle",
      "support": 15
    },
    {
      "x": -4,
      "y": 74,
      "z": -3,
      "name": "Plant_Leaves_Jungle",
      "support": 15
    },
    {
      "x": -4,
      "y": 78,
      "z": -3,
      "name": "Wood_Jungle_Branch_Long",
      "support": 15,
      "rotation": 4
    },
    {
      "x": -4,
      "y": 79,
      "z": -3,
      "name": "Plant_Leaves_Jungle",
      "support": 15
    },
    {
      "x": -4,
      "y": -8,
      "z": -2,
      "name": "Rock_Magma_Cooled"
    },
    {
      "x": -4,
      "y": -7,
      "z": -2,
      "name": "Rock_Magma_Cooled"
    },
    {
      "x": -4,
      "y": -6,
      "z": -2,
      "name": "Rock_Magma_Cooled"
    },
    {
      "x": -4,
      "y": -5,
      "z": -2,
      "name": "Rock_Basalt"
    },
    {
      "x": -4,
      "y": -4,
      "z": -2,
      "name": "Rock_Basalt"
    },
    {
      "x": -4,
      "y": -3,
      "z": -2,
      "name": "Rock_Basalt"
    },
    {
      "x": -4,
      "y": -2,
      "z": -2,
      "name": "Rock_Basalt"
    },
    {
      "x": -4,
      "y": -1,
      "z": -2,
      "name": "Rock_Basalt"
    },
    {
      "x": -4,
      "y": 0,
      "z": -2,
      "name": "Rock_Basalt"
    },
    {
      "x": -4,
      "y": 1,
      "z": -2,
      "name": "Rock_Basalt"
    },
    {
      "x": -4,
      "y": 2,
      "z": -2,
      "name": "Rock_Basalt"
    },
    {
      "x": -4,
      "y": 3,
      "z": -2,
      "name": "Rock_Basalt"
    },
    {
      "x": -4,
      "y": 4,
      "z": -2,
      "name": "Rock_Basalt"
    },
    {
      "x": -4,
      "y": 10,
      "z": -2,
      "name": "Wood_Jungle_Trunk",
      "support": 15
    },
    {
      "x": -4,
      "y": 11,
      "z": -2,
      "name": "Wood_Jungle_Trunk",
      "support": 15
    },
    {
      "x": -4,
      "y": 12,
      "z": -2,
      "name": "Wood_Jungle_Trunk_Full",
      "support": 15
    },
    {
      "x": -4,
      "y": 14,
      "z": -2,
      "name": "Empty"
    },
    {
      "x": -4,
      "y": 15,
      "z": -2,
      "name": "Empty"
    },
    {
      "x": -4,
      "y": 16,
      "z": -2,
      "name": "Empty"
    },
    {
      "x": -4,
      "y": 18,
      "z": -2,
      "name": "Wood_Jungle_Trunk",
      "support": 15
    },
    {
      "x": -4,
      "y": 19,
      "z": -2,
      "name": "Wood_Jungle_Trunk",
      "support": 15
    },
    {
      "x": -4,
      "y": 20,
      "z": -2,
      "name": "Wood_Jungle_Trunk",
      "support": 15
    },
    {
      "x": -4,
      "y": 21,
      "z": -2,
      "name": "Wood_Jungle_Trunk_Full",
      "support": 15
    },
    {
      "x": -4,
      "y": 22,
      "z": -2,
      "name": "Empty"
    },
    {
      "x": -4,
      "y": 23,
      "z": -2,
      "name": "Empty"
    },
    {
      "x": -4,
      "y": 24,
      "z": -2,
      "name": "Empty"
    },
    {
      "x": -4,
      "y": 25,
      "z": -2,
      "name": "Empty"
    },
    {
      "x": -4,
      "y": 26,
      "z": -2,
      "name": "Empty"
    },
    {
      "x": -4,
      "y": 40,
      "z": -2,
      "name": "Soil_Dirt_Burnt"
    },
    {
      "x": -4,
      "y": 41,
      "z": -2,
      "name": "Wood_Jungle_Trunk",
      "support": 15
    },
    {
      "x": -4,
      "y": 42,
      "z": -2,
      "name": "Wood_Jungle_Trunk",
      "support": 15
    },
    {
      "x": -4,
      "y": 43,
      "z": -2,
      "name": "Wood_Jungle_Trunk_Full",
      "support": 15
    },
    {
      "x": -4,
      "y": 71,
      "z": -2,
      "name": "Plant_Leaves_Jungle",
      "support": 15
    },
    {
      "x": -4,
      "y": 72,
      "z": -2,
      "name": "Plant_Leaves_Jungle",
      "support": 15
    },
    {
      "x": -4,
      "y": 73,
      "z": -2,
      "name": "Plant_Leaves_Jungle",
      "support": 15
    },
    {
      "x": -4,
      "y": 78,
      "z": -2,
      "name": "Wood_Jungle_Branch_Long",
      "support": 15,
      "rotation": 4
    },
    {
      "x": -4,
      "y": 79,
      "z": -2,
      "name": "Plant_Leaves_Jungle",
      "support": 15
    },
    {
      "x": -4,
      "y": 81,
      "z": -2,
      "name": "Plant_Leaves_Jungle",
      "support": 15
    },
    {
      "x": -4,
      "y": -8,
      "z": -1,
      "name": "Rock_Magma_Cooled"
    },
    {
      "x": -4,
      "y": -7,
      "z": -1,
      "name": "Rock_Magma_Cooled"
    },
    {
      "x": -4,
      "y": -6,
      "z": -1,
      "name": "Rock_Basalt"
    },
    {
      "x": -4,
      "y": -5,
      "z": -1,
      "name": "Rock_Basalt"
    },
    {
      "x": -4,
      "y": -4,
      "z": -1,
      "name": "Rock_Basalt"
    },
    {
      "x": -4,
      "y": -3,
      "z": -1,
      "name": "Rock_Basalt"
    },
    {
      "x": -4,
      "y": -2,
      "z": -1,
      "name": "Rock_Basalt"
    },
    {
      "x": -4,
      "y": -1,
      "z": -1,
      "name": "Rock_Basalt"
    },
    {
      "x": -4,
      "y": 0,
      "z": -1,
      "name": "Rock_Basalt"
    },
    {
      "x": -4,
      "y": 1,
      "z": -1,
      "name": "Rock_Basalt"
    },
    {
      "x": -4,
      "y": 2,
      "z": -1,
      "name": "Rock_Basalt"
    },
    {
      "x": -4,
      "y": 3,
      "z": -1,
      "name": "Rock_Basalt"
    },
    {
      "x": -4,
      "y": 4,
      "z": -1,
      "name": "Empty"
    },
    {
      "x": -4,
      "y": 5,
      "z": -1,
      "name": "Empty"
    },
    {
      "x": -4,
      "y": 10,
      "z": -1,
      "name": "Soil_Dirt_Burnt"
    },
    {
      "x": -4,
      "y": 11,
      "z": -1,
      "name": "Wood_Jungle_Trunk",
      "support": 15
    },
    {
      "x": -4,
      "y": 12,
      "z": -1,
      "name": "Wood_Jungle_Trunk_Full",
      "support": 15
    },
    {
      "x": -4,
      "y": 13,
      "z": -1,
      "name": "Soil_Dirt_Burnt"
    },
    {
      "x": -4,
      "y": 14,
      "z": -1,
      "name": "Empty"
    },
    {
      "x": -4,
      "y": 15,
      "z": -1,
      "name": "Empty"
    },
    {
      "x": -4,
      "y": 16,
      "z": -1,
      "name": "Empty"
    },
    {
      "x": -4,
      "y": 17,
      "z": -1,
      "name": "Empty"
    },
    {
      "x": -4,
      "y": 18,
      "z": -1,
      "name": "Empty"
    },
    {
      "x": -4,
      "y": 19,
      "z": -1,
      "name": "Wood_Jungle_Trunk",
      "support": 15
    },
    {
      "x": -4,
      "y": 20,
      "z": -1,
      "name": "Wood_Jungle_Trunk",
      "support": 15
    },
    {
      "x": -4,
      "y": 21,
      "z": -1,
      "name": "Wood_Jungle_Trunk",
      "support": 15
    },
    {
      "x": -4,
      "y": 22,
      "z": -1,
      "name": "Wood_Jungle_Trunk_Full",
      "support": 15
    },
    {
      "x": -4,
      "y": 23,
      "z": -1,
      "name": "Empty"
    },
    {
      "x": -4,
      "y": 24,
      "z": -1,
      "name": "Empty"
    },
    {
      "x": -4,
      "y": 25,
      "z": -1,
      "name": "Empty"
    },
    {
      "x": -4,
      "y": 26,
      "z": -1,
      "name": "Empty"
    },
    {
      "x": -4,
      "y": 27,
      "z": -1,
      "name": "Empty"
    },
    {
      "x": -4,
      "y": 28,
      "z": -1,
      "name": "Empty"
    },
    {
      "x": -4,
      "y": 29,
      "z": -1,
      "name": "Empty"
    },
    {
      "x": -4,
      "y": 40,
      "z": -1,
      "name": "Soil_Dirt_Burnt"
    },
    {
      "x": -4,
      "y": 41,
      "z": -1,
      "name": "Soil_Dirt_Burnt"
    },
    {
      "x": -4,
      "y": 42,
      "z": -1,
      "name": "Wood_Jungle_Trunk",
      "support": 15
    },
    {
      "x": -4,
      "y": 43,
      "z": -1,
      "name": "Wood_Jungle_Trunk",
      "support": 15
    },
    {
      "x": -4,
      "y": 44,
      "z": -1,
      "name": "Wood_Jungle_Trunk",
      "support": 15
    },
    {
      "x": -4,
      "y": 45,
      "z": -1,
      "name": "Wood_Jungle_Trunk_Full",
      "support": 15
    },
    {
      "x": -4,
      "y": 46,
      "z": -1,
      "name": "Soil_Dirt_Burnt"
    },
    {
      "x": -4,
      "y": 47,
      "z": -1,
      "name": "Soil_Dirt_Burnt"
    },
    {
      "x": -4,
      "y": 48,
      "z": -1,
      "name": "Soil_Dirt_Burnt"
    },
    {
      "x": -4,
      "y": 49,
      "z": -1,
      "name": "Soil_Dirt_Burnt"
    },
    {
      "x": -4,
      "y": 50,
      "z": -1,
      "name": "Soil_Grass_Full"
    },
    {
      "x": -4,
      "y": 78,
      "z": -1,
      "name": "Wood_Jungle_Branch_Long",
      "support": 15,
      "rotation": 4
    },
    {
      "x": -4,
      "y": 79,
      "z": -1,
      "name": "Plant_Leaves_Jungle",
      "support": 15
    },
    {
      "x": -4,
      "y": 80,
      "z": -1,
      "name": "Plant_Leaves_Jungle",
      "support": 15
    },
    {
      "x": -4,
      "y": 81,
      "z": -1,
      "name": "Plant_Leaves_Jungle",
      "support": 15
    },
    {
      "x": -4,
      "y": 82,
      "z": -1,
      "name": "Plant_Leaves_Jungle",
      "support": 15
    },
    {
      "x": -4,
      "y": -8,
      "z": 0,
      "name": "Rock_Magma_Cooled"
    },
    {
      "x": -4,
      "y": -7,
      "z": 0,
      "name": "Rock_Magma_Cooled"
    },
    {
      "x": -4,
      "y": -6,
      "z": 0,
      "name": "Rock_Magma_Cooled"
    },
    {
      "x": -4,
      "y": -5,
      "z": 0,
      "name": "Rock_Basalt"
    },
    {
      "x": -4,
      "y": -4,
      "z": 0,
      "name": "Rock_Basalt"
    },
    {
      "x": -4,
      "y": -3,
      "z": 0,
      "name": "Rock_Basalt"
    },
    {
      "x": -4,
      "y": -2,
      "z": 0,
      "name": "Rock_Basalt"
    },
    {
      "x": -4,
      "y": -1,
      "z": 0,
      "name": "Rock_Basalt"
    },
    {
      "x": -4,
      "y": 0,
      "z": 0,
      "name": "Rock_Basalt"
    },
    {
      "x": -4,
      "y": 1,
      "z": 0,
      "name": "Rock_Basalt"
    },
    {
      "x": -4,
      "y": 2,
      "z": 0,
      "name": "Rock_Basalt"
    },
    {
      "x": -4,
      "y": 3,
      "z": 0,
      "name": "Empty"
    },
    {
      "x": -4,
      "y": 4,
      "z": 0,
      "name": "Empty"
    },
    {
      "x": -4,
      "y": 5,
      "z": 0,
      "name": "Empty"
    },
    {
      "x": -4,
      "y": 6,
      "z": 0,
      "name": "Empty"
    },
    {
      "x": -4,
      "y": 10,
      "z": 0,
      "name": "Soil_Dirt_Burnt"
    },
    {
      "x": -4,
      "y": 11,
      "z": 0,
      "name": "Wood_Jungle_Trunk",
      "support": 15
    },
    {
      "x": -4,
      "y": 12,
      "z": 0,
      "name": "Wood_Jungle_Trunk",
      "support": 15
    },
    {
      "x": -4,
      "y": 13,
      "z": 0,
      "name": "Wood_Jungle_Trunk_Full",
      "support": 15
    },
    {
      "x": -4,
      "y": 14,
      "z": 0,
      "name": "Empty"
    },
    {
      "x": -4,
      "y": 15,
      "z": 0,
      "name": "Empty"
    },
    {
      "x": -4,
      "y": 16,
      "z": 0,
      "name": "Empty"
    },
    {
      "x": -4,
      "y": 17,
      "z": 0,
      "name": "Empty"
    },
    {
      "x": -4,
      "y": 18,
      "z": 0,
      "name": "Empty"
    },
    {
      "x": -4,
      "y": 19,
      "z": 0,
      "name": "Empty"
    },
    {
      "x": -4,
      "y": 20,
      "z": 0,
      "name": "Empty"
    },
    {
      "x": -4,
      "y": 21,
      "z": 0,
      "name": "Wood_Jungle_Trunk",
      "support": 15
    },
    {
      "x": -4,
      "y": 22,
      "z": 0,
      "name": "Wood_Jungle_Trunk",
      "support": 15
    },
    {
      "x": -4,
      "y": 23,
      "z": 0,
      "name": "Wood_Jungle_Trunk",
      "support": 15
    },
    {
      "x": -4,
      "y": 24,
      "z": 0,
      "name": "Wood_Jungle_Trunk",
      "support": 15
    },
    {
      "x": -4,
      "y": 25,
      "z": 0,
      "name": "Wood_Jungle_Trunk_Full",
      "support": 15
    },
    {
      "x": -4,
      "y": 26,
      "z": 0,
      "name": "Empty"
    },
    {
      "x": -4,
      "y": 27,
      "z": 0,
      "name": "Empty"
    },
    {
      "x": -4,
      "y": 28,
      "z": 0,
      "name": "Empty"
    },
    {
      "x": -4,
      "y": 29,
      "z": 0,
      "name": "Empty"
    },
    {
      "x": -4,
      "y": 30,
      "z": 0,
      "name": "Empty"
    },
    {
      "x": -4,
      "y": 41,
      "z": 0,
      "name": "Soil_Dirt_Burnt"
    },
    {
      "x": -4,
      "y": 42,
      "z": 0,
      "name": "Soil_Dirt_Burnt"
    },
    {
      "x": -4,
      "y": 43,
      "z": 0,
      "name": "Soil_Dirt_Burnt"
    },
    {
      "x": -4,
      "y": 44,
      "z": 0,
      "name": "Wood_Jungle_Trunk",
      "support": 15
    },
    {
      "x": -4,
      "y": 45,
      "z": 0,
      "name": "Wood_Jungle_Trunk",
      "support": 15
    },
    {
      "x": -4,
      "y": 46,
      "z": 0,
      "name": "Wood_Jungle_Trunk",
      "support": 15
    },
    {
      "x": -4,
      "y": 47,
      "z": 0,
      "name": "Wood_Jungle_Trunk",
      "support": 15
    },
    {
      "x": -4,
      "y": 48,
      "z": 0,
      "name": "Wood_Jungle_Trunk_Full",
      "support": 15
    },
    {
      "x": -4,
      "y": 49,
      "z": 0,
      "name": "Soil_Dirt_Burnt"
    },
    {
      "x": -4,
      "y": 50,
      "z": 0,
      "name": "Soil_Grass_Full"
    },
    {
      "x": -4,
      "y": 55,
      "z": 0,
      "name": "Plant_Crop_Mushroom_Block_Green"
    },
    {
      "x": -4,
      "y": 70,
      "z": 0,
      "name": "Plant_Leaves_Palm_Oasis",
      "support": 15
    },
    {
      "x": -4,
      "y": 71,
      "z": 0,
      "name": "Wood_Jungle_Branch_Long",
      "support": 15
    },
    {
      "x": -4,
      "y": 72,
      "z": 0,
      "name": "Wood_Jungle_Branch_Long",
      "support": 15
    },
    {
      "x": -4,
      "y": 73,
      "z": 0,
      "name": "Wood_Jungle_Branch_Long",
      "support": 15
    },
    {
      "x": -4,
      "y": 74,
      "z": 0,
      "name": "Wood_Jungle_Branch_Long",
      "support": 15
    },
    {
      "x": -4,
      "y": 75,
      "z": 0,
      "name": "Wood_Jungle_Branch_Long",
      "support": 15
    },
    {
      "x": -4,
      "y": 76,
      "z": 0,
      "name": "Wood_Jungle_Branch_Long",
      "support": 15
    },
    {
      "x": -4,
      "y": 77,
      "z": 0,
      "name": "Wood_Jungle_Branch_Long",
      "support": 15
    },
    {
      "x": -4,
      "y": 78,
      "z": 0,
      "name": "Wood_Jungle_Trunk",
      "support": 15
    },
    {
      "x": -4,
      "y": 79,
      "z": 0,
      "name": "Wood_Jungle_Trunk",
      "support": 15
    },
    {
      "x": -4,
      "y": 80,
      "z": 0,
      "name": "Wood_Jungle_Trunk",
      "support": 15
    },
    {
      "x": -4,
      "y": 81,
      "z": 0,
      "name": "Plant_Leaves_Jungle",
      "support": 15
    },
    {
      "x": -4,
      "y": -8,
      "z": 1,
      "name": "Rock_Magma_Cooled"
    },
    {
      "x": -4,
      "y": -7,
      "z": 1,
      "name": "Rock_Magma_Cooled"
    },
    {
      "x": -4,
      "y": -6,
      "z": 1,
      "name": "Rock_Magma_Cooled"
    },
    {
      "x": -4,
      "y": -5,
      "z": 1,
      "name": "Rock_Basalt"
    },
    {
      "x": -4,
      "y": -4,
      "z": 1,
      "name": "Rock_Basalt"
    },
    {
      "x": -4,
      "y": -3,
      "z": 1,
      "name": "Rock_Basalt"
    },
    {
      "x": -4,
      "y": -2,
      "z": 1,
      "name": "Rock_Basalt"
    },
    {
      "x": -4,
      "y": -1,
      "z": 1,
      "name": "Rock_Magma_Cooled"
    },
    {
      "x": -4,
      "y": 0,
      "z": 1,
      "name": "Rock_Basalt"
    },
    {
      "x": -4,
      "y": 1,
      "z": 1,
      "name": "Rock_Basalt"
    },
    {
      "x": -4,
      "y": 2,
      "z": 1,
      "name": "Rock_Basalt"
    },
    {
      "x": -4,
      "y": 3,
      "z": 1,
      "name": "Empty"
    },
    {
      "x": -4,
      "y": 4,
      "z": 1,
      "name": "Empty"
    },
    {
      "x": -4,
      "y": 10,
      "z": 1,
      "name": "Soil_Dirt_Burnt"
    },
    {
      "x": -4,
      "y": 11,
      "z": 1,
      "name": "Soil_Dirt_Burnt"
    },
    {
      "x": -4,
      "y": 12,
      "z": 1,
      "name": "Wood_Jungle_Trunk",
      "support": 15
    },
    {
      "x": -4,
      "y": 13,
      "z": 1,
      "name": "Wood_Jungle_Trunk",
      "support": 15
    },
    {
      "x": -4,
      "y": 14,
      "z": 1,
      "name": "Wood_Jungle_Trunk",
      "support": 15
    },
    {
      "x": -4,
      "y": 15,
      "z": 1,
      "name": "Wood_Jungle_Trunk_Full",
      "support": 15
    },
    {
      "x": -4,
      "y": 16,
      "z": 1,
      "name": "Empty"
    },
    {
      "x": -4,
      "y": 17,
      "z": 1,
      "name": "Empty"
    },
    {
      "x": -4,
      "y": 18,
      "z": 1,
      "name": "Empty"
    },
    {
      "x": -4,
      "y": 19,
      "z": 1,
      "name": "Empty"
    },
    {
      "x": -4,
      "y": 20,
      "z": 1,
      "name": "Empty"
    },
    {
      "x": -4,
      "y": 23,
      "z": 1,
      "name": "Wood_Jungle_Trunk",
      "support": 15
    },
    {
      "x": -4,
      "y": 24,
      "z": 1,
      "name": "Wood_Jungle_Trunk",
      "support": 15
    },
    {
      "x": -4,
      "y": 25,
      "z": 1,
      "name": "Wood_Jungle_Trunk",
      "support": 15
    },
    {
      "x": -4,
      "y": 26,
      "z": 1,
      "name": "Wood_Jungle_Trunk_Full",
      "support": 15
    },
    {
      "x": -4,
      "y": 27,
      "z": 1,
      "name": "Empty"
    },
    {
      "x": -4,
      "y": 28,
      "z": 1,
      "name": "Empty"
    },
    {
      "x": -4,
      "y": 29,
      "z": 1,
      "name": "Empty"
    },
    {
      "x": -4,
      "y": 30,
      "z": 1,
      "name": "Empty"
    },
    {
      "x": -4,
      "y": 31,
      "z": 1,
      "name": "Empty"
    },
    {
      "x": -4,
      "y": 43,
      "z": 1,
      "name": "Soil_Dirt_Burnt"
    },
    {
      "x": -4,
      "y": 44,
      "z": 1,
      "name": "Soil_Dirt_Burnt"
    },
    {
      "x": -4,
      "y": 45,
      "z": 1,
      "name": "Soil_Dirt_Burnt"
    },
    {
      "x": -4,
      "y": 46,
      "z": 1,
      "name": "Soil_Dirt_Burnt"
    },
    {
      "x": -4,
      "y": 47,
      "z": 1,
      "name": "Wood_Jungle_Trunk",
      "support": 15
    },
    {
      "x": -4,
      "y": 48,
      "z": 1,
      "name": "Wood_Jungle_Trunk",
      "support": 15
    },
    {
      "x": -4,
      "y": 49,
      "z": 1,
      "name": "Wood_Jungle_Trunk",
      "support": 15
    },
    {
      "x": -4,
      "y": 50,
      "z": 1,
      "name": "Wood_Jungle_Trunk",
      "support": 15
    },
    {
      "x": -4,
      "y": 51,
      "z": 1,
      "name": "Wood_Jungle_Trunk",
      "support": 15
    },
    {
      "x": -4,
      "y": 52,
      "z": 1,
      "name": "Wood_Jungle_Trunk",
      "support": 15
    },
    {
      "x": -4,
      "y": 53,
      "z": 1,
      "name": "Wood_Jungle_Trunk",
      "support": 15
    },
    {
      "x": -4,
      "y": 54,
      "z": 1,
      "name": "Wood_Jungle_Trunk",
      "support": 15
    },
    {
      "x": -4,
      "y": 55,
      "z": 1,
      "name": "Plant_Crop_Mushroom_Block_Green"
    },
    {
      "x": -4,
      "y": 56,
      "z": 1,
      "name": "Wood_Jungle_Trunk",
      "support": 15
    },
    {
      "x": -4,
      "y": 57,
      "z": 1,
      "name": "Wood_Jungle_Trunk_Full",
      "support": 15
    },
    {
      "x": -4,
      "y": 78,
      "z": 1,
      "name": "Wood_Jungle_Branch_Long",
      "support": 15,
      "rotation": 5
    },
    {
      "x": -4,
      "y": 79,
      "z": 1,
      "name": "Wood_Jungle_Trunk",
      "support": 15
    },
    {
      "x": -4,
      "y": 80,
      "z": 1,
      "name": "Plant_Leaves_Jungle",
      "support": 15
    },
    {
      "x": -4,
      "y": 81,
      "z": 1,
      "name": "Plant_Leaves_Jungle",
      "support": 15
    },
    {
      "x": -4,
      "y": -8,
      "z": 2,
      "name": "Rock_Magma_Cooled"
    },
    {
      "x": -4,
      "y": -7,
      "z": 2,
      "name": "Rock_Magma_Cooled"
    },
    {
      "x": -4,
      "y": -6,
      "z": 2,
      "name": "Rock_Magma_Cooled"
    },
    {
      "x": -4,
      "y": -5,
      "z": 2,
      "name": "Rock_Magma_Cooled"
    },
    {
      "x": -4,
      "y": -4,
      "z": 2,
      "name": "Rock_Basalt"
    },
    {
      "x": -4,
      "y": -3,
      "z": 2,
      "name": "Rock_Basalt"
    },
    {
      "x": -4,
      "y": -2,
      "z": 2,
      "name": "Rock_Magma_Cooled"
    },
    {
      "x": -4,
      "y": -1,
      "z": 2,
      "name": "Rock_Magma_Cooled"
    },
    {
      "x": -4,
      "y": 0,
      "z": 2,
      "name": "Rock_Magma_Cooled"
    },
    {
      "x": -4,
      "y": 1,
      "z": 2,
      "name": "Rock_Basalt"
    },
    {
      "x": -4,
      "y": 2,
      "z": 2,
      "name": "Rock_Basalt"
    },
    {
      "x": -4,
      "y": 3,
      "z": 2,
      "name": "Rock_Basalt"
    },
    {
      "x": -4,
      "y": 10,
      "z": 2,
      "name": "Soil_Dirt_Burnt"
    },
    {
      "x": -4,
      "y": 11,
      "z": 2,
      "name": "Soil_Dirt_Burnt"
    },
    {
      "x": -4,
      "y": 12,
      "z": 2,
      "name": "Soil_Dirt_Burnt"
    },
    {
      "x": -4,
      "y": 13,
      "z": 2,
      "name": "Soil_Dirt_Burnt"
    },
    {
      "x": -4,
      "y": 14,
      "z": 2,
      "name": "Wood_Jungle_Trunk",
      "support": 15
    },
    {
      "x": -4,
      "y": 15,
      "z": 2,
      "name": "Wood_Jungle_Trunk",
      "support": 15
    },
    {
      "x": -4,
      "y": 16,
      "z": 2,
      "name": "Wood_Jungle_Trunk_Full",
      "support": 15
    },
    {
      "x": -4,
      "y": 17,
      "z": 2,
      "name": "Empty"
    },
    {
      "x": -4,
      "y": 18,
      "z": 2,
      "name": "Empty"
    },
    {
      "x": -4,
      "y": 19,
      "z": 2,
      "name": "Empty"
    },
    {
      "x": -4,
      "y": 20,
      "z": 2,
      "name": "Empty"
    },
    {
      "x": -4,
      "y": 21,
      "z": 2,
      "name": "Empty"
    },
    {
      "x": -4,
      "y": 25,
      "z": 2,
      "name": "Wood_Jungle_Trunk",
      "support": 15
    },
    {
      "x": -4,
      "y": 26,
      "z": 2,
      "name": "Wood_Jungle_Trunk",
      "support": 15
    },
    {
      "x": -4,
      "y": 27,
      "z": 2,
      "name": "Wood_Jungle_Trunk",
      "support": 15
    },
    {
      "x": -4,
      "y": 28,
      "z": 2,
      "name": "Wood_Jungle_Trunk_Full",
      "support": 15
    },
    {
      "x": -4,
      "y": 55,
      "z": 2,
      "name": "Plant_Crop_Mushroom_Block_Green"
    },
    {
      "x": -4,
      "y": 80,
      "z": 2,
      "name": "Plant_Leaves_Jungle",
      "support": 15
    },
    {
      "x": -4,
      "y": 81,
      "z": 2,
      "name": "Plant_Leaves_Jungle",
      "support": 15
    },
    {
      "x": -4,
      "y": -7,
      "z": 3,
      "name": "Rock_Magma_Cooled"
    },
    {
      "x": -4,
      "y": -6,
      "z": 3,
      "name": "Rock_Magma_Cooled"
    },
    {
      "x": -4,
      "y": -5,
      "z": 3,
      "name": "Rock_Magma_Cooled"
    },
    {
      "x": -4,
      "y": -4,
      "z": 3,
      "name": "Rock_Magma_Cooled"
    },
    {
      "x": -4,
      "y": -3,
      "z": 3,
      "name": "Rock_Magma_Cooled"
    },
    {
      "x": -4,
      "y": -2,
      "z": 3,
      "name": "Rock_Magma_Cooled"
    },
    {
      "x": -4,
      "y": -1,
      "z": 3,
      "name": "Rock_Magma_Cooled"
    },
    {
      "x": -4,
      "y": 0,
      "z": 3,
      "name": "Rock_Magma_Cooled"
    },
    {
      "x": -4,
      "y": 1,
      "z": 3,
      "name": "Rock_Magma_Cooled"
    },
    {
      "x": -4,
      "y": 2,
      "z": 3,
      "name": "Rock_Basalt"
    },
    {
      "x": -4,
      "y": 3,
      "z": 3,
      "name": "Rock_Basalt"
    },
    {
      "x": -4,
      "y": 11,
      "z": 3,
      "name": "Soil_Dirt_Burnt"
    },
    {
      "x": -4,
      "y": 12,
      "z": 3,
      "name": "Soil_Dirt_Burnt"
    },
    {
      "x": -4,
      "y": 13,
      "z": 3,
      "name": "Soil_Dirt_Burnt"
    },
    {
      "x": -4,
      "y": 14,
      "z": 3,
      "name": "Soil_Dirt_Burnt"
    },
    {
      "x": -4,
      "y": 15,
      "z": 3,
      "name": "Soil_Dirt_Burnt"
    },
    {
      "x": -4,
      "y": 16,
      "z": 3,
      "name": "Wood_Jungle_Trunk_Full",
      "support": 15
    },
    {
      "x": -4,
      "y": 17,
      "z": 3,
      "name": "Soil_Dirt_Burnt"
    },
    {
      "x": -4,
      "y": 19,
      "z": 3,
      "name": "Empty"
    },
    {
      "x": -4,
      "y": 20,
      "z": 3,
      "name": "Empty"
    },
    {
      "x": -4,
      "y": 21,
      "z": 3,
      "name": "Empty"
    },
    {
      "x": -4,
      "y": 80,
      "z": 3,
      "name": "Plant_Leaves_Jungle",
      "support": 15
    },
    {
      "x": -4,
      "y": 81,
      "z": 3,
      "name": "Plant_Leaves_Jungle",
      "support": 15
    },
    {
      "x": -4,
      "y": -6,
      "z": 4,
      "name": "Rock_Magma_Cooled"
    },
    {
      "x": -4,
      "y": -5,
      "z": 4,
      "name": "Rock_Magma_Cooled"
    },
    {
      "x": -4,
      "y": -4,
      "z": 4,
      "name": "Rock_Magma_Cooled"
    },
    {
      "x": -4,
      "y": -3,
      "z": 4,
      "name": "Rock_Magma_Cooled"
    },
    {
      "x": -4,
      "y": -2,
      "z": 4,
      "name": "Rock_Magma_Cooled"
    },
    {
      "x": -4,
      "y": -1,
      "z": 4,
      "name": "Rock_Magma_Cooled"
    },
    {
      "x": -4,
      "y": 0,
      "z": 4,
      "name": "Rock_Magma_Cooled"
    },
    {
      "x": -4,
      "y": 1,
      "z": 4,
      "name": "Rock_Basalt"
    },
    {
      "x": -4,
      "y": 2,
      "z": 4,
      "name": "Rock_Basalt"
    },
    {
      "x": -4,
      "y": 3,
      "z": 4,
      "name": "Rock_Basalt"
    },
    {
      "x": -4,
      "y": 13,
      "z": 4,
      "name": "Soil_Dirt_Burnt"
    },
    {
      "x": -4,
      "y": 14,
      "z": 4,
      "name": "Soil_Dirt_Burnt"
    },
    {
      "x": -4,
      "y": 15,
      "z": 4,
      "name": "Soil_Dirt_Burnt"
    },
    {
      "x": -4,
      "y": 16,
      "z": 4,
      "name": "Soil_Dirt_Burnt"
    },
    {
      "x": -4,
      "y": 80,
      "z": 4,
      "name": "Plant_Leaves_Jungle",
      "support": 15
    },
    {
      "x": -4,
      "y": -6,
      "z": 5,
      "name": "Rock_Magma_Cooled"
    },
    {
      "x": -4,
      "y": -5,
      "z": 5,
      "name": "Rock_Magma_Cooled"
    },
    {
      "x": -4,
      "y": -4,
      "z": 5,
      "name": "Rock_Magma_Cooled"
    },
    {
      "x": -4,
      "y": -3,
      "z": 5,
      "name": "Rock_Magma_Cooled"
    },
    {
      "x": -4,
      "y": -2,
      "z": 5,
      "name": "Rock_Magma_Cooled"
    },
    {
      "x": -4,
      "y": -1,
      "z": 5,
      "name": "Rock_Magma_Cooled"
    },
    {
      "x": -4,
      "y": 80,
      "z": 5,
      "name": "Plant_Leaves_Jungle",
      "support": 15
    },
    {
      "x": -4,
      "y": -5,
      "z": 6,
      "name": "Rock_Magma_Cooled"
    },
    {
      "x": -4,
      "y": -4,
      "z": 6,
      "name": "Rock_Basalt"
    },
    {
      "x": -4,
      "y": -3,
      "z": 6,
      "name": "Rock_Basalt"
    },
    {
      "x": -4,
      "y": -2,
      "z": 6,
      "name": "Rock_Basalt"
    },
    {
      "x": -4,
      "y": 80,
      "z": 6,
      "name": "Wood_Jungle_Branch_Long",
      "support": 15,
      "rotation": 5
    },
    {
      "x": -4,
      "y": 81,
      "z": 6,
      "name": "Plant_Leaves_Jungle",
      "support": 15
    },
    {
      "x": -4,
      "y": 80,
      "z": 7,
      "name": "Plant_Leaves_Jungle",
      "support": 15
    },
    {
      "x": -4,
      "y": 81,
      "z": 7,
      "name": "Plant_Leaves_Jungle",
      "support": 15
    },
    {
      "x": -4,
      "y": 80,
      "z": 8,
      "name": "Plant_Leaves_Jungle",
      "support": 15
    },
    {
      "x": -3,
      "y": -6,
      "z": -8,
      "name": "Rock_Magma_Cooled"
    },
    {
      "x": -3,
      "y": -5,
      "z": -8,
      "name": "Rock_Magma_Cooled"
    },
    {
      "x": -3,
      "y": -4,
      "z": -8,
      "name": "Rock_Magma_Cooled"
    },
    {
      "x": -3,
      "y": -3,
      "z": -8,
      "name": "Rock_Magma_Cooled"
    },
    {
      "x": -3,
      "y": -2,
      "z": -8,
      "name": "Rock_Magma_Cooled"
    },
    {
      "x": -3,
      "y": 74,
      "z": -8,
      "name": "Plant_Leaves_Jungle",
      "support": 15
    },
    {
      "x": -3,
      "y": -7,
      "z": -7,
      "name": "Rock_Magma_Cooled"
    },
    {
      "x": -3,
      "y": -6,
      "z": -7,
      "name": "Rock_Magma_Cooled"
    },
    {
      "x": -3,
      "y": -5,
      "z": -7,
      "name": "Rock_Magma_Cooled"
    },
    {
      "x": -3,
      "y": -4,
      "z": -7,
      "name": "Rock_Magma_Cooled"
    },
    {
      "x": -3,
      "y": -3,
      "z": -7,
      "name": "Rock_Magma_Cooled"
    },
    {
      "x": -3,
      "y": -2,
      "z": -7,
      "name": "Rock_Magma_Cooled"
    },
    {
      "x": -3,
      "y": -1,
      "z": -7,
      "name": "Rock_Basalt"
    },
    {
      "x": -3,
      "y": 0,
      "z": -7,
      "name": "Rock_Basalt"
    },
    {
      "x": -3,
      "y": -7,
      "z": -6,
      "name": "Rock_Magma_Cooled"
    },
    {
      "x": -3,
      "y": -6,
      "z": -6,
      "name": "Rock_Magma_Cooled"
    },
    {
      "x": -3,
      "y": -5,
      "z": -6,
      "name": "Rock_Magma_Cooled"
    },
    {
      "x": -3,
      "y": -4,
      "z": -6,
      "name": "Rock_Basalt"
    },
    {
      "x": -3,
      "y": -3,
      "z": -6,
      "name": "Rock_Basalt"
    },
    {
      "x": -3,
      "y": -2,
      "z": -6,
      "name": "Rock_Basalt"
    },
    {
      "x": -3,
      "y": -1,
      "z": -6,
      "name": "Rock_Basalt"
    },
    {
      "x": -3,
      "y": 0,
      "z": -6,
      "name": "Rock_Basalt"
    },
    {
      "x": -3,
      "y": 6,
      "z": -6,
      "name": "Soil_Dirt_Burnt"
    },
    {
      "x": -3,
      "y": 7,
      "z": -6,
      "name": "Soil_Dirt_Burnt"
    },
    {
      "x": -3,
      "y": 8,
      "z": -6,
      "name": "Soil_Dirt_Burnt"
    },
    {
      "x": -3,
      "y": 9,
      "z": -6,
      "name": "Soil_Dirt_Burnt"
    },
    {
      "x": -3,
      "y": 10,
      "z": -6,
      "name": "Soil_Dirt_Burnt"
    },
    {
      "x": -3,
      "y": 73,
      "z": -6,
      "name": "Plant_Leaves_Jungle",
      "support": 15
    },
    {
      "x": -3,
      "y": 74,
      "z": -6,
      "name": "Plant_Leaves_Jungle",
      "support": 15
    },
    {
      "x": -3,
      "y": -7,
      "z": -5,
      "name": "Rock_Magma_Cooled"
    },
    {
      "x": -3,
