{
  "version": 8,
  "blockIdVersion": 11,
  "anchorX": 0,
  "anchorY": 50,
  "anchorZ": 0,
  "blocks": [
    {
      "x": -12,
      "y": 77,
      "z": 1,
      "name": "Plant_Leaves_Jungle",
      "support": 15
    },
    {
      "x": -12,
      "y": 77,
      "z": 2,
      "name": "Plant_Leaves_Palm",
      "support": 15
    },
    {
      "x": -12,
      "y": 77,
      "z": 3,
      "name": "Plant_Leaves_Palm",
      "support": 15
    },
    {
      "x": -12,
      "y": 78,
      "z": 3,
      "name": "Plant_Leaves_Palm",
      "support": 15
    },
    {
      "x": -12,
      "y": 77,
      "z": 4,
      "name": "Plant_Leaves_Palm",
      "support": 15
    },
    {
      "x": -11,
      "y": 77,
      "z": -1,
      "name": "Plant_Leaves_Jungle",
      "support": 15
    },
    {
      "x": -11,
      "y": 78,
      "z": -1,
      "name": "Plant_Leaves_Jungle",
      "support": 15
    },
    {
      "x": -11,
      "y": 78,
      "z": 0,
      "name": "Plant_Leaves_Jungle",
      "support": 15
    },
    {
      "x": -11,
      "y": 78,
      "z": 1,
      "name": "Plant_Leaves_Jungle",
      "support": 15
    },
    {
      "x": -11,
      "y": 77,
      "z": 2,
      "name": "Plant_Leaves_Jungle",
      "support": 15
    },
    {
      "x": -11,
      "y": 78,
      "z": 2,
      "name": "Plant_Leaves_Palm",
      "support": 15
    },
    {
      "x": -11,
      "y": 77,
      "z": 3,
      "name": "Plant_Leaves_Palm",
      "support": 15
    },
    {
      "x": -11,
      "y": 78,
      "z": 3,
      "name": "Plant_Leaves_Palm",
      "support": 15
    },
    {
      "x": -11,
      "y": 77,
      "z": 4,
      "name": "Plant_Leaves_Jungle",
      "support": 15
    },
    {
      "x": -11,
      "y": 78,
      "z": 4,
      "name": "Plant_Leaves_Palm",
      "support": 15
    },
    {
      "x": -11,
      "y": 77,
      "z": 5,
      "name": "Plant_Leaves_Jungle",
      "support": 15
    },
    {
      "x": -11,
      "y": 77,
      "z": 6,
      "name": "Plant_Leaves_Jungle",
      "support": 15
    },
    {
      "x": -11,
      "y": 77,
      "z": 7,
      "name": "Plant_Leaves_Jungle",
      "support": 15
    },
    {
      "x": -10,
      "y": 77,
      "z": -3,
      "name": "Plant_Leaves_Jungle",
      "support": 15
    },
    {
      "x": -10,
      "y": 78,
      "z": -2,
      "name": "Plant_Leaves_Jungle",
      "support": 15
    },
    {
      "x": -10,
      "y": 78,
      "z": -1,
      "name": "Plant_Leaves_Jungle",
      "support": 15
    },
    {
      "x": -10,
      "y": 78,
      "z": 0,
      "name": "Plant_Leaves_Jungle",
      "support": 15
    },
    {
      "x": -10,
      "y": 77,
      "z": 1,
      "name": "Plant_Leaves_Jungle",
      "support": 15
    },
    {
      "x": -10,
      "y": 77,
      "z": 2,
      "name": "Plant_Leaves_Jungle",
      "support": 15
    },
    {
      "x": -10,
      "y": 78,
      "z": 2,
      "name": "Plant_Leaves_Jungle",
      "support": 15
    },
    {
      "x": -10,
      "y": 77,
      "z": 3,
      "name": "Wood_Jungle_Trunk",
      "support": 15
    },
    {
      "x": -10,
      "y": 78,
      "z": 3,
      "name": "Plant_Leaves_Jungle",
      "support": 15
    },
    {
      "x": -10,
      "y": 77,
      "z": 4,
      "name": "Wood_Jungle_Branch_Long",
      "support": 15,
      "rotation": 4
    },
    {
      "x": -10,
      "y": 78,
      "z": 4,
      "name": "Plant_Leaves_Jungle",
      "support": 15
    },
    {
      "x": -10,
      "y": 77,
      "z": 5,
      "name": "Wood_Jungle_Branch_Long",
      "support": 15,
      "rotation": 4
    },
    {
      "x": -10,
      "y": 78,
      "z": 5,
      "name": "Plant_Leaves_Jungle",
      "support": 15
    },
    {
      "x": -10,
      "y": 76,
      "z": 6,
      "name": "Plant_Leaves_Jungle",
      "support": 15
    },
    {
      "x": -10,
      "y": 77,
      "z": 6,
      "name": "Plant_Leaves_Jungle",
      "support": 15
    },
    {
      "x": -9,
      "y": 70,
      "z": -3,
      "name": "Plant_Leaves_Jungle",
      "support": 15
    },
    {
      "x": -9,
      "y": 77,
      "z": -3,
      "name": "Plant_Leaves_Jungle",
      "support": 15
    },
    {
      "x": -9,
      "y": 78,
      "z": -3,
      "name": "Plant_Leaves_Jungle",
      "support": 15
    },
    {
      "x": -9,
      "y": 78,
      "z": -2,
      "name": "Plant_Leaves_Jungle",
      "support": 15
    },
    {
      "x": -9,
      "y": 78,
      "z": -1,
      "name": "Plant_Leaves_Jungle",
      "support": 15
    },
    {
      "x": -9,
      "y": 78,
      "z": 0,
      "name": "Plant_Leaves_Jungle",
      "support": 15
    },
    {
      "x": -9,
      "y": 78,
      "z": 1,
      "name": "Plant_Leaves_Jungle",
      "support": 15
    },
    {
      "x": -9,
      "y": 77,
      "z": 2,
      "name": "Plant_Leaves_Jungle",
      "support": 15
    },
    {
      "x": -9,
      "y": 78,
      "z": 2,
      "name": "Plant_Leaves_Jungle",
      "support": 15
    },
    {
      "x": -9,
      "y": 62,
      "z": 3,
      "name": "Plant_Leaves_Palm_Oasis",
      "support": 15
    },
    {
      "x": -9,
      "y": 63,
      "z": 3,
      "name": "Wood_Jungle_Branch_Long",
      "support": 15
    },
    {
      "x": -9,
      "y": 64,
      "z": 3,
      "name": "Wood_Jungle_Branch_Long",
      "support": 15
    },
    {
      "x": -9,
      "y": 65,
      "z": 3,
      "name": "Wood_Jungle_Branch_Long",
      "support": 15
    },
    {
      "x": -9,
      "y": 66,
      "z": 3,
      "name": "Wood_Jungle_Branch_Long",
      "support": 15
    },
    {
      "x": -9,
      "y": 67,
      "z": 3,
      "name": "Wood_Jungle_Branch_Long",
      "support": 15
    },
    {
      "x": -9,
      "y": 68,
      "z": 3,
      "name": "Wood_Jungle_Branch_Long",
      "support": 15
    },
    {
      "x": -9,
      "y": 69,
      "z": 3,
      "name": "Wood_Jungle_Branch_Long",
      "support": 15
    },
    {
      "x": -9,
      "y": 70,
      "z": 3,
      "name": "Wood_Jungle_Branch_Long",
      "support": 15
    },
    {
      "x": -9,
      "y": 71,
      "z": 3,
      "name": "Wood_Jungle_Branch_Long",
      "support": 15
    },
    {
      "x": -9,
      "y": 72,
      "z": 3,
      "name": "Wood_Jungle_Branch_Long",
      "support": 15
    },
    {
      "x": -9,
      "y": 73,
      "z": 3,
      "name": "Wood_Jungle_Branch_Long",
      "support": 15
    },
    {
      "x": -9,
      "y": 74,
      "z": 3,
      "name": "Wood_Jungle_Branch_Long",
      "support": 15
    },
    {
      "x": -9,
      "y": 75,
      "z": 3,
      "name": "Wood_Jungle_Branch_Long",
      "support": 15
    },
    {
      "x": -9,
      "y": 76,
      "z": 3,
      "name": "Wood_Jungle_Branch_Long",
      "support": 15
    },
    {
      "x": -9,
      "y": 77,
      "z": 3,
      "name": "Wood_Jungle_Trunk",
      "support": 15
    },
    {
      "x": -9,
      "y": 78,
      "z": 3,
      "name": "Plant_Leaves_Jungle",
      "support": 15
    },
    {
      "x": -9,
      "y": 77,
      "z": 4,
      "name": "Plant_Leaves_Jungle",
      "support": 15
    },
    {
      "x": -9,
      "y": 78,
      "z": 4,
      "name": "Plant_Leaves_Jungle",
      "support": 15
    },
    {
      "x": -9,
      "y": 77,
      "z": 5,
      "name": "Plant_Leaves_Jungle",
      "support": 15
    },
    {
      "x": -9,
      "y": 77,
      "z": 6,
      "name": "Plant_Leaves_Jungle",
      "support": 15
    },
    {
      "x": -9,
      "y": 77,
      "z": 7,
      "name": "Plant_Leaves_Jungle",
      "support": 15
    },
    {
      "x": -8,
      "y": 70,
      "z": -6,
      "name": "Plant_Leaves_Jungle",
      "support": 15
    },
    {
      "x": -8,
      "y": 70,
      "z": -5,
      "name": "Plant_Leaves_Jungle",
      "support": 15
    },
    {
      "x": -8,
      "y": 70,
      "z": -4,
      "name": "Plant_Leaves_Jungle",
      "support": 15
    },
    {
      "x": -8,
      "y": 77,
      "z": -4,
      "name": "Plant_Leaves_Jungle",
      "support": 15
    },
    {
      "x": -8,
      "y": 65,
      "z": -3,
      "name": "Plant_Leaves_Palm_Oasis",
      "support": 15
    },
    {
      "x": -8,
      "y": 66,
      "z": -3,
      "name": "Wood_Jungle_Branch_Long",
      "support": 15
    },
    {
      "x": -8,
      "y": 67,
      "z": -3,
      "name": "Wood_Jungle_Branch_Long",
      "support": 15
    },
    {
      "x": -8,
      "y": 68,
      "z": -3,
      "name": "Wood_Jungle_Branch_Long",
      "support": 15
    },
    {
      "x": -8,
      "y": 69,
      "z": -3,
      "name": "Wood_Jungle_Branch_Long",
      "support": 15
    },
    {
      "x": -8,
      "y": 70,
      "z": -3,
      "name": "Wood_Jungle_Branch_Corner",
      "support": 15,
      "rotation": 9
    },
    {
      "x": -8,
      "y": 71,
      "z": -3,
      "name": "Plant_Leaves_Jungle",
      "support": 15
    },
    {
      "x": -8,
      "y": 75,
      "z": -3,
      "name": "Plant_Leaves_Jungle",
      "support": 15
    },
    {
      "x": -8,
      "y": 76,
      "z": -3,
      "name": "Plant_Leaves_Jungle",
      "support": 15
    },
    {
      "x": -8,
      "y": 77,
      "z": -3,
      "name": "Plant_Leaves_Jungle",
      "support": 15
    },
    {
      "x": -8,
      "y": 29,
      "z": -2,
      "name": "Soil_Dirt_Burnt"
    },
    {
      "x": -8,
      "y": 30,
      "z": -2,
      "name": "Soil_Dirt_Burnt"
    },
    {
      "x": -8,
      "y": 70,
      "z": -2,
      "name": "Plant_Leaves_Jungle",
      "support": 15
    },
    {
      "x": -8,
      "y": 71,
      "z": -2,
      "name": "Plant_Leaves_Jungle",
      "support": 15
    },
    {
      "x": -8,
      "y": 77,
      "z": -2,
      "name": "Wood_Jungle_Branch_Long",
      "support": 15,
      "rotation": 4
    },
    {
      "x": -8,
      "y": 78,
      "z": -2,
      "name": "Plant_Leaves_Jungle",
      "support": 15
    },
    {
      "x": -8,
      "y": 29,
      "z": -1,
      "name": "Soil_Dirt_Burnt"
    },
    {
      "x": -8,
      "y": 30,
      "z": -1,
      "name": "Soil_Dirt_Burnt"
    },
    {
      "x": -8,
      "y": 77,
      "z": -1,
      "name": "Wood_Jungle_Branch_Long",
      "support": 15,
      "rotation": 4
    },
    {
      "x": -8,
      "y": 78,
      "z": -1,
      "name": "Plant_Leaves_Jungle",
      "support": 15
    },
    {
      "x": -8,
      "y": 77,
      "z": 0,
      "name": "Wood_Jungle_Branch_Long",
      "support": 15,
      "rotation": 4
    },
    {
      "x": -8,
      "y": 78,
      "z": 0,
      "name": "Plant_Leaves_Jungle",
      "support": 15
    },
    {
      "x": -8,
      "y": 77,
      "z": 1,
      "name": "Wood_Jungle_Branch_Long",
      "support": 15,
      "rotation": 4
    },
    {
      "x": -8,
      "y": 78,
      "z": 1,
      "name": "Plant_Leaves_Jungle",
      "support": 15
    },
    {
      "x": -8,
      "y": 77,
      "z": 2,
      "name": "Wood_Jungle_Trunk",
      "support": 15
    },
    {
      "x": -8,
      "y": 78,
      "z": 2,
      "name": "Plant_Leaves_Jungle",
      "support": 15
    },
    {
      "x": -8,
      "y": 77,
      "z": 3,
      "name": "Wood_Jungle_Trunk",
      "support": 15
    },
    {
      "x": -8,
      "y": 78,
      "z": 3,
      "name": "Plant_Leaves_Jungle",
      "support": 15
    },
    {
      "x": -8,
      "y": 77,
      "z": 4,
      "name": "Plant_Leaves_Jungle",
      "support": 15
    },
    {
      "x": -8,
      "y": 78,
      "z": 4,
      "name": "Plant_Leaves_Jungle",
      "support": 15
    },
    {
      "x": -8,
      "y": 78,
      "z": 5,
      "name": "Plant_Leaves_Jungle",
      "support": 15
    },
    {
      "x": -8,
      "y": 77,
      "z": 6,
      "name": "Plant_Leaves_Jungle",
      "support": 15
    },
    {
      "x": -8,
      "y": 78,
      "z": 6,
      "name": "Plant_Leaves_Jungle",
      "support": 15
    },
    {
      "x": -8,
      "y": 77,
      "z": 7,
      "name": "Plant_Leaves_Jungle",
      "support": 15
    },
    {
      "x": -7,
      "y": 70,
      "z": -9,
      "name": "Plant_Leaves_Jungle",
      "support": 15
    },
    {
      "x": -7,
      "y": 70,
      "z": -8,
      "name": "Plant_Leaves_Jungle",
      "support": 15
    },
    {
      "x": -7,
      "y": 71,
      "z": -8,
      "name": "Plant_Leaves_Jungle",
      "support": 15
    },
    {
      "x": -7,
      "y": 70,
      "z": -7,
      "name": "Plant_Leaves_Jungle",
      "support": 15
    },
    {
      "x": -7,
      "y": 71,
      "z": -7,
      "name": "Plant_Leaves_Jungle",
      "support": 15
    },
    {
      "x": -7,
      "y": 71,
      "z": -6,
      "name": "Plant_Leaves_Jungle",
      "support": 15
    },
    {
      "x": -7,
      "y": 70,
      "z": -5,
      "name": "Plant_Leaves_Jungle",
      "support": 15
    },
    {
      "x": -7,
      "y": 71,
      "z": -5,
      "name": "Plant_Leaves_Jungle",
      "support": 15
    },
    {
      "x": -7,
      "y": 70,
      "z": -4,
      "name": "Plant_Leaves_Jungle",
      "support": 15
    },
    {
      "x": -7,
      "y": 71,
      "z": -4,
      "name": "Plant_Leaves_Jungle",
      "support": 15
    },
    {
      "x": -7,
      "y": 76,
      "z": -4,
      "name": "Plant_Leaves_Jungle",
      "support": 15
    },
    {
      "x": -7,
      "y": 29,
      "z": -3,
      "name": "Soil_Dirt_Burnt"
    },
    {
      "x": -7,
      "y": 70,
      "z": -3,
      "name": "Wood_Jungle_Branch_Long",
      "support": 15,
      "rotation": 5
    },
    {
      "x": -7,
      "y": 71,
      "z": -3,
      "name": "Plant_Leaves_Jungle",
      "support": 15
    },
    {
      "x": -7,
      "y": 76,
      "z": -3,
      "name": "Plant_Leaves_Jungle",
      "support": 15
    },
    {
      "x": -7,
      "y": 77,
      "z": -3,
      "name": "Plant_Leaves_Jungle",
      "support": 15
    },
    {
      "x": -7,
      "y": 28,
      "z": -2,
      "name": "Soil_Dirt_Burnt"
    },
    {
      "x": -7,
      "y": 29,
      "z": -2,
      "name": "Soil_Dirt_Burnt"
    },
    {
      "x": -7,
      "y": 30,
      "z": -2,
      "name": "Soil_Dirt_Burnt"
    },
    {
      "x": -7,
      "y": 31,
      "z": -2,
      "name": "Soil_Dirt_Burnt"
    },
    {
      "x": -7,
      "y": 70,
      "z": -2,
      "name": "Plant_Leaves_Jungle",
      "support": 15
    },
    {
      "x": -7,
      "y": 71,
      "z": -2,
      "name": "Plant_Leaves_Jungle",
      "support": 15
    },
    {
      "x": -7,
      "y": 76,
      "z": -2,
      "name": "Plant_Leaves_Jungle",
      "support": 15
    },
    {
      "x": -7,
      "y": 77,
      "z": -2,
      "name": "Plant_Leaves_Jungle",
      "support": 15
    },
    {
      "x": -7,
      "y": 78,
      "z": -2,
      "name": "Plant_Leaves_Jungle",
      "support": 15
    },
    {
      "x": -7,
      "y": 28,
      "z": -1,
      "name": "Soil_Dirt_Burnt"
    },
    {
      "x": -7,
      "y": 29,
      "z": -1,
      "name": "Soil_Dirt_Burnt"
    },
    {
      "x": -7,
      "y": 30,
      "z": -1,
      "name": "Soil_Dirt_Burnt"
    },
    {
      "x": -7,
      "y": 31,
      "z": -1,
      "name": "Soil_Dirt_Burnt"
    },
    {
      "x": -7,
      "y": 76,
      "z": -1,
      "name": "Plant_Leaves_Jungle",
      "support": 15
    },
    {
      "x": -7,
      "y": 77,
      "z": -1,
      "name": "Plant_Leaves_Jungle",
      "support": 15
    },
    {
      "x": -7,
      "y": 78,
      "z": -1,
      "name": "Plant_Leaves_Jungle",
      "support": 15
    },
    {
      "x": -7,
      "y": 28,
      "z": 0,
      "name": "Soil_Dirt_Burnt"
    },
    {
      "x": -7,
      "y": 29,
      "z": 0,
      "name": "Soil_Dirt_Burnt"
    },
    {
      "x": -7,
      "y": 30,
      "z": 0,
      "name": "Soil_Dirt_Burnt"
    },
    {
      "x": -7,
      "y": 31,
      "z": 0,
      "name": "Soil_Dirt_Burnt"
    },
    {
      "x": -7,
      "y": 32,
      "z": 0,
      "name": "Soil_Dirt_Burnt"
    },
    {
      "x": -7,
      "y": 77,
      "z": 0,
      "name": "Plant_Leaves_Jungle",
      "support": 15
    },
    {
      "x": -7,
      "y": 78,
      "z": 0,
      "name": "Plant_Leaves_Jungle",
      "support": 15
    },
    {
      "x": -7,
      "y": 28,
      "z": 1,
      "name": "Soil_Dirt_Burnt"
    },
    {
      "x": -7,
      "y": 29,
      "z": 1,
      "name": "Soil_Dirt_Burnt"
    },
    {
      "x": -7,
      "y": 30,
      "z": 1,
      "name": "Soil_Dirt_Burnt"
    },
    {
      "x": -7,
      "y": 31,
      "z": 1,
      "name": "Soil_Dirt_Burnt"
    },
    {
      "x": -7,
      "y": 76,
      "z": 1,
      "name": "Wood_Jungle_Trunk",
      "support": 15
    },
    {
      "x": -7,
      "y": 77,
      "z": 1,
      "name": "Plant_Leaves_Jungle",
      "support": 15
    },
    {
      "x": -7,
      "y": 78,
      "z": 1,
      "name": "Plant_Leaves_Jungle",
      "support": 15
    },
    {
      "x": -7,
      "y": 29,
      "z": 2,
      "name": "Soil_Dirt_Burnt"
    },
    {
      "x": -7,
      "y": 30,
      "z": 2,
      "name": "Soil_Dirt_Burnt"
    },
    {
      "x": -7,
      "y": 76,
      "z": 2,
      "name": "Wood_Jungle_Trunk",
      "support": 15
    },
    {
      "x": -7,
      "y": 77,
      "z": 2,
      "name": "Wood_Jungle_Trunk",
      "support": 15
    },
    {
      "x": -7,
      "y": 78,
      "z": 2,
      "name": "Plant_Leaves_Jungle",
      "support": 15
    },
    {
      "x": -7,
      "y": 77,
      "z": 3,
      "name": "Plant_Leaves_Jungle",
      "support": 15
    },
    {
      "x": -7,
      "y": 78,
      "z": 3,
      "name": "Plant_Leaves_Jungle",
      "support": 15
    },
    {
      "x": -7,
      "y": 77,
      "z": 4,
      "name": "Plant_Leaves_Jungle",
      "support": 15
    },
    {
      "x": -7,
      "y": 78,
      "z": 4,
      "name": "Plant_Leaves_Jungle",
      "support": 15
    },
    {
      "x": -7,
      "y": 77,
      "z": 5,
      "name": "Plant_Leaves_Jungle",
      "support": 15
    },
    {
      "x": -7,
      "y": 77,
      "z": 6,
      "name": "Plant_Leaves_Jungle",
      "support": 15
    },
    {
      "x": -6,
      "y": 70,
      "z": -10,
      "name": "Plant_Leaves_Jungle",
      "support": 15
    },
    {
      "x": -6,
      "y": 71,
      "z": -9,
      "name": "Plant_Leaves_Jungle",
      "support": 15
    },
    {
      "x": -6,
      "y": 71,
      "z": -8,
      "name": "Plant_Leaves_Jungle",
      "support": 15
    },
    {
      "x": -6,
      "y": 70,
      "z": -7,
      "name": "Wood_Jungle_Branch_Long",
      "support": 15,
      "rotation": 5
    },
    {
      "x": -6,
      "y": 71,
      "z": -7,
      "name": "Plant_Leaves_Jungle",
      "support": 15
    },
    {
      "x": -6,
      "y": 71,
      "z": -6,
      "name": "Plant_Leaves_Jungle",
      "support": 15
    },
    {
      "x": -6,
      "y": 72,
      "z": -6,
      "name": "Plant_Leaves_Jungle",
      "support": 15
    },
    {
      "x": -6,
      "y": 71,
      "z": -5,
      "name": "Plant_Leaves_Jungle",
      "support": 15
    },
    {
      "x": -6,
      "y": 72,
      "z": -5,
      "name": "Plant_Leaves_Jungle",
      "support": 15
    },
    {
      "x": -6,
      "y": 71,
      "z": -4,
      "name": "Plant_Leaves_Jungle",
      "support": 15
    },
    {
      "x": -6,
      "y": 72,
      "z": -4,
      "name": "Plant_Leaves_Jungle",
      "support": 15
    },
    {
      "x": -6,
      "y": 76,
      "z": -4,
      "name": "Plant_Leaves_Jungle",
      "support": 15
    },
    {
      "x": -6,
      "y": 27,
      "z": -3,
      "name": "Soil_Dirt_Burnt"
    },
    {
      "x": -6,
      "y": 28,
      "z": -3,
      "name": "Soil_Dirt_Burnt"
    },
    {
      "x": -6,
      "y": 29,
      "z": -3,
      "name": "Soil_Dirt_Burnt"
    },
    {
      "x": -6,
      "y": 30,
      "z": -3,
      "name": "Soil_Dirt_Burnt"
    },
    {
      "x": -6,
      "y": 70,
      "z": -3,
      "name": "Wood_Jungle_Branch_Long",
      "support": 15,
      "rotation": 5
    },
    {
      "x": -6,
      "y": 71,
      "z": -3,
      "name": "Plant_Leaves_Jungle",
      "support": 15
    },
    {
      "x": -6,
      "y": 76,
      "z": -3,
      "name": "Plant_Leaves_Jungle",
      "support": 15
    },
    {
      "x": -6,
      "y": 77,
      "z": -3,
      "name": "Plant_Leaves_Jungle",
      "support": 15
    },
    {
      "x": -6,
      "y": 24,
      "z": -2,
      "name": "Empty"
    },
    {
      "x": -6,
      "y": 27,
      "z": -2,
      "name": "Soil_Dirt_Burnt"
    },
    {
      "x": -6,
      "y": 28,
      "z": -2,
      "name": "Soil_Dirt_Burnt"
    },
    {
      "x": -6,
      "y": 29,
      "z": -2,
      "name": "Soil_Dirt_Burnt"
    },
    {
      "x": -6,
      "y": 30,
      "z": -2,
      "name": "Soil_Dirt_Burnt"
    },
    {
      "x": -6,
      "y": 31,
      "z": -2,
      "name": "Soil_Dirt_Burnt"
    },
    {
      "x": -6,
      "y": 70,
      "z": -2,
      "name": "Plant_Leaves_Jungle",
      "support": 15
    },
    {
      "x": -6,
      "y": 71,
      "z": -2,
      "name": "Plant_Leaves_Jungle",
      "support": 15
    },
    {
      "x": -6,
      "y": 76,
      "z": -2,
      "name": "Plant_Leaves_Jungle",
      "support": 15
    },
    {
      "x": -6,
      "y": 23,
      "z": -1,
      "name": "Empty"
    },
    {
      "x": -6,
      "y": 24,
      "z": -1,
      "name": "Empty"
    },
    {
      "x": -6,
      "y": 25,
      "z": -1,
      "name": "Empty"
    },
    {
      "x": -6,
      "y": 27,
      "z": -1,
      "name": "Soil_Dirt_Burnt"
    },
    {
      "x": -6,
      "y": 28,
      "z": -1,
      "name": "Soil_Dirt_Burnt"
    },
    {
      "x": -6,
      "y": 29,
      "z": -1,
      "name": "Soil_Dirt_Burnt"
    },
    {
      "x": -6,
      "y": 30,
      "z": -1,
      "name": "Soil_Dirt_Burnt"
    },
    {
      "x": -6,
      "y": 31,
      "z": -1,
      "name": "Soil_Dirt_Burnt"
    },
    {
      "x": -6,
      "y": 32,
      "z": -1,
      "name": "Soil_Dirt_Burnt"
    },
    {
      "x": -6,
      "y": 70,
      "z": -1,
      "name": "Plant_Leaves_Jungle",
      "support": 15
    },
    {
      "x": -6,
      "y": 76,
      "z": -1,
      "name": "Plant_Leaves_Jungle",
      "support": 15
    },
    {
      "x": -6,
      "y": 77,
      "z": -1,
      "name": "Plant_Leaves_Jungle",
      "support": 15
    },
    {
      "x": -6,
      "y": 23,
      "z": 0,
      "name": "Empty"
    },
    {
      "x": -6,
      "y": 24,
      "z": 0,
      "name": "Empty"
    },
    {
      "x": -6,
      "y": 25,
      "z": 0,
      "name": "Empty"
    },
    {
      "x": -6,
      "y": 27,
      "z": 0,
      "name": "Soil_Dirt_Burnt"
    },
    {
      "x": -6,
      "y": 28,
      "z": 0,
      "name": "Soil_Dirt_Burnt"
    },
    {
      "x": -6,
      "y": 29,
      "z": 0,
      "name": "Soil_Dirt_Burnt"
    },
    {
      "x": -6,
      "y": 30,
      "z": 0,
      "name": "Soil_Dirt_Burnt"
    },
    {
      "x": -6,
      "y": 31,
      "z": 0,
      "name": "Soil_Dirt_Burnt"
    },
    {
      "x": -6,
      "y": 32,
      "z": 0,
      "name": "Soil_Dirt_Burnt"
    },
    {
      "x": -6,
      "y": 33,
      "z": 0,
      "name": "Soil_Dirt_Burnt"
    },
    {
      "x": -6,
      "y": 76,
      "z": 0,
      "name": "Plant_Leaves_Jungle",
      "support": 15
    },
    {
      "x": -6,
      "y": 77,
      "z": 0,
      "name": "Plant_Leaves_Jungle",
      "support": 15
    },
    {
      "x": -6,
      "y": 27,
      "z": 1,
      "name": "Soil_Dirt_Burnt"
    },
    {
      "x": -6,
      "y": 28,
      "z": 1,
      "name": "Soil_Dirt_Burnt"
    },
    {
      "x": -6,
      "y": 29,
      "z": 1,
      "name": "Soil_Dirt_Burnt"
    },
    {
      "x": -6,
      "y": 30,
      "z": 1,
      "name": "Soil_Dirt_Burnt"
    },
    {
      "x": -6,
      "y": 31,
      "z": 1,
      "name": "Soil_Dirt_Burnt"
    },
    {
      "x": -6,
      "y": 32,
      "z": 1,
      "name": "Soil_Dirt_Burnt"
    },
    {
      "x": -6,
      "y": 75,
      "z": 1,
      "name": "Wood_Jungle_Trunk",
      "support": 15
    },
    {
      "x": -6,
      "y": 76,
      "z": 1,
      "name": "Wood_Jungle_Trunk",
      "support": 15
    },
    {
      "x": -6,
      "y": 77,
      "z": 1,
      "name": "Plant_Leaves_Jungle",
      "support": 15
    },
    {
      "x": -6,
      "y": 78,
      "z": 1,
      "name": "Plant_Leaves_Jungle",
      "support": 15
    },
    {
      "x": -6,
      "y": 28,
      "z": 2,
      "name": "Soil_Dirt_Burnt"
    },
    {
      "x": -6,
      "y": 29,
      "z": 2,
      "name": "Soil_Dirt_Burnt"
    },
    {
      "x": -6,
      "y": 30,
      "z": 2,
      "name": "Soil_Dirt_Burnt"
    },
    {
      "x": -6,
      "y": 31,
      "z": 2,
      "name": "Soil_Dirt_Burnt"
    },
    {
      "x": -6,
      "y": 32,
      "z": 2,
      "name": "Soil_Dirt_Burnt"
    },
    {
      "x": -6,
      "y": 76,
      "z": 2,
      "name": "Wood_Jungle_Trunk",
      "support": 15
    },
    {
      "x": -6,
      "y": 77,
      "z": 2,
      "name": "Plant_Leaves_Jungle",
      "support": 15
    },
    {
      "x": -6,
      "y": 78,
      "z": 2,
      "name": "Plant_Leaves_Jungle",
      "support": 15
    },
    {
      "x": -6,
      "y": 28,
      "z": 3,
      "name": "Soil_Dirt_Burnt"
    },
    {
      "x": -6,
      "y": 29,
      "z": 3,
      "name": "Soil_Dirt_Burnt"
    },
    {
      "x": -6,
      "y": 30,
      "z": 3,
      "name": "Soil_Dirt_Burnt"
    },
    {
      "x": -6,
      "y": 31,
      "z": 3,
      "name": "Soil_Dirt_Burnt"
    },
    {
      "x": -6,
      "y": 76,
      "z": 3,
      "name": "Plant_Leaves_Jungle",
      "support": 15
    },
    {
      "x": -6,
      "y": 77,
      "z": 3,
      "name": "Plant_Leaves_Jungle",
      "support": 15
    },
    {
      "x": -6,
      "y": 78,
      "z": 3,
      "name": "Plant_Leaves_Jungle",
      "support": 15
    },
    {
      "x": -6,
      "y": 29,
      "z": 4,
      "name": "Soil_Dirt_Burnt"
    },
    {
      "x": -6,
      "y": 30,
      "z": 4,
      "name": "Soil_Dirt_Burnt"
    },
    {
      "x": -6,
      "y": 76,
      "z": 4,
      "name": "Plant_Leaves_Jungle",
      "support": 15
    },
    {
      "x": -6,
      "y": 77,
      "z": 4,
      "name": "Plant_Leaves_Jungle",
      "support": 15
    },
    {
      "x": -6,
      "y": 78,
      "z": 4,
      "name": "Plant_Leaves_Jungle",
      "support": 15
    },
    {
      "x": -6,
      "y": 76,
      "z": 5,
      "name": "Plant_Leaves_Jungle",
      "support": 15
    },
    {
      "x": -5,
      "y": 70,
      "z": -10,
      "name": "Plant_Leaves_Jungle",
      "support": 15
    },
    {
      "x": -5,
      "y": 70,
      "z": -9,
      "name": "Plant_Leaves_Jungle",
      "support": 15
    },
    {
      "x": -5,
      "y": 71,
      "z": -9,
      "name": "Plant_Leaves_Jungle",
      "support": 15
    },
    {
      "x": -5,
      "y": 71,
      "z": -8,
      "name": "Plant_Leaves_Jungle",
      "support": 15
    },
    {
      "x": -5,
      "y": 72,
      "z": -8,
      "name": "Plant_Leaves_Jungle",
      "support": 15
    },
    {
      "x": -5,
      "y": 70,
      "z": -7,
      "name": "Wood_Jungle_Branch_Long",
      "support": 15,
      "rotation": 5
    },
    {
      "x": -5,
      "y": 71,
      "z": -7,
      "name": "Plant_Leaves_Jungle",
      "support": 15
    },
    {
      "x": -5,
      "y": 72,
      "z": -7,
      "name": "Plant_Leaves_Jungle",
      "support": 15
    },
    {
      "x": -5,
      "y": 71,
      "z": -6,
      "name": "Plant_Leaves_Jungle",
      "support": 15
    },
    {
      "x": -5,
      "y": 72,
      "z": -6,
      "name": "Plant_Leaves_Jungle",
      "support": 15
    },
    {
      "x": -5,
      "y": 71,
      "z": -5,
      "name": "Plant_Leaves_Jungle",
      "support": 15
    },
    {
      "x": -5,
      "y": 72,
      "z": -5,
      "name": "Plant_Leaves_Jungle",
      "support": 15
    },
    {
      "x": -5,
      "y": 24,
      "z": -4,
      "name": "Soil_Dirt_Burnt"
    },
    {
      "x": -5,
      "y": 25,
      "z": -4,
      "name": "Soil_Dirt_Burnt"
    },
    {
      "x": -5,
      "y": 26,
      "z": -4,
      "name": "Soil_Dirt_Burnt"
    },
    {
      "x": -5,
      "y": 71,
      "z": -4,
      "name": "Plant_Leaves_Jungle",
      "support": 15
    },
    {
      "x": -5,
      "y": 72,
      "z": -4,
      "name": "Plant_Leaves_Jungle",
      "support": 15
    },
    {
      "x": -5,
      "y": 75,
      "z": -4,
      "name": "Plant_Leaves_Jungle",
      "support": 15
    },
    {
      "x": -5,
      "y": 23,
      "z": -3,
      "name": "Soil_Dirt_Burnt"
    },
    {
      "x": -5,
      "y": 24,
      "z": -3,
      "name": "Soil_Dirt_Burnt"
    },
    {
      "x": -5,
      "y": 25,
      "z": -3,
      "name": "Soil_Dirt_Burnt"
    },
    {
      "x": -5,
      "y": 26,
      "z": -3,
      "name": "Soil_Dirt_Burnt"
    },
    {
      "x": -5,
      "y": 27,
      "z": -3,
      "name": "Soil_Dirt_Burnt"
    },
    {
      "x": -5,
      "y": 28,
      "z": -3,
      "name": "Wood_Jungle_Trunk",
      "support": 15
    },
    {
      "x": -5,
      "y": 29,
      "z": -3,
      "name": "Wood_Jungle_Trunk",
      "support": 15
    },
    {
      "x": -5,
      "y": 30,
      "z": -3,
      "name": "Wood_Jungle_Trunk_Full",
      "support": 15
    },
    {
      "x": -5,
      "y": 70,
      "z": -3,
      "name": "Wood_Jungle_Branch_Long",
      "support": 15,
      "rotation": 5
    },
    {
      "x": -5,
      "y": 71,
      "z": -3,
      "name": "Plant_Leaves_Jungle",
      "support": 15
    },
    {
      "x": -5,
      "y": 72,
      "z": -3,
      "name": "Plant_Leaves_Jungle",
      "support": 15
    },
    {
      "x": -5,
      "y": 75,
      "z": -3,
      "name": "Wood_Jungle_Branch_Long",
      "support": 15,
      "rotation": 4
    },
    {
      "x": -5,
      "y": 76,
      "z": -3,
      "name": "Plant_Leaves_Jungle",
      "support": 15
    },
    {
      "x": -5,
      "y": 22,
      "z": -2,
      "name": "Soil_Dirt_Burnt"
    },
    {
      "x": -5,
      "y": 23,
      "z": -2,
      "name": "Soil_Dirt_Burnt"
    },
    {
      "x": -5,
      "y": 24,
      "z": -2,
      "name": "Soil_Dirt_Burnt"
    },
    {
      "x": -5,
      "y": 25,
      "z": -2,
      "name": "Soil_Dirt_Burnt"
    },
    {
      "x": -5,
      "y": 26,
      "z": -2,
      "name": "Soil_Dirt_Burnt"
    },
    {
      "x": -5,
      "y": 27,
      "z": -2,
      "name": "Soil_Dirt_Burnt"
    },
    {
      "x": -5,
      "y": 28,
      "z": -2,
      "name": "Wood_Jungle_Trunk",
      "support": 15
    },
    {
      "x": -5,
      "y": 29,
      "z": -2,
      "name": "Wood_Jungle_Trunk",
      "support": 15
    },
    {
      "x": -5,
      "y": 30,
      "z": -2,
      "name": "Wood_Jungle_Trunk",
      "support": 15
    },
    {
      "x": -5,
      "y": 31,
      "z": -2,
      "name": "Wood_Jungle_Trunk",
      "support": 15
    },
    {
      "x": -5,
      "y": 32,
      "z": -2,
      "name": "Wood_Jungle_Trunk_Full",
      "support": 15
    },
    {
      "x": -5,
      "y": 70,
      "z": -2,
      "name": "Plant_Leaves_Jungle",
      "support": 15
    },
    {
      "x": -5,
      "y": 71,
      "z": -2,
      "name": "Plant_Leaves_Jungle",
      "support": 15
    },
    {
      "x": -5,
      "y": 75,
      "z": -2,
      "name": "Wood_Jungle_Branch_Long",
      "support": 15,
      "rotation": 4
    },
    {
      "x": -5,
      "y": 76,
      "z": -2,
      "name": "Plant_Leaves_Jungle",
      "support": 15
    },
    {
      "x": -5,
      "y": 23,
      "z": -1,
      "name": "Empty"
    },
    {
      "x": -5,
      "y": 24,
      "z": -1,
      "name": "Empty"
    },
    {
      "x": -5,
      "y": 25,
      "z": -1,
      "name": "Empty"
    },
    {
      "x": -5,
      "y": 26,
      "z": -1,
      "name": "Soil_Dirt_Burnt"
    },
    {
      "x": -5,
      "y": 27,
      "z": -1,
      "name": "Soil_Dirt_Burnt"
    },
    {
      "x": -5,
      "y": 28,
      "z": -1,
      "name": "Soil_Dirt_Burnt"
    },
    {
      "x": -5,
      "y": 29,
      "z": -1,
      "name": "Soil_Dirt_Burnt"
    },
    {
      "x": -5,
      "y": 30,
      "z": -1,
      "name": "Wood_Jungle_Trunk",
      "support": 15
    },
    {
      "x": -5,
      "y": 31,
      "z": -1,
      "name": "Wood_Jungle_Trunk",
      "support": 15
    },
    {
      "x": -5,
      "y": 32,
      "z": -1,
      "name": "Wood_Jungle_Trunk",
      "support": 15
    },
    {
      "x": -5,
      "y": 33,
      "z": -1,
      "name": "Wood_Jungle_Trunk_Full",
      "support": 15
    },
    {
      "x": -5,
      "y": 70,
      "z": -1,
      "name": "Plant_Leaves_Jungle",
      "support": 15
    },
    {
      "x": -5,
      "y": 75,
      "z": -1,
      "name": "Wood_Jungle_Branch_Long",
      "support": 15,
      "rotation": 4
    },
    {
      "x": -5,
      "y": 76,
      "z": -1,
      "name": "Plant_Leaves_Jungle",
      "support": 15
    },
    {
      "x": -5,
      "y": 23,
      "z": 0,
      "name": "Empty"
    },
    {
      "x": -5,
      "y": 24,
      "z": 0,
      "name": "Empty"
    },
    {
      "x": -5,
      "y": 25,
      "z": 0,
      "name": "Empty"
    },
    {
      "x": -5,
      "y": 26,
      "z": 0,
      "name": "Soil_Dirt_Burnt"
    },
    {
      "x": -5,
      "y": 27,
      "z": 0,
      "name": "Soil_Dirt_Burnt"
    },
    {
      "x": -5,
      "y": 28,
      "z": 0,
      "name": "Soil_Dirt_Burnt"
    },
    {
      "x": -5,
      "y": 29,
      "z": 0,
      "name": "Soil_Dirt_Burnt"
    },
    {
      "x": -5,
      "y": 30,
      "z": 0,
      "name": "Soil_Dirt_Burnt"
    },
    {
      "x": -5,
      "y": 31,
      "z": 0,
      "name": "Wood_Jungle_Trunk",
      "support": 15
    },
    {
      "x": -5,
      "y": 32,
      "z": 0,
      "name": "Wood_Jungle_Trunk",
      "support": 15
    },
    {
      "x": -5,
      "y": 33,
      "z": 0,
      "name": "Wood_Jungle_Trunk",
      "support": 15
    },
    {
      "x": -5,
      "y": 34,
      "z": 0,
      "name": "Wood_Jungle_Trunk_Full",
      "support": 15
    },
    {
      "x": -5,
      "y": 75,
      "z": 0,
      "name": "Wood_Jungle_Trunk",
      "support": 15
    },
    {
      "x": -5,
      "y": 76,
      "z": 0,
      "name": "Plant_Leaves_Jungle",
      "support": 15
    },
    {
      "x": -5,
      "y": 77,
      "z": 0,
      "name": "Plant_Leaves_Jungle",
      "support": 15
    },
    {
      "x": -5,
      "y": 22,
      "z": 1,
      "name": "Empty"
    },
    {
      "x": -5,
      "y": 23,
      "z": 1,
      "name": "Empty"
    },
    {
      "x": -5,
      "y": 24,
      "z": 1,
      "name": "Empty"
    },
    {
      "x": -5,
      "y": 25,
      "z": 1,
      "name": "Empty"
    },
    {
      "x": -5,
      "y": 27,
      "z": 1,
      "name": "Soil_Dirt_Burnt"
    },
    {
      "x": -5,
      "y": 28,
      "z": 1,
      "name": "Soil_Dirt_Burnt"
    },
    {
      "x": -5,
      "y": 29,
      "z": 1,
      "name": "Soil_Dirt_Burnt"
    },
    {
      "x": -5,
      "y": 30,
      "z": 1,
      "name": "Soil_Dirt_Burnt"
    },
    {
      "x": -5,
      "y": 31,
      "z": 1,
      "name": "Soil_Dirt_Burnt"
    },
    {
      "x": -5,
      "y": 32,
      "z": 1,
      "name": "Soil_Dirt_Burnt"
    },
    {
      "x": -5,
      "y": 33,
      "z": 1,
      "name": "Wood_Jungle_Trunk_Full",
      "support": 15
    },
    {
      "x": -5,
      "y": 70,
      "z": 1,
      "name": "Plant_Leaves_Palm_Oasis",
      "support": 15
    },
    {
      "x": -5,
      "y": 71,
      "z": 1,
      "name": "Wood_Jungle_Branch_Long",
      "support": 15
    },
    {
      "x": -5,
      "y": 72,
      "z": 1,
      "name": "Wood_Jungle_Branch_Long",
      "support": 15
    },
    {
      "x": -5,
      "y": 73,
      "z": 1,
      "name": "Wood_Jungle_Branch_Long",
      "support": 15
    },
    {
      "x": -5,
      "y": 74,
      "z": 1,
      "name": "Wood_Jungle_Branch_Long",
      "support": 15
    },
    {
      "x": -5,
      "y": 75,
      "z": 1,
      "name": "Wood_Jungle_Trunk",
      "support": 15
    },
    {
      "x": -5,
      "y": 76,
      "z": 1,
      "name": "Plant_Leaves_Jungle",
      "support": 15
    },
    {
      "x": -5,
      "y": 77,
      "z": 1,
      "name": "Plant_Leaves_Jungle",
      "support": 15
    },
    {
      "x": -5,
      "y": 27,
      "z": 2,
      "name": "Soil_Dirt_Burnt"
    },
    {
      "x": -5,
      "y": 28,
      "z": 2,
      "name": "Soil_Dirt_Burnt"
    },
    {
      "x": -5,
      "y": 29,
      "z": 2,
      "name": "Soil_Dirt_Burnt"
    },
    {
      "x": -5,
      "y": 30,
      "z": 2,
      "name": "Soil_Dirt_Burnt"
    },
    {
      "x": -5,
      "y": 31,
      "z": 2,
      "name": "Soil_Dirt_Burnt"
    },
    {
      "x": -5,
      "y": 32,
      "z": 2,
      "name": "Soil_Dirt_Burnt"
    },
    {
      "x": -5,
      "y": 33,
      "z": 2,
      "name": "Soil_Dirt_Burnt"
    },
    {
      "x": -5,
      "y": 75,
      "z": 2,
      "name": "Plant_Leaves_Jungle",
      "support": 15
    },
    {
      "x": -5,
      "y": 76,
      "z": 2,
      "name": "Plant_Leaves_Jungle",
      "support": 15
    },
    {
      "x": -5,
      "y": 77,
      "z": 2,
      "name": "Plant_Leaves_Jungle",
      "support": 15
    },
    {
      "x": -5,
      "y": 27,
      "z": 3,
      "name": "Soil_Dirt_Burnt"
    },
    {
      "x": -5,
      "y": 28,
      "z": 3,
      "name": "Soil_Dirt_Burnt"
    },
    {
      "x": -5,
      "y": 29,
      "z": 3,
      "name": "Soil_Dirt_Burnt"
    },
    {
      "x": -5,
      "y": 30,
      "z": 3,
      "name": "Soil_Dirt_Burnt"
    },
    {
      "x": -5,
      "y": 31,
      "z": 3,
      "name": "Soil_Dirt_Burnt"
    },
    {
      "x": -5,
      "y": 32,
      "z": 3,
      "name": "Soil_Dirt_Burnt"
    },
    {
      "x": -5,
      "y": 76,
      "z": 3,
      "name": "Plant_Leaves_Jungle",
      "support": 15
    },
    {
      "x": -5,
      "y": 77,
      "z": 3,
      "name": "Plant_Leaves_Jungle",
      "support": 15
    },
    {
      "x": -5,
      "y": 28,
      "z": 4,
      "name": "Soil_Dirt_Burnt"
    },
    {
      "x": -5,
      "y": 29,
      "z": 4,
      "name": "Soil_Dirt_Burnt"
    },
    {
      "x": -5,
      "y": 30,
      "z": 4,
      "name": "Soil_Dirt_Burnt"
    },
    {
      "x": -5,
      "y": 31,
      "z": 4,
      "name": "Soil_Dirt_Burnt"
    },
    {
      "x": -5,
      "y": 76,
      "z": 4,
      "name": "Plant_Leaves_Jungle",
      "support": 15
    },
    {
      "x": -5,
      "y": 77,
      "z": 4,
      "name": "Plant_Leaves_Jungle",
      "support": 15
    },
    {
      "x": -5,
      "y": 29,
      "z": 5,
      "name": "Soil_Dirt_Burnt"
    },
    {
      "x": -5,
      "y": 30,
      "z": 5,
      "name": "Soil_Dirt_Burnt"
    },
    {
      "x": -5,
      "y": 77,
      "z": 5,
      "name": "Plant_Leaves_Jungle",
      "support": 15
    },
    {
      "x": -4,
      "y": 70,
      "z": -10,
      "name": "Plant_Leaves_Jungle",
      "support": 15
    },
    {
      "x": -4,
      "y": 70,
      "z": -9,
      "name": "Wood_Jungle_Trunk",
      "support": 15
    },
    {
      "x": -4,
      "y": 71,
      "z": -9,
      "name": "Plant_Leaves_Jungle",
      "support": 15
    },
    {
      "x": -4,
      "y": 70,
      "z": -8,
      "name": "Wood_Jungle_Trunk",
      "support": 15
    },
    {
      "x": -4,
      "y": 71,
      "z": -8,
      "name": "Plant_Leaves_Jungle",
      "support": 15
    },
    {
      "x": -4,
      "y": 72,
      "z": -8,
      "name": "Plant_Leaves_Jungle",
      "support": 15
    },
    {
      "x": -4,
      "y": 70,
      "z": -7,
      "name": "Wood_Jungle_Trunk",
      "support": 15
    },
    {
      "x": -4,
      "y": 71,
      "z": -7,
      "name": "Plant_Leaves_Jungle",
      "support": 15
    },
    {
      "x": -4,
      "y": 72,
      "z": -7,
      "name": "Plant_Leaves_Jungle",
      "support": 15
    },
    {
      "x": -4,
      "y": 70,
      "z": -6,
      "name": "Wood_Jungle_Trunk",
      "support": 15
    },
    {
      "x": -4,
      "y": 71,
      "z": -6,
      "name": "Plant_Leaves_Jungle",
      "support": 15
    },
    {
      "x": -4,
      "y": 72,
      "z": -6,
      "name": "Plant_Leaves_Jungle",
      "support": 15
    },
    {
      "x": -4,
      "y": 23,
      "z": -5,
      "name": "Soil_Dirt_Burnt"
    },
    {
      "x": -4,
      "y": 24,
      "z": -5,
      "name": "Soil_Dirt_Burnt"
    },
    {
      "x": -4,
      "y": 25,
      "z": -5,
      "name": "Soil_Dirt_Burnt"
    },
    {
      "x": -4,
      "y": 70,
      "z": -5,
      "name": "Wood_Jungle_Trunk",
      "support": 15
    },
    {
      "x": -4,
      "y": 71,
      "z": -5,
      "name": "Plant_Leaves_Jungle",
      "support": 15
    },
    {
      "x": -4,
      "y": 72,
      "z": -5,
      "name": "Plant_Leaves_Jungle",
      "support": 15
    },
    {
      "x": -4,
      "y": 22,
      "z": -4,
      "name": "Soil_Dirt_Burnt"
    },
    {
      "x": -4,
      "y": 23,
      "z": -4,
      "name": "Soil_Dirt_Burnt"
    },
    {
      "x": -4,
      "y": 24,
      "z": -4,
      "name": "Soil_Dirt_Burnt"
    },
    {
      "x": -4,
      "y": 25,
      "z": -4,
      "name": "Soil_Dirt_Burnt"
    },
    {
      "x": -4,
      "y": 26,
      "z": -4,
      "name": "Wood_Jungle_Trunk",
      "support": 15
    },
    {
      "x": -4,
      "y": 27,
      "z": -4,
      "name": "Wood_Jungle_Trunk",
      "support": 15
    },
    {
      "x": -4,
      "y": 28,
      "z": -4,
      "name": "Wood_Jungle_Trunk_Full",
      "support": 15
    },
    {
      "x": -4,
      "y": 71,
      "z": -4,
      "name": "Plant_Leaves_Jungle",
      "support": 15
    },
    {
      "x": -4,
      "y": 72,
      "z": -4,
      "name": "Plant_Leaves_Jungle",
      "support": 15
    },
    {
      "x": -4,
      "y": 22,
      "z": -3,
      "name": "Soil_Dirt_Burnt"
    },
    {
      "x": -4,
      "y": 23,
      "z": -3,
      "name": "Soil_Dirt_Burnt"
    },
    {
      "x": -4,
      "y": 24,
      "z": -3,
      "name": "Soil_Dirt_Burnt"
    },
    {
      "x": -4,
      "y": 25,
      "z": -3,
      "name": "Soil_Dirt_Burnt"
    },
    {
      "x": -4,
      "y": 26,
      "z": -3,
      "name": "Wood_Jungle_Trunk",
      "support": 15
    },
    {
      "x": -4,
      "y": 27,
      "z": -3,
      "name": "Wood_Jungle_Trunk",
      "support": 15
    },
    {
      "x": -4,
      "y": 28,
      "z": -3,
      "name": "Wood_Jungle_Trunk",
      "support": 15
    },
    {
      "x": -4,
      "y": 29,
      "z": -3,
      "name": "Wood_Jungle_Trunk",
      "support": 15
    },
    {
      "x": -4,
      "y": 30,
      "z": -3,
      "name": "Wood_Jungle_Trunk_Full",
      "support": 15
    },
    {
      "x": -4,
      "y": 70,
      "z": -3,
      "name": "Wood_Jungle_Branch_Long",
      "support": 15,
      "rotation": 5
    },
    {
      "x": -4,
      "y": 71,
      "z": -3,
      "name": "Plant_Leaves_Jungle",
      "support": 15
    },
    {
      "x": -4,
      "y": 72,
      "z": -3,
      "name": "Plant_Leaves_Jungle",
      "support": 15
    },
    {
      "x": -4,
      "y": 76,
      "z": -3,
      "name": "Plant_Leaves_Jungle",
      "support": 15
    },
    {
      "x": -4,
      "y": 21,
      "z": -2,
      "name": "Soil_Dirt_Burnt"
    },
    {
      "x": -4,
      "y": 22,
      "z": -2,
      "name": "Soil_Dirt_Burnt"
    },
    {
      "x": -4,
      "y": 23,
      "z": -2,
      "name": "Soil_Dirt_Burnt"
    },
    {
      "x": -4,
      "y": 24,
      "z": -2,
      "name": "Soil_Dirt_Burnt"
    },
    {
      "x": -4,
      "y": 25,
      "z": -2,
      "name": "Soil_Dirt_Burnt"
    },
    {
      "x": -4,
      "y": 26,
      "z": -2,
      "name": "Soil_Dirt_Burnt"
    },
    {
      "x": -4,
      "y": 27,
      "z": -2,
      "name": "Soil_Dirt_Burnt"
    },
    {
      "x": -4,
      "y": 28,
      "z": -2,
      "name": "Wood_Jungle_Trunk",
      "support": 15
    },
    {
      "x": -4,
      "y": 29,
      "z": -2,
      "name": "Wood_Jungle_Trunk",
      "support": 15
    },
    {
      "x": -4,
      "y": 30,
      "z": -2,
      "name": "Wood_Jungle_Trunk",
      "support": 15
    },
    {
      "x": -4,
      "y": 31,
      "z": -2,
      "name": "Wood_Jungle_Trunk",
      "support": 15
    },
    {
      "x": -4,
      "y": 32,
      "z": -2,
      "name": "Wood_Jungle_Trunk_Full",
      "support": 15
    },
    {
      "x": -4,
      "y": 70,
      "z": -2,
      "name": "Plant_Leaves_Jungle",
      "support": 15
    },
    {
      "x": -4,
      "y": 71,
      "z": -2,
      "name": "Plant_Leaves_Jungle",
      "support": 15
    },
    {
      "x": -4,
      "y": 76,
      "z": -2,
      "name": "Plant_Leaves_Jungle",
      "support": 15
    },
    {
      "x": -4,
      "y": 22,
      "z": -1,
      "name": "Empty"
    },
    {
      "x": -4,
      "y": 23,
      "z": -1,
      "name": "Empty"
    },
    {
      "x": -4,
      "y": 24,
      "z": -1,
      "name": "Empty"
    },
    {
      "x": -4,
      "y": 25,
      "z": -1,
      "name": "Empty"
    },
    {
      "x": -4,
      "y": 26,
      "z": -1,
      "name": "Empty"
    },
    {
      "x": -4,
      "y": 27,
      "z": -1,
      "name": "Empty"
    },
    {
      "x": -4,
      "y": 28,
      "z": -1,
      "name": "Empty"
    },
    {
      "x": -4,
      "y": 29,
      "z": -1,
      "name": "Soil_Dirt_Burnt"
    },
    {
      "x": -4,
      "y": 30,
      "z": -1,
      "name": "Wood_Jungle_Trunk",
      "support": 15
    },
    {
      "x": -4,
      "y": 31,
      "z": -1,
      "name": "Wood_Jungle_Trunk",
      "support": 15
    },
    {
      "x": -4,
      "y": 32,
      "z": -1,
      "name": "Wood_Jungle_Trunk",
      "support": 15
    },
    {
      "x": -4,
      "y": 33,
      "z": -1,
      "name": "Wood_Jungle_Trunk_Full",
      "support": 15
    },
    {
      "x": -4,
      "y": 40,
      "z": -1,
      "name": "Soil_Dirt_Burnt"
    },
    {
      "x": -4,
      "y": 46,
      "z": -1,
      "name": "Soil_Dirt_Burnt"
    },
    {
      "x": -4,
      "y": 47,
      "z": -1,
      "name": "Soil_Dirt_Burnt"
    },
    {
      "x": -4,
      "y": 48,
      "z": -1,
      "name": "Soil_Dirt_Burnt"
    },
    {
      "x": -4,
      "y": 70,
      "z": -1,
      "name": "Plant_Leaves_Jungle",
      "support": 15
    },
    {
      "x": -4,
      "y": 75,
      "z": -1,
      "name": "Plant_Leaves_Jungle",
      "support": 15
    },
    {
      "x": -4,
      "y": 76,
      "z": -1,
      "name": "Plant_Leaves_Jungle",
      "support": 15
    },
    {
      "x": -4,
      "y": 22,
      "z": 0,
      "name": "Empty"
    },
    {
      "x": -4,
      "y": 23,
      "z": 0,
      "name": "Empty"
    },
    {
      "x": -4,
      "y": 24,
      "z": 0,
      "name": "Empty"
    },
    {
      "x": -4,
      "y": 25,
      "z": 0,
      "name": "Empty"
    },
    {
      "x": -4,
      "y": 26,
      "z": 0,
      "name": "Empty"
    },
    {
      "x": -4,
      "y": 27,
      "z": 0,
      "name": "Empty"
    },
    {
      "x": -4,
      "y": 28,
      "z": 0,
      "name": "Empty"
    },
    {
      "x": -4,
      "y": 29,
      "z": 0,
      "name": "Empty"
    },
    {
      "x": -4,
      "y": 30,
      "z": 0,
      "name": "Soil_Dirt_Burnt"
    },
    {
      "x": -4,
      "y": 31,
      "z": 0,
      "name": "Wood_Jungle_Trunk",
      "support": 15
    },
    {
      "x": -4,
      "y": 32,
      "z": 0,
      "name": "Wood_Jungle_Trunk",
      "support": 15
    },
    {
      "x": -4,
      "y": 33,
      "z": 0,
      "name": "Wood_Jungle_Trunk",
      "support": 15
    },
    {
      "x": -4,
      "y": 34,
      "z": 0,
      "name": "Wood_Jungle_Trunk",
      "support": 15
    },
    {
      "x": -4,
      "y": 35,
      "z": 0,
      "name": "Wood_Jungle_Trunk_Full",
      "support": 15
    },
    {
      "x": -4,
      "y": 39,
      "z": 0,
      "name": "Soil_Dirt_Burnt"
    },
    {
      "x": -4,
      "y": 40,
      "z": 0,
      "name": "Soil_Dirt_Burnt"
    },
    {
      "x": -4,
      "y": 47,
      "z": 0,
      "name": "Soil_Dirt_Burnt"
    },
    {
      "x": -4,
      "y": 48,
      "z": 0,
      "name": "Soil_Dirt_Burnt"
    },
    {
      "x": -4,
      "y": 49,
      "z": 0,
      "name": "Soil_Dirt_Burnt"
    },
    {
      "x": -4,
      "y": 50,
      "z": 0,
      "name": "Soil_Grass_Full"
    },
    {
      "x": -4,
      "y": 74,
      "z": 0,
      "name": "Wood_Jungle_Trunk",
      "support": 15
    },
    {
      "x": -4,
      "y": 75,
      "z": 0,
      "name": "Wood_Jungle_Trunk",
      "support": 15
    },
    {
      "x": -4,
      "y": 76,
      "z": 0,
      "name": "Plant_Leaves_Jungle",
      "support": 15
    },
    {
      "x": -4,
      "y": 22,
      "z": 1,
      "name": "Empty"
    },
    {
      "x": -4,
      "y": 23,
      "z": 1,
      "name": "Empty"
    },
    {
      "x": -4,
      "y": 24,
      "z": 1,
      "name": "Empty"
    },
    {
      "x": -4,
      "y": 25,
      "z": 1,
      "name": "Empty"
    },
    {
      "x": -4,
      "y": 26,
      "z": 1,
      "name": "Empty"
    },
    {
      "x": -4,
      "y": 27,
      "z": 1,
      "name": "Wood_Jungle_Trunk",
      "support": 15
    },
    {
      "x": -4,
      "y": 28,
      "z": 1,
      "name": "Soil_Dirt_Burnt"
    },
    {
      "x": -4,
      "y": 29,
      "z": 1,
      "name": "Soil_Dirt_Burnt"
    },
    {
      "x": -4,
      "y": 30,
      "z": 1,
      "name": "Soil_Dirt_Burnt"
    },
    {
      "x": -4,
      "y": 31,
      "z": 1,
      "name": "Soil_Dirt_Burnt"
    },
    {
      "x": -4,
      "y": 32,
      "z": 1,
      "name": "Wood_Jungle_Trunk",
      "support": 15
    },
    {
      "x": -4,
      "y": 33,
      "z": 1,
      "name": "Wood_Jungle_Trunk",
      "support": 15
    },
    {
      "x": -4,
      "y": 34,
      "z": 1,
      "name": "Wood_Jungle_Trunk",
      "support": 15
    },
    {
      "x": -4,
      "y": 35,
      "z": 1,
      "name": "Wood_Jungle_Trunk",
      "support": 15
    },
    {
      "x": -4,
      "y": 36,
      "z": 1,
      "name": "Wood_Jungle_Trunk",
      "support": 15
    },
    {
      "x": -4,
      "y": 37,
      "z": 1,
      "name": "Wood_Jungle_Trunk",
      "support": 15
    },
    {
      "x": -4,
      "y": 38,
      "z": 1,
      "name": "Soil_Dirt_Burnt"
    },
    {
      "x": -4,
      "y": 39,
      "z": 1,
      "name": "Soil_Dirt_Burnt"
    },
    {
      "x": -4,
      "y": 40,
      "z": 1,
      "name": "Soil_Dirt_Burnt"
    },
    {
      "x": -4,
      "y": 41,
      "z": 1,
      "name": "Soil_Grass_Full"
    },
    {
      "x": -4,
      "y": 42,
      "z": 1,
      "name": "Empty"
    },
    {
      "x": -4,
      "y": 43,
      "z": 1,
      "name": "Empty"
    },
    {
      "x": -4,
      "y": 44,
      "z": 1,
      "name": "Empty"
    },
    {
      "x": -4,
      "y": 47,
      "z": 1,
      "name": "Soil_Dirt_Burnt"
    },
    {
      "x": -4,
      "y": 48,
      "z": 1,
      "name": "Soil_Dirt_Burnt"
    },
    {
      "x": -4,
      "y": 49,
      "z": 1,
      "name": "Soil_Dirt_Burnt"
    },
    {
      "x": -4,
      "y": 50,
      "z": 1,
      "name": "Soil_Grass_Full"
    },
    {
      "x": -4,
      "y": 75,
      "z": 1,
      "name": "Wood_Jungle_Trunk",
      "support": 15
    },
    {
      "x": -4,
      "y": 76,
      "z": 1,
      "name": "Plant_Leaves_Jungle",
      "support": 15
    },
    {
      "x": -4,
      "y": 23,
      "z": 2,
      "name": "Empty"
    },
    {
      "x": -4,
      "y": 24,
      "z": 2,
      "name": "Empty"
    },
    {
      "x": -4,
      "y": 27,
      "z": 2,
      "name": "Wood_Jungle_Trunk",
      "support": 15
    },
    {
      "x": -4,
      "y": 28,
      "z": 2,
      "name": "Soil_Dirt_Burnt"
    },
    {
      "x": -4,
      "y": 29,
      "z": 2,
      "name": "Soil_Dirt_Burnt"
    },
    {
      "x": -4,
      "y": 30,
      "z": 2,
      "name": "Soil_Grass_Full"
    },
    {
      "x": -4,
      "y": 31,
      "z": 2,
      "name": "Empty"
    },
    {
      "x": -4,
      "y": 32,
      "z": 2,
      "name": "Empty"
    },
    {
      "x": -4,
      "y": 33,
      "z": 2,
      "name": "Empty"
    },
    {
      "x": -4,
      "y": 34,
      "z": 2,
      "name": "Soil_Dirt_Burnt"
    },
    {
      "x": -4,
      "y": 35,
      "z": 2,
      "name": "Soil_Dirt_Burnt"
    },
    {
      "x": -4,
      "y": 36,
      "z": 2,
      "name": "Wood_Jungle_Trunk_Full",
      "support": 15
    },
    {
      "x": -4,
      "y": 39,
      "z": 2,
      "name": "Soil_Dirt_Burnt"
    },
    {
      "x": -4,
      "y": 40,
      "z": 2,
      "name": "Soil_Dirt_Burnt"
    },
    {
      "x": -4,
      "y": 41,
      "z": 2,
      "name": "Soil_Grass_Full"
    },
    {
      "x": -4,
      "y": 42,
      "z": 2,
      "name": "Empty"
    },
    {
      "x": -4,
      "y": 43,
      "z": 2,
      "name": "Empty"
    },
    {
      "x": -4,
      "y": 44,
      "z": 2,
      "name": "Empty"
    },
    {
      "x": -4,
      "y": 47,
      "z": 2,
      "name": "Soil_Dirt_Burnt"
    },
    {
      "x": -4,
      "y": 48,
      "z": 2,
      "name": "Soil_Dirt_Burnt"
    },
    {
      "x": -4,
      "y": 49,
      "z": 2,
      "name": "Soil_Dirt_Burnt"
    },
    {
      "x": -4,
      "y": 50,
      "z": 2,
      "name": "Soil_Grass_Full"
    },
    {
      "x": -4,
      "y": 75,
      "z": 2,
      "name": "Wood_Jungle_Branch_Long",
      "support": 15,
      "rotation": 4
    },
    {
      "x": -4,
      "y": 76,
      "z": 2,
      "name": "Plant_Leaves_Jungle",
      "support": 15
    },
    {
      "x": -4,
      "y": 77,
      "z": 2,
      "name": "Plant_Leaves_Jungle",
      "support": 15
    },
    {
      "x": -4,
      "y": 27,
      "z": 3,
      "name": "Soil_Dirt_Burnt"
    },
    {
      "x": -4,
      "y": 28,
      "z": 3,
      "name": "Soil_Dirt_Burnt"
    },
    {
      "x": -4,
      "y": 29,
      "z": 3,
      "name": "Soil_Dirt_Burnt"
    },
    {
      "x": -4,
      "y": 30,
      "z": 3,
      "name": "Soil_Grass_Full"
    },
    {
      "x": -4,
      "y": 31,
      "z": 3,
      "name": "Empty"
    },
    {
      "x": -4,
      "y": 32,
      "z": 3,
      "name": "Empty"
    },
    {
      "x": -4,
      "y": 33,
      "z": 3,
      "name": "Empty"
    },
    {
      "x": -4,
      "y": 70,
      "z": 3,
      "name": "Plant_Leaves_Jungle",
      "support": 15
    },
    {
      "x": -4,
      "y": 75,
      "z": 3,
      "name": "Wood_Jungle_Branch_Long",
      "support": 15,
      "rotation": 4
    },
    {
      "x": -4,
      "y": 76,
      "z": 3,
      "name": "Plant_Leaves_Jungle",
      "support": 15
    },
    {
      "x": -4,
      "y": 28,
      "z": 4,
      "name": "Soil_Dirt_Burnt"
    },
    {
      "x": -4,
      "y": 29,
      "z": 4,
      "name": "Soil_Dirt_Burnt"
    },
    {
      "x": -4,
      "y": 30,
      "z": 4,
      "name": "Soil_Dirt_Burnt"
    },
    {
      "x": -4,
      "y": 31,
      "z": 4,
      "name": "Soil_Dirt_Burnt"
    },
    {
      "x": -4,
      "y": 70,
      "z": 4,
      "name": "Plant_Leaves_Jungle",
      "support": 15
    },
    {
      "x": -4,
      "y": 71,
      "z": 4,
      "name": "Plant_Leaves_Jungle",
      "support": 15
    },
    {
      "x": -4,
      "y": 75,
      "z": 4,
      "name": "Plant_Leaves_Jungle",
      "support": 15
    },
    {
      "x": -4,
      "y": 76,
      "z": 4,
      "name": "Plant_Leaves_Jungle",
      "support": 15
    },
    {
      "x": -4,
      "y": 29,
      "z": 5,
      "name": "Soil_Dirt_Burnt"
    },
    {
      "x": -4,
      "y": 30,
      "z": 5,
      "name": "Soil_Dirt_Burnt"
    },
    {
      "x": -4,
      "y": 72,
      "z": 5,
      "name": "Plant_Leaves_Jungle",
      "support": 15
    },
    {
      "x": -4,
      "y": 71,
      "z": 6,
      "name": "Plant_Leaves_Jungle",
      "support": 15
    },
    {
      "x": -4,
      "y": 72,
      "z": 6,
      "name": "Plant_Leaves_Jungle",
      "support": 15
    },
    {
      "x": -4,
      "y": 72,
      "z": 7,
      "name": "Plant_Leaves_Jungle",
      "support": 15
    },
    {
      "x": -4,
      "y": 72,
      "z": 8,
      "name": "Plant_Leaves_Jungle",
      "support": 15
    },
    {
      "x": -4,
      "y": 71,
      "z": 9,
      "name": "Plant_Leaves_Jungle",
      "support": 15
    },
    {
      "x": -3,
      "y": 70,
      "z": -11,
      "name": "Plant_Leaves_Palm",
      "support": 15
    },
    {
      "x": -3,
      "y": 71,
      "z": -11,
      "name": "Plant_Leaves_Palm",
      "support": 15
    },
    {
      "x": -3,
      "y": 70,
      "z": -10,
      "name": "Wood_Jungle_Trunk",
      "support": 15
    },
    {
      "x": -3,
      "y": 71,
      "z": -10,
      "name": "Plant_Leaves_Jungle",
      "support": 15
    },
    {
      "x": -3,
      "y": 62,
      "z": -9,
      "name": "Plant_Leaves_Palm_Oasis",
      "support": 15
    },
    {
      "x": -3,
      "y": 63,
      "z": -9,
      "name": "Wood_Jungle_Branch_Long",
      "support": 15
    },
    {
      "x": -3,
      "y": 64,
      "z": -9,
      "name": "Wood_Jungle_Branch_Long",
      "support": 15
    },
    {
      "x": -3,
      "y": 65,
      "z": -9,
      "name": "Wood_Jungle_Branch_Long",
      "support": 15
    },
    {
      "x": -3,
      "y": 66,
      "z": -9,
      "name": "Wood_Jungle_Branch_Long",
      "support": 15
    },
    {
      "x": -3,
      "y": 67,
      "z": -9,
      "name": "Wood_Jungle_Branch_Long",
      "support": 15
    },
    {
      "x": -3,
      "y": 68,
      "z": -9,
      "name": "Wood_Jungle_Branch_Long",
      "support": 15
    },
    {
      "x": -3,
      "y": 69,
      "z": -9,
      "name": "Wood_Jungle_Branch_Long",
      "support": 15
    },
    {
      "x": -3,
      "y": 70,
      "z": -9,
      "name": "Wood_Jungle_Trunk",
      "support": 15
    },
    {
      "x": -3,
      "y": 71,
      "z": -9,
      "name": "Plant_Leaves_Jungle",
      "support": 15
    },
    {
      "x": -3,
      "y": 70,
      "z": -8,
      "name": "Wood_Jungle_Trunk",
      "support": 15
    },
    {
      "x": -3,
      "y": 71,
      "z": -8,
      "name": "Plant_Leaves_Jungle",
      "support": 15
    },
    {
      "x": -3,
      "y": 71,
      "z": -7,
      "name": "Plant_Leaves_Jungle",
      "support": 15
    },
    {
      "x": -3,
      "y": 71,
      "z": -6,
      "name": "Plant_Leaves_Jungle",
      "support": 15
    },
    {
      "x": -3,
      "y": 72,
      "z": -6,
      "name": "Plant_Leaves_Jungle",
      "support": 15
    },
    {
      "x": -3,
      "y": 22,
      "z": -5,
      "name": "Soil_Dirt_Burnt"
    },
    {
      "x": -3,
      "y": 23,
      "z": -5,
      "name": "Soil_Dirt_Burnt"
    },
    {
      "x": -3,
      "y": 24,
      "z": -5,
      "name": "Soil_Dirt_Burnt"
    },
    {
      "x": -3,
      "y": 25,
      "z": -5,
      "name": "Wood_Jungle_Trunk",
      "support": 15
    },
    {
      "x": -3,
      "y": 26,
      "z": -5,
      "name": "Wood_Jungle_Trunk_Full",
      "support": 15
    },
    {
      "x": -3,
      "y": 70,
      "z": -5,
      "name": "Wood_Jungle_Trunk",
      "support": 15
    },
    {
      "x": -3,
      "y": 71,
      "z": -5,
      "name": "Plant_Leaves_Jungle",
      "support": 15
    },
    {
      "x": -3,
      "y": 72,
      "z": -5,
      "name": "Plant_Leaves_Jungle",
      "support": 15
    },
    {
      "x": -3,
      "y": 21,
      "z": -4,
      "name": "Soil_Dirt_Burnt"
    },
    {
      "x": -3,
      "y": 22,
      "z": -4,
      "name": "Soil_Dirt_Burnt"
    },
    {
      "x": -3,
      "y": 23,
      "z": -4,
      "name": "Soil_Dirt_Burnt"
    },
    {
      "x": -3,
      "y": 24,
      "z": -4,
      "name": "Wood_Jungle_Trunk",
      "support": 15
    },
    {
      "x": -3,
      "y": 25,
      "z": -4,
      "name": "Wood_Jungle_Trunk",
      "support": 15
    },
    {
      "x": -3,
      "y": 26,
      "z": -4,
      "name": "Wood_Jungle_Trunk",
      "support": 15
    },
    {
      "x": -3,
      "y": 27,
      "z": -4,
      "name": "Wood_Jungle_Trunk_Full",
      "support": 15
    },
    {
      "x": -3,
      "y": 65,
      "z": -4,
      "name": "Plant_Leaves_Palm_Oasis",
      "support": 15
    },
    {
      "x": -3,
      "y": 66,
      "z": -4,
      "name": "Wood_Jungle_Branch_Long",
      "support": 15
    },
    {
      "x": -3,
      "y": 67,
      "z": -4,
      "name": "Wood_Jungle_Branch_Long",
      "support": 15
    },
    {
      "x": -3,
      "y": 68,
      "z": -4,
      "name": "Wood_Jungle_Branch_Long",
      "support": 15
    },
    {
      "x": -3,
      "y": 69,
      "z": -4,
      "name": "Wood_Jungle_Trunk",
      "support": 15
    },
    {
      "x": -3,
      "y": 70,
      "z": -4,
      "name": "Wood_Jungle_Trunk",
      "support": 15
    },
    {
      "x": -3,
      "y": 71,
      "z": -4,
      "name": "Plant_Leaves_Jungle",
      "support": 15
    },
    {
      "x": -3,
      "y": 21,
      "z": -3,
      "name": "Soil_Dirt_Burnt"
    },
    {
      "x": -3,
      "y": 22,
      "z": -3,
      "name": "Soil_Dirt_Burnt"
    },
    {
      "x": -3,
      "y": 23,
      "z": -3,
      "name": "Soil_Dirt_Burnt"
    },
    {
      "x": -3,
      "y": 24,
      "z": -3,
      "name": "Soil_Dirt_Burnt"
    },
    {
      "x": -3,
      "y": 25,
      "z": -3,
      "name": "Soil_Dirt_Burnt"
    },
    {
      "x": -3,
      "y": 26,
      "z": -3,
      "name": "Soil_Dirt_Burnt"
    },
    {
      "x": -3,
      "y": 27,
      "z": -3,
      "name": "Wood_Jungle_Trunk",
      "support": 15
    },
    {
      "x": -3,
      "y": 28,
      "z": -3,
      "name": "Wood_Jungle_Trunk",
      "support": 15
    },
    {
      "x": -3,
      "y": 29,
      "z": -3,
      "name": "Wood_Jungle_Trunk_Full",
      "support": 15
    },
    {
      "x": -3,
      "y": 69,
      "z": -3,
      "name": "Wood_Jungle_Trunk",
      "support": 15
    },
    {
      "x": -3,
      "y": 70,
      "z": -3,
      "name": "Wood_Jungle_Trunk",
      "support": 15
    },
    {
      "x": -3,
      "y": 71,
      "z": -3,
      "name": "Plant_Leaves_Jungle",
      "support": 15
    },
    {
      "x": -3,
      "y": 21,
      "z": -2,
      "name": "Soil_Dirt_Burnt"
    },
    {
      "x": -3,
      "y": 22,
      "z": -2,
      "name": "Soil_Dirt_Burnt"
    },
    {
      "x": -3,
      "y": 23,
      "z": -2,
      "name": "Soil_Dirt_Burnt"
    },
    {
      "x": -3,
      "y": 24,
      "z": -2,
      "name": "Soil_Dirt_Burnt"
    },
    {
      "x": -3,
      "y": 25,
      "z": -2,
      "name": "Soil_Dirt_Burnt"
    },
    {
      "x": -3,
      "y": 26,
      "z": -2,
      "name": "Empty"
    },
    {
      "x": -3,
      "y": 27,
      "z": -2,
      "name": "Empty"
    },
    {
      "x": -3,
      "y": 28,
      "z": -2,
      "name": "Empty"
    },
    {
      "x": -3,
      "y": 29,
      "z": -2,
      "name": "Empty"
    },
    {
      "x": -3,
      "y": 30,
      "z": -2,
      "name": "Empty"
    },
    {
      "x": -3,
      "y": 31,
      "z": -2,
      "name": "Empty"
    },
    {
      "x": -3,
      "y": 32,
      "z": -2,
      "name": "Empty"
    },
    {
      "x": -3,
      "y": 33,
      "z": -2,
      "name": "Empty"
    },
    {
      "x": -3,
      "y": 46,
      "z": -2,
      "name": "Soil_Dirt_Burnt"
    },
    {
      "x": -3,
      "y": 47,
      "z": -2,
      "name": "Soil_Dirt_Burnt"
    },
    {
      "x": -3,
      "y": 48,
      "z": -2,
      "name": "Soil_Dirt_Burnt"
    },
    {
      "x": -3,
      "y": 49,
      "z": -2,
      "name": "Soil_Dirt_Burnt"
    },
    {
      "x": -3,
      "y": 50,
      "z": -2,
      "name": "Soil_Grass_Full"
    },
    {
      "x": -3,
      "y": 70,
      "z": -2,
      "name": "Plant_Leaves_Jungle",
      "support": 15
    },
    {
      "x": -3,
      "y": 71,
      "z": -2,
      "name": "Plant_Leaves_Jungle",
      "support": 15
    },
    {
      "x": -3,
      "y": 75,
      "z": -2,
      "name": "Plant_Leaves_Jungle",
      "support": 15
    },
    {
      "x": -3,
      "y": 76,
      "z": -2,
      "name": "Plant_Leaves_Jungle",
      "support": 15
    },
    {
      "x": -3,
      "y": 21,
      "z": -1,
      "name": "Empty"
    },
    {
      "x": -3,
      "y": 22,
      "z": -1,
      "name": "Empty"
    },
    {
      "x": -3,
      "y": 23,
      "z": -1,
      "name": "Empty"
    },
    {
      "x": -3,
      "y": 24,
      "z": -1,
      "name": "Empty"
    },
    {
      "x": -3,
      "y": 25,
      "z": -1,
      "name": "Empty"
    },
    {
      "x": -3,
      "y": 26,
      "z": -1,
      "name": "Empty"
    },
    {
      "x": -3,
      "y": 27,
      "z": -1,
      "name": "Empty"
    },
    {
      "x": -3,
      "y": 28,
      "z": -1,
      "name": "Empty"
    },
    {
      "x": -3,
      "y": 29,
      "z": -1,
      "name": "Empty"
    },
    {
      "x": -3,
      "y": 30,
      "z": -1,
      "name": "Empty"
    },
    {
      "x": -3,
      "y": 31,
      "z": -1,
      "name": "Empty"
    },
    {
      "x": -3,
      "y": 32,
      "z": -1,
      "name": "Empty"
    },
    {
      "x": -3,
      "y": 33,
      "z": -1,
      "name": "Empty"
    },
    {
      "x": -3,
      "y": 34,
      "z": -1,
      "name": "Empty"
    },
    {
      "x": -3,
      "y": 35,
      "z": -1,
      "name": "Empty"
    },
    {
      "x": -3,
      "y": 39,
      "z": -1,
      "name": "Soil_Dirt_Burnt"
    },
    {
      "x": -3,
      "y": 40,
      "z": -1,
      "name": "Soil_Dirt_Burnt"
    },
    {
      "x": -3,
      "y": 41,
      "z": -1,
      "name": "Soil_Grass_Full"
    },
    {
      "x": -3,
      "y": 42,
      "z": -1,
      "name": "Empty"
    },
    {
      "x": -3,
      "y": 43,
      "z": -1,
      "name": "Empty"
    },
    {
      "x": -3,
      "y": 44,
      "z": -1,
      "name": "Empty"
    },
    {
      "x": -3,
      "y": 45,
      "z": -1,
      "name": "Soil_Dirt_Burnt"
    },
    {
      "x": -3,
      "y": 46,
      "z": -1,
      "name": "Soil_Dirt_Burnt"
    },
    {
      "x": -3,
      "y": 47,
      "z": -1,
      "name": "Soil_Dirt_Burnt"
    },
    {
      "x": -3,
      "y": 48,
      "z": -1,
      "name": "Soil_Dirt_Burnt"
    },
    {
      "x": -3,
      "y": 49,
      "z": -1,
      "name": "Soil_Dirt_Burnt"
    },
    {
      "x": -3,
      "y": 50,
      "z": -1,
      "name": "Soil_Grass_Full"
    },
    {
      "x": -3,
      "y": 70,
      "z": -1,
      "name": "Plant_Leaves_Jungle",
      "support": 15
    },
    {
      "x": -3,
      "y": 74,
      "z": -1,
      "name": "Plant_Leaves_Jungle",
      "support": 15
    },
    {
      "x": -3,
      "y": 75,
      "z": -1,
      "name": "Plant_Leaves_Jungle",
      "support": 15
    },
    {
      "x": -3,
      "y": 21,
      "z": 0,
      "name": "Empty"
    },
    {
      "x": -3,
      "y": 22,
      "z": 0,
      "name": "Empty"
    },
    {
      "x": -3,
      "y": 23,
      "z": 0,
      "name": "Empty"
    },
    {
      "x": -3,
      "y": 24,
      "z": 0,
      "name": "Empty"
    },
    {
      "x": -3,
      "y": 25,
      "z": 0,
      "name": "Empty"
    },
    {
      "x": -3,
      "y": 26,
      "z": 0,
      "name": "Empty"
    },
    {
      "x": -3,
      "y": 27,
      "z": 0,
      "name": "Empty"
    },
    {
      "x": -3,
      "y": 28,
      "z": 0,
      "name": "Empty"
    },
    {
      "x": -3,
      "y": 29,
      "z": 0,
      "name": "Empty"
    },
    {
      "x": -3,
      "y": 30,
      "z": 0,
      "name": "Empty"
    },
    {
      "x": -3,
      "y": 31,
      "z": 0,
      "name": "Empty"
    },
    {
      "x": -3,
      "y": 32,
      "z": 0,
      "name": "Empty"
    },
    {
      "x": -3,
      "y": 33,
      "z": 0,
      "name": "Empty"
    },
    {
      "x": -3,
      "y": 34,
      "z": 0,
      "name": "Empty"
    },
    {
      "x": -3,
      "y": 35,
      "z": 0,
      "name": "Wood_Jungle_Trunk",
      "support": 15
    },
    {
      "x": -3,
      "y": 36,
      "z": 0,
      "name": "Wood_Jungle_Trunk_Full",
      "support": 15
    },
    {
      "x": -3,
      "y": 38,
      "z": 0,
      "name": "Soil_Dirt_Burnt"
    },
    {
      "x": -3,
      "y": 39,
      "z": 0,
      "name": "Soil_Dirt_Burnt"
    },
    {
      "x": -3,
      "y": 40,
      "z": 0,
      "name": "Soil_Dirt_Burnt"
    },
    {
      "x": -3,
      "y": 41,
      "z": 0,
      "name": "Soil_Grass_Full"
    },
    {
      "x": -3,
      "y": 42,
      "z": 0,
      "name": "Empty"
    },
    {
      "x": -3,
      "y": 43,
      "z": 0,
      "name": "Empty"
    },
    {
      "x": -3,
      "y": 44,
      "z": 0,
      "name": "Empty"
    },
    {
      "x": -3,
      "y": 45,
      "z": 0,
      "name": "Empty"
    },
    {
      "x": -3,
      "y": 46,
      "z": 0,
      "name": "Soil_Dirt_Burnt"
    },
    {
      "x": -3,
      "y": 47,
      "z": 0,
      "name": "Soil_Dirt_Burnt"
    },
    {
      "x": -3,
      "y": 48,
      "z": 0,
      "name": "Soil_Dirt_Burnt"
    },
    {
      "x": -3,
      "y": 49,
      "z": 0,
      "name": "Soil_Dirt_Burnt"
    },
    {
      "x": -3,
      "y": 50,
      "z": 0,
      "name": "Soil_Grass_Full"
    },
    {
      "x": -3,
      "y": 73,
      "z": 0,
      "name": "Wood_Jungle_Trunk",
      "support": 15
    },
    {
      "x": -3,
      "y": 74,
      "z": 0,
      "name": "Wood_Jungle_Trunk",
      "support": 15
    },
    {
      "x": -3,
      "y": 75,
      "z": 0,
      "name": "Plant_Leaves_Jungle",
      "support": 15
    },
    {
      "x": -3,
      "y": 76,
      "z": 0,
      "name": "Plant_Leaves_Jungle",
      "support": 15
    },
    {
      "x": -3,
      "y": 21,
      "z": 1,
      "name": "Empty"
    },
    {
      "x": -3,
      "y": 22,
      "z": 1,
      "name": "Empty"
    },
    {
      "x": -3,
      "y": 23,
      "z": 1,
      "name": "Empty"
    },
    {
      "x": -3,
      "y": 24,
      "z": 1,
      "name": "Empty"
    },
    {
      "x": -3,
      "y": 25,
      "z": 1,
      "name": "Empty"
    },
    {
      "x": -3,
      "y": 26,
      "z": 1,
      "name": "Empty"
    },
    {
      "x": -3,
      "y": 27,
      "z": 1,
      "name": "Empty"
    },
    {
      "x": -3,
      "y": 28,
      "z": 1,
      "name": "Empty"
    },
    {
      "x": -3,
      "y": 29,
      "z": 1,
      "name": "Empty"
    },
    {
      "x": -3,
      "y": 30,
      "z": 1,
      "name": "Empty"
    },
    {
      "x": -3,
      "y": 31,
      "z": 1,
      "name": "Empty"
    },
    {
      "x": -3,
      "y": 32,
      "z": 1,
      "name": "Empty"
    },
    {
      "x": -3,
      "y": 33,
      "z": 1,
      "name": "Wood_Jungle_Trunk",
      "support": 15
    },
    {
      "x": -3,
      "y": 34,
      "z": 1,
      "name": "Wood_Jungle_Trunk",
      "support": 15
    },
    {
      "x": -3,
      "y": 35,
      "z": 1,
      "name": "Wood_Jungle_Trunk",
      "support": 15
    },
    {
      "x": -3,
      "y": 36,
      "z": 1,
      "name": "Wood_Jungle_Trunk",
      "support": 15
    },
    {
      "x": -3,
      "y": 37,
      "z": 1,
      "name": "Wood_Jungle_Trunk",
      "support": 15
    },
    {
      "x": -3,
      "y": 38,
      "z": 1,
      "name": "Wood_Jungle_Trunk",
      "support": 15
    },
    {
      "x": -3,
      "y": 39,
      "z": 1,
      "name": "Wood_Jungle_Trunk",
      "support": 15
    },
    {
      "x": -3,
      "y": 40,
      "z": 1,
      "name": "Soil_Dirt_Burnt"
    },
    {
      "x": -3,
      "y": 41,
      "z": 1,
      "name": "Soil_Grass_Full"
    },
    {
      "x": -3,
      "y": 42,
      "z": 1,
      "name": "Empty"
    },
    {
      "x": -3,
      "y": 43,
      "z": 1,
      "name": "Empty"
    },
    {
      "x": -3,
      "y": 44,
      "z": 1,
      "name": "Empty"
    },
    {
      "x": -3,
      "y": 45,
      "z": 1,
      "name": "Empty"
    },
    {
      "x": -3,
      "y": 46,
      "z": 1,
      "name": "Empty"
    },
    {
      "x": -3,
      "y": 47,
      "z": 1,
      "name": "Soil_Dirt_Burnt"
    },
    {
      "x": -3,
      "y": 48,
      "z": 1,
      "name": "Soil_Dirt_Burnt"
    },
    {
      "x": -3,
      "y": 49,
      "z": 1,
      "name": "Soil_Dirt_Burnt"
    },
    {
      "x": -3,
      "y": 50,
      "z": 1,
      "name": "Soil_Grass_Full"
    },
    {
      "x": -3,
      "y": 74,
      "z": 1,
      "name": "Plant_Leaves_Jungle",
      "support": 15
    },
    {
      "x": -3,
      "y": 75,
      "z": 1,
      "name": "Plant_Leaves_Jungle",
      "support": 15
    },
    {
      "x": -3,
      "y": 76,
      "z": 1,
      "name": "Plant_Leaves_Jungle",
      "support": 15
    },
    {
      "x": -3,
      "y": 23,
      "z": 2,
      "name": "Empty"
    },
    {
      "x": -3,
      "y": 24,
      "z": 2,
      "name": "Empty"
    },
    {
      "x": -3,
      "y": 25,
      "z": 2,
      "name": "Empty"
    },
    {
      "x": -3,
      "y": 27,
      "z": 2,
      "name": "Wood_Jungle_Trunk",
      "support": 15
    },
    {
      "x": -3,
      "y": 28,
      "z": 2,
      "name": "Soil_Dirt_Burnt"
    },
    {
      "x": -3,
      "y": 29,
      "z": 2,
      "name": "Soil_Dirt_Burnt"
    },
    {
      "x": -3,
      "y": 30,
      "z": 2,
      "name": "Soil_Grass_Full"
    },
    {
      "x": -3,
      "y": 31,
      "z": 2,
      "name": "Empty"
    },
    {
      "x": -3,
      "y": 32,
      "z": 2,
      "name": "Empty"
    },
    {
      "x": -3,
      "y": 33,
      "z": 2,
      "name": "Empty"
    },
    {
      "x": -3,
      "y": 34,
      "z": 2,
      "name": "Empty"
    },
    {
      "x": -3,
      "y": 35,
      "z": 2,
      "name": "Wood_Jungle_Trunk",
      "support": 15
    },
    {
      "x": -3,
      "y": 36,
      "z": 2,
      "name": "Wood_Jungle_Trunk",
      "support": 15
    },
    {
      "x": -3,
      "y": 37,
      "z": 2,
      "name": "Wood_Jungle_Trunk",
      "support": 15
    },
    {
      "x": -3,
      "y": 38,
      "z": 2,
      "name": "Wood_Jungle_Trunk",
      "support": 15
    },
    {
      "x": -3,
      "y": 39,
      "z": 2,
      "name": "Wood_Jungle_Trunk",
      "support": 15
    },
    {
      "x": -3,
      "y": 40,
      "z": 2,
      "name": "Wood_Jungle_Trunk",
      "support": 15
    },
    {
      "x": -3,
      "y": 41,
      "z": 2,
      "name": "Wood_Jungle_Trunk",
      "support": 15
    },
    {
      "x": -3,
      "y": 42,
      "z": 2,
      "name": "Wood_Jungle_Trunk",
      "support": 15
    },
    {
      "x": -3,
      "y": 43,
      "z": 2,
      "name": "Wood_Jungle_Trunk_Full",
      "support": 15
    },
    {
      "x": -3,
      "y": 44,
      "z": 2,
      "name": "Empty"
    },
    {
      "x": -3,
      "y": 45,
      "z": 2,
      "name": "Empty"
    },
    {
      "x": -3,
      "y": 46,
      "z": 2,
      "name": "Soil_Dirt_Burnt"
    },
    {
      "x": -3,
      "y": 47,
      "z": 2,
      "name": "Soil_Dirt_Burnt"
    },
    {
      "x": -3,
      "y": 48,
      "z": 2,
      "name": "Soil_Dirt_Burnt"
    },
    {
      "x": -3,
      "y": 49,
      "z": 2,
      "name": "Soil_Dirt_Burnt"
    },
    {
      "x": -3,
      "y": 50,
      "z": 2,
      "name": "Soil_Grass_Full"
    },
    {
      "x": -3,
      "y": 69,
      "z": 2,
      "name": "Plant_Leaves_Jungle",
      "support": 15
    },
    {
      "x": -3,
      "y": 75,
      "z": 2,
      "name": "Plant_Leaves_Jungle",
      "support": 15
    },
    {
      "x": -3,
      "y": 76,
      "z": 2,
      "name": "Plant_Leaves_Jungle",
      "support": 15
    },
    {
      "x": -3,
      "y": 27,
      "z": 3,
      "name": "Wood_Jungle_Trunk",
      "support": 15
    },
    {
      "x": -3,
      "y": 28,
      "z": 3,
      "name": "Soil_Dirt_Burnt"
    },
    {
      "x": -3,
      "y": 29,
      "z": 3,
      "name": "Soil_Dirt_Burnt"
    },
    {
      "x": -3,
      "y": 30,
      "z": 3,
      "name": "Soil_Grass_Full"
    },
    {
      "x": -3,
      "y": 31,
      "z": 3,
      "name": "Empty"
    },
    {
      "x": -3,
      "y": 32,
      "z": 3,
      "name": "Empty"
    },
    {
      "x": -3,
      "y": 33,
      "z": 3,
      "name": "Empty"
    },
    {
      "x": -3,
      "y": 34,
      "z": 3,
      "name": "Empty"
    },
    {
      "x": -3,
      "y": 48,
      "z": 3,
      "name": "Soil_Dirt_Burnt"
    },
    {
      "x": -3,
      "y": 49,
      "z": 3,
      "name": "Soil_Dirt_Burnt"
    },
    {
      "x": -3,
      "y": 70,
      "z": 3,
      "name": "Plant_Leaves_Jungle",
      "support": 15
    },
    {
      "x": -3,
      "y": 75,
      "z": 3,
      "name": "Plant_Leaves_Jungle",
      "support": 15
    },
    {
      "x": -3,
      "y": 27,
      "z": 4,
      "name": "Soil_Dirt_Burnt"
    },
    {
      "x": -3,
      "y": 28,
      "z": 4,
      "name": "Soil_Dirt_Burnt"
    },
    {
      "x": -3,
      "y": 29,
      "z": 4,
      "name": "Soil_Dirt_Burnt"
    },
    {
      "x": -3,
      "y": 30,
      "z": 4,
      "name": "Soil_Grass_Full"
    },
    {
      "x": -3,
      "y": 31,
      "z": 4,
      "name": "Empty"
    },
    {
      "x": -3,
      "y": 32,
      "z": 4,
      "name": "Empty"
    },
    {
      "x": -3,
      "y": 33,
      "z": 4,
      "name": "Empty"
    },
    {
      "x": -3,
      "y": 61,
      "z": 4,
      "name": "Plant_Leaves_Palm_Oasis",
      "support": 15
    },
    {
      "x": -3,
      "y": 62,
      "z": 4,
      "name": "Wood_Jungle_Branch_Long",
      "support": 15
    },
    {
      "x": -3,
      "y": 63,
      "z": 4,
      "name": "Wood_Jungle_Branch_Long",
      "support": 15
    },
    {
      "x": -3,
      "y": 64,
      "z": 4,
      "name": "Wood_Jungle_Branch_Long",
      "support": 15
    },
    {
      "x": -3,
      "y": 65,
      "z": 4,
      "name": "Wood_Jungle_Branch_Long",
      "support": 15
    },
    {
      "x": -3,
      "y": 66,
      "z": 4,
      "name": "Wood_Jungle_Branch_Long",
      "support": 15
    },
    {
      "x": -3,
      "y": 67,
      "z": 4,
      "name": "Wood_Jungle_Branch_Long",
      "support": 15
    },
    {
      "x": -3,
      "y": 68,
      "z": 4,
      "name": "Wood_Jungle_Branch_Long",
      "support": 15
    },
    {
      "x": -3,
      "y": 69,
      "z": 4,
      "name": "Wood_Jungle_Branch_Long",
      "support": 15
    },
    {
      "x": -3,
      "y": 70,
      "z": 4,
      "name": "Wood_Jungle_Branch_Corner",
      "support": 15,
      "rotation": 9
    },
    {
      "x": -3,
      "y": 71,
      "z": 4,
      "name": "Plant_Leaves_Jungle",
      "support": 15
    },
    {
      "x": -3,
      "y": 75,
      "z": 4,
      "name": "Plant_Leaves_Jungle",
      "support": 15
    },
    {
      "x": -3,
      "y": 28,
      "z": 5,
      "name": "Soil_Dirt_Burnt"
    },
    {
      "x": -3,
      "y": 29,
      "z": 5,
      "name": "Soil_Dirt_Burnt"
    },
    {
      "x": -3,
      "y": 30,
      "z": 5,
      "name": "Soil_Dirt_Burnt"
    },
    {
      "x": -3,
      "y": 71,
      "z": 5,
      "name": "Plant_Leaves_Jungle",
      "support": 15
    },
    {
      "x": -3,
      "y": 72,
      "z": 5,
      "name": "Plant_Leaves_Jungle",
      "support": 15
    },
    {
      "x": -3,
      "y": 72,
      "z": 6,
      "name": "Plant_Leaves_Jungle",
      "support": 15
    },
    {
      "x": -3,
      "y": 72,
      "z": 7,
      "name": "Plant_Leaves_Jungle",
      "support": 15
    },
    {
      "x": -3,
      "y": 71,
      "z": 8,
      "name": "Plant_Leaves_Jungle",
      "support": 15
    },
    {
      "x": -3,
      "y": 72,
      "z": 8,
      "name": "Plant_Leaves_Jungle",
      "support": 15
    },
    {
      "x": -3,
      "y": 71,
      "z": 9,
      "name": "Plant_Leaves_Jungle",
      "support": 15
    },
    {
      "x": -3,
      "y": 72,
      "z": 9,
      "name": "Plant_Leaves_Jungle",
      "support": 15
    },
    {
      "x": -2,
      "y": 70,
      "z": -11,
      "name": "Plant_Leaves_Palm",
      "support": 15
    },
    {
      "x": -2,
      "y": 71,
      "z": -10,
      "name": "Plant_Leaves_Jungle",
      "support": 15
    },
    {
      "x": -2,
      "y": 70,
      "z": -9,
      "name": "Wood_Jungle_Branch_Long",
      "support": 15,
      "rotation": 5
    },
    {
      "x": -2,
      "y": 71,
      "z": -9,
      "name": "Plant_Leaves_Jungle",
      "support": 15
    },
    {
      "x": -2,
      "y": 71,
      "z": -8,
      "name": "Plant_Leaves_Jungle",
      "support": 15
    },
    {
      "x": -2,
      "y": 71,
      "z": -6,
      "name": "Plant_Leaves_Jungle",
      "support": 15
    },
    {
      "x": -2,
      "y": 22,
      "z": -5,
      "name": "Soil_Dirt_Burnt"
    },
    {
      "x": -2,
      "y": 23,
      "z": -5,
      "name": "Soil_Dirt_Burnt"
    },
    {
      "x": -2,
      "y": 24,
      "z": -5,
      "name": "Wood_Jungle_Trunk",
      "support": 15
    },
    {
      "x": -2,
      "y": 25,
      "z": -5,
      "name": "Wood_Jungle_Trunk_Full",
      "support": 15
    },
    {
      "x": -2,
      "y": 70,
      "z": -5,
      "name": "Wood_Jungle_Branch_Long",
      "support": 15,
      "rotation": 5
    },
    {
      "x": -2,
      "y": 71,
      "z": -5,
      "name": "Plant_Leaves_Jungle",
      "support": 15
    },
    {
      "x": -2,
      "y": 72,
      "z": -5,
      "name": "Plant_Leaves_Jungle",
      "support": 15
    },
    {
      "x": -2,
      "y": 21,
      "z": -4,
      "name": "Soil_Dirt_Burnt"
    },
    {
      "x": -2,
      "y": 22,
      "z": -4,
      "name": "Wood_Jungle_Trunk",
      "support": 15
    },
    {
      "x": -2,
      "y": 23,
      "z": -4,
      "name": "Wood_Jungle_Trunk",
      "support": 15
    },
    {
      "x": -2,
      "y": 24,
      "z": -4,
      "name": "Wood_Jungle_Trunk",
      "support": 15
    },
    {
      "x": -2,
      "y": 25,
      "z": -4,
      "name": "Wood_Jungle_Trunk",
      "support": 15
    },
    {
      "x": -2,
      "y": 26,
      "z": -4,
      "name": "Wood_Jungle_Trunk_Full",
      "support": 15
    },
    {
      "x": -2,
      "y": 27,
      "z": -4,
      "name": "Empty"
    },
    {
      "x": -2,
      "y": 70,
      "z": -4,
      "name": "Plant_Leaves_Jungle",
      "support": 15
    },
    {
      "x": -2,
      "y": 71,
      "z": -4,
      "name": "Plant_Leaves_Jungle",
      "support": 15
    },
    {
      "x": -2,
      "y": 72,
      "z": -4,
      "name": "Plant_Leaves_Jungle",
      "support": 15
    },
    {
      "x": -2,
      "y": 21,
      "z": -3,
      "name": "Soil_Dirt_Burnt"
    },
    {
      "x": -2,
      "y": 22,
      "z": -3,
      "name": "Soil_Dirt_Burnt"
    },
    {
      "x": -2,
      "y": 23,
      "z": -3,
      "name": "Soil_Dirt_Burnt"
    },
    {
      "x": -2,
      "y": 24,
      "z": -3,
      "name": "Soil_Dirt_Burnt"
    },
    {
      "x": -2,
      "y": 25,
      "z": -3,
      "name": "Soil_Dirt_Burnt"
    },
    {
      "x": -2,
      "y": 26,
      "z": -3,
      "name": "Empty"
    },
    {
      "x": -2,
      "y": 27,
      "z": -3,
      "name": "Empty"
    },
    {
      "x": -2,
      "y": 28,
      "z": -3,
      "name": "Empty"
    },
    {
      "x": -2,
      "y": 29,
      "z": -3,
      "name": "Empty"
    },
    {
      "x": -2,
      "y": 30,
      "z": -3,
      "name": "Empty"
    },
    {
      "x": -2,
      "y": 31,
      "z": -3,
      "name": "Empty"
    },
    {
      "x": -2,
      "y": 47,
      "z": -3,
      "name": "Soil_Dirt_Burnt"
    },
    {
      "x": -2,
      "y": 48,
      "z": -3,
      "name": "Soil_Dirt_Burnt"
    },
    {
      "x": -2,
      "y": 49,
      "z": -3,
      "name": "Soil_Dirt_Burnt"
    },
    {
      "x": -2,
      "y": 50,
      "z": -3,
      "name": "Soil_Grass_Full"
    },
    {
      "x": -2,
      "y": 54,
      "z": -3,
      "name": "Plant_Vine_Jungle",
      "support": 15,
      "rotation": 3
    },
    {
      "x": -2,
      "y": 55,
      "z": -3,
      "name": "Plant_Vine_Jungle",
      "support": 15,
      "rotation": 3
    },
    {
      "x": -2,
      "y": 56,
      "z": -3,
      "name": "Plant_Vine_Jungle",
      "support": 15,
      "rotation": 3
    },
    {
      "x": -2,
      "y": 57,
      "z": -3,
      "name": "Plant_Vine_Jungle",
      "support": 15,
      "rotation": 3
    },
    {
      "x": -2,
      "y": 68,
      "z": -3,
      "name": "Wood_Jungle_Trunk",
      "support": 15
    },
    {
      "x": -2,
      "y": 69,
      "z": -3,
      "name": "Wood_Jungle_Trunk",
      "support": 15
    },
    {
      "x": -2,
      "y": 71,
      "z": -3,
      "name": "Plant_Leaves_Jungle",
      "support": 15
    },
    {
      "x": -2,
      "y": 75,
      "z": -3,
      "name": "Plant_Leaves_Jungle",
      "support": 15
    },
    {
      "x": -2,
      "y": 76,
      "z": -3,
      "name": "Plant_Leaves_Jungle",
      "support": 15
    },
    {
      "x": -2,
      "y": 22,
      "z": -2,
      "name": "Soil_Dirt_Burnt"
    },
    {
      "x": -2,
      "y": 23,
      "z": -2,
      "name": "Soil_Dirt_Burnt"
    },
    {
      "x": -2,
      "y": 24,
      "z": -2,
      "name": "Soil_Dirt_Burnt"
    },
    {
      "x": -2,
      "y": 25,
      "z": -2,
      "name": "Empty"
    },
    {
      "x": -2,
      "y": 26,
      "z": -2,
      "name": "Empty"
    },
    {
      "x": -2,
      "y": 27,
      "z": -2,
      "name": "Empty"
    },
    {
      "x": -2,
      "y": 28,
      "z": -2,
      "name": "Empty"
    },
    {
      "x": -2,
      "y": 29,
      "z": -2,
      "name": "Empty"
    },
    {
      "x": -2,
      "y": 30,
      "z": -2,
      "name": "Empty"
    },
    {
      "x": -2,
      "y": 31,
      "z": -2,
      "name": "Empty"
    },
    {
      "x": -2,
      "y": 32,
      "z": -2,
      "name": "Empty"
    },
    {
      "x": -2,
      "y": 33,
      "z": -2,
      "name": "Empty"
    },
    {
      "x": -2,
      "y": 34,
      "z": -2,
      "name": "Empty"
    },
    {
      "x": -2,
      "y": 35,
      "z": -2,
      "name": "Empty"
    },
    {
      "x": -2,
      "y": 41,
      "z": -2,
      "name": "Empty"
    },
    {
      "x": -2,
      "y": 42,
      "z": -2,
      "name": "Empty"
    },
    {
      "x": -2,
      "y": 43,
      "z": -2,
      "name": "Empty"
    },
    {
      "x": -2,
      "y": 44,
      "z": -2,
      "name": "Empty"
    },
    {
      "x": -2,
      "y": 46,
      "z": -2,
      "name": "Soil_Dirt_Burnt"
    },
    {
      "x": -2,
      "y": 47,
      "z": -2,
      "name": "Soil_Dirt_Burnt"
    },
    {
      "x": -2,
      "y": 48,
      "z": -2,
      "name": "Soil_Dirt_Burnt"
    },
    {
      "x": -2,
      "y": 49,
      "z": -2,
      "name": "Soil_Dirt_Burnt"
    },
    {
      "x": -2,
      "y": 50,
      "z": -2,
      "name": "Soil_Grass_Full"
    },
    {
      "x": -2,
      "y": 52,
      "z": -2,
      "name": "Wood_Jungle_Trunk_Full",
      "support": 15
    },
    {
      "x": -2,
      "y": 53,
      "z": -2,
      "name": "Wood_Jungle_Trunk",
      "support": 15
    },
    {
      "x": -2,
      "y": 54,
      "z": -2,
      "name": "Wood_Jungle_Trunk",
      "support": 15
    },
    {
      "x": -2,
      "y": 55,
      "z": -2,
      "name": "Wood_Jungle_Trunk_Full",
      "support": 15
    },
    {
      "x": -2,
      "y": 56,
      "z": -2,
      "name": "Plant_Vine_Jungle",
      "support": 15,
      "rotation": 3
    },
    {
      "x": -2,
      "y": 57,
      "z": -2,
      "name": "Plant_Vine_Jungle",
      "support": 15,
      "rotation": 3
    },
    {
      "x": -2,
      "y": 58,
      "z": -2,
      "name": "Plant_Vine_Jungle",
      "support": 15,
      "rotation": 3
    },
    {
      "x": -2,
      "y": 59,
      "z": -2,
      "name": "Plant_Vine_Jungle",
      "support": 15,
      "rotation": 3
    },
    {
      "x": -2,
      "y": 60,
      "z": -2,
      "name": "Plant_Vine_Jungle",
      "support": 15,
      "rotation": 3
    },
    {
      "x": -2,
      "y": 68,
      "z": -2,
      "name": "Wood_Jungle_Trunk",
      "support": 15
    },
    {
      "x": -2,
      "y": 69,
      "z": -2,
      "name": "Wood_Jungle_Trunk",
      "support": 15
    },
    {
      "x": -2,
      "y": 70,
      "z": -2,
      "name": "Plant_Leaves_Jungle",
      "support": 15
    },
    {
      "x": -2,
      "y": 75,
      "z": -2,
      "name": "Plant_Leaves_Jungle",
      "support": 15
    },
    {
      "x": -2,
      "y": 21,
      "z": -1,
      "name": "Empty"
    },
    {
      "x": -2,
      "y": 22,
      "z": -1,
      "name": "Empty"
    },
    {
      "x": -2,
      "y": 23,
      "z": -1,
      "name": "Empty"
    },
    {
      "x": -2,
      "y": 24,
      "z": -1,
      "name": "Empty"
    },
    {
      "x": -2,
      "y": 25,
      "z": -1,
      "name": "Empty"
    },
    {
      "x": -2,
      "y": 26,
      "z": -1,
      "name": "Empty"
    },
    {
      "x": -2,
      "y": 27,
      "z": -1,
      "name": "Empty"
    },
    {
      "x": -2,
      "y": 28,
      "z": -1,
      "name": "Empty"
    },
    {
      "x": -2,
      "y": 29,
      "z": -1,
      "name": "Empty"
    },
    {
      "x": -2,
      "y": 30,
      "z": -1,
      "name": "Empty"
    },
    {
      "x": -2,
      "y": 31,
      "z": -1,
      "name": "Empty"
    },
    {
      "x": -2,
      "y": 32,
      "z": -1,
      "name": "Empty"
    },
    {
      "x": -2,
      "y": 33,
      "z": -1,
      "name": "Empty"
    },
    {
      "x": -2,
      "y": 34,
      "z": -1,
      "name": "Empty"
    },
    {
      "x": -2,
      "y": 35,
      "z": -1,
      "name": "Empty"
    },
    {
      "x": -2,
      "y": 36,
      "z": -1,
      "name": "Empty"
    },
    {
      "x": -2,
      "y": 37,
      "z": -1,
      "name": "Empty"
    },
    {
      "x": -2,
      "y": 38,
      "z": -1,
      "name": "Empty"
    },
    {
      "x": -2,
      "y": 39,
      "z": -1,
      "name": "Empty"
    },
    {
      "x": -2,
      "y": 40,
      "z": -1,
      "name": "Soil_Dirt_Burnt"
    },
    {
      "x": -2,
      "y": 41,
      "z": -1,
      "name": "Soil_Grass_Full"
    },
    {
      "x": -2,
      "y": 42,
      "z": -1,
      "name": "Empty"
    },
    {
      "x": -2,
      "y": 43,
      "z": -1,
      "name": "Empty"
    },
    {
      "x": -2,
      "y": 44,
      "z": -1,
      "name": "Empty"
    },
    {
      "x": -2,
      "y": 45,
      "z": -1,
      "name": "Empty"
    },
    {
      "x": -2,
      "y": 46,
      "z": -1,
      "name": "Empty"
    },
    {
      "x": -2,
      "y": 47,
      "z": -1,
      "name": "Soil_Dirt_Burnt"
    },
    {
      "x": -2,
      "y": 48,
      "z": -1,
      "name": "Soil_Dirt_Burnt"
    },
    {
      "x": -2,
      "y": 49,
      "z": -1,
      "name": "Soil_Dirt_Burnt"
    },
    {
      "x": -2,
      "y": 50,
      "z": -1,
      "name": "Soil_Grass_Full"
    },
    {
      "x": -2,
      "y": 51,
      "z": -1,
      "name": "Empty"
    },
    {
      "x": -2,
      "y": 52,
      "z": -1,
      "name": "Empty"
    },
    {
      "x": -2,
      "y": 54,
      "z": -1,
      "name": "Wood_Jungle_Trunk_Full",
      "support": 15
    },
    {
      "x": -2,
      "y": 55,
      "z": -1,
      "name": "Wood_Jungle_Trunk",
      "support": 15
    },
    {
      "x": -2,
      "y": 56,
      "z": -1,
      "name": "Wood_Jungle_Trunk",
      "support": 15
    },
    {
      "x": -2,
      "y": 57,
      "z": -1,
      "name": "Wood_Jungle_Trunk",
      "support": 15
    },
    {
      "x": -2,
      "y": 58,
      "z": -1,
      "name": "Wood_Jungle_Trunk_Full",
      "support": 15
    },
    {
      "x": -2,
      "y": 60,
      "z": -1,
      "name": "Plant_Vine_Jungle",
      "support": 15,
      "rotation": 3
    },
    {
      "x": -2,
      "y": 61,
      "z": -1,
      "name": "Plant_Vine_Jungle",
      "support": 15,
      "rotation": 3
    },
    {
      "x": -2,
      "y": 62,
      "z": -1,
      "name": "Plant_Vine_Jungle",
      "support": 15,
      "rotation": 3
    },
    {
      "x": -2,
      "y": 64,
      "z": -1,
      "name": "Plant_Vine_Jungle",
      "support": 15,
      "rotation": 3
    },
    {
      "x": -2,
      "y": 69,
      "z": -1,
      "name": "Wood_Jungle_Trunk",
      "support": 15
    },
    {
      "x": -2,
      "y": 74,
      "z": -1,
      "name": "Plant_Leaves_Jungle",
      "support": 15
    },
    {
      "x": -2,
      "y": 75,
      "z": -1,
      "name": "Plant_Leaves_Jungle",
      "support": 15
    },
    {
      "x": -2,
      "y": 21,
      "z": 0,
      "name": "Empty"
    },
    {
      "x": -2,
      "y": 22,
      "z": 0,
      "name": "Empty"
    },
    {
      "x": -2,
      "y": 23,
      "z": 0,
      "name": "Empty"
    },
    {
      "x": -2,
      "y": 24,
      "z": 0,
      "name": "Empty"
    },
    {
      "x": -2,
      "y": 25,
      "z": 0,
      "name": "Empty"
    },
    {
      "x": -2,
      "y": 26,
      "z": 0,
      "name": "Empty"
    },
    {
      "x": -2,
      "y": 27,
      "z": 0,
      "name": "Empty"
    },
    {
      "x": -2,
      "y": 28,
      "z": 0,
      "name": "Empty"
    },
    {
      "x": -2,
      "y": 29,
      "z": 0,
      "name": "Empty"
    },
    {
      "x": -2,
      "y": 30,
      "z": 0,
      "name": "Empty"
    },
    {
      "x": -2,
      "y": 31,
      "z": 0,
      "name": "Empty"
    },
    {
      "x": -2,
      "y": 32,
      "z": 0,
      "name": "Empty"
    },
    {
      "x": -2,
      "y": 33,
      "z": 0,
      "name": "Empty"
    },
    {
      "x": -2,
      "y": 34,
      "z": 0,
      "name": "Empty"
    },
    {
      "x": -2,
      "y": 35,
      "z": 0,
      "name": "Empty"
    },
    {
      "x": -2,
      "y": 36,
      "z": 0,
      "name": "Empty"
    },
    {
      "x": -2,
      "y": 37,
      "z": 0,
      "name": "Empty"
    },
    {
      "x": -2,
      "y": 38,
      "z": 0,
      "name": "Empty"
    },
    {
      "x": -2,
      "y": 39,
      "z": 0,
      "name": "Empty"
    },
    {
      "x": -2,
      "y": 40,
      "z": 0,
      "name": "Soil_Dirt_Burnt"
    },
    {
      "x": -2,
      "y": 41,
      "z": 0,
      "name": "Soil_Grass_Full"
    },
    {
      "x": -2,
      "y": 42,
      "z": 0,
      "name": "Empty"
    },
    {
      "x": -2,
      "y": 43,
      "z": 0,
      "name": "Empty"
    },
    {
      "x": -2,
      "y": 44,
      "z": 0,
      "name": "Empty"
    },
    {
      "x": -2,
      "y": 45,
      "z": 0,
      "name": "Empty"
    },
    {
      "x": -2,
      "y": 46,
      "z": 0,
      "name": "Empty"
    },
    {
      "x": -2,
      "y": 47,
      "z": 0,
      "name": "Empty"
    },
    {
      "x": -2,
      "y": 48,
      "z": 0,
      "name": "Empty"
    },
    {
      "x": -2,
      "y": 49,
      "z": 0,
      "name": "Soil_Dirt_Burnt"
    },
    {
      "x": -2,
      "y": 50,
      "z": 0,
      "name": "Soil_Grass_Full"
    },
    {
      "x": -2,
      "y": 51,
      "z": 0,
      "name": "Empty"
    },
    {
      "x": -2,
      "y": 52,
      "z": 0,
      "name": "Empty"
    },
    {
      "x": -2,
      "y": 53,
      "z": 0,
      "name": "Empty"
    },
    {
      "x": -2,
      "y": 54,
      "z": 0,
      "name": "Empty"
    },
    {
      "x": -2,
      "y": 55,
      "z": 0,
      "name": "Empty"
    },
    {
      "x": -2,
      "y": 56,
      "z": 0,
      "name": "Empty"
    },
    {
      "x": -2,
      "y": 72,
      "z": 0,
      "name": "Wood_Jungle_Trunk",
      "support": 15
    },
    {
      "x": -2,
      "y": 73,
      "z": 0,
      "name": "Wood_Jungle_Trunk",
      "support": 15
    },
    {
      "x": -2,
      "y": 74,
      "z": 0,
      "name": "Plant_Leaves_Jungle",
      "support": 15
    },
    {
      "x": -2,
      "y": 75,
      "z": 0,
      "name": "Plant_Leaves_Jungle",
      "support": 15
    },
    {
      "x": -2,
      "y": 21,
      "z": 1,
      "name": "Empty"
    },
    {
      "x": -2,
      "y": 22,
      "z": 1,
      "name": "Empty"
    },
    {
      "x": -2,
      "y": 23,
      "z": 1,
      "name": "Empty"
    },
    {
      "x": -2,
      "y": 24,
      "z": 1,
      "name": "Empty"
    },
    {
      "x": -2,
      "y": 25,
      "z": 1,
      "name": "Empty"
    },
    {
      "x": -2,
      "y": 26,
      "z": 1,
      "name": "Empty"
    },
    {
      "x": -2,
      "y": 27,
      "z": 1,
      "name": "Empty"
    },
    {
      "x": -2,
      "y": 28,
      "z": 1,
      "name": "Empty"
    },
    {
      "x": -2,
      "y": 29,
      "z": 1,
      "name": "Empty"
    },
    {
      "x": -2,
      "y": 30,
      "z": 1,
      "name": "Empty"
    },
    {
      "x": -2,
      "y": 31,
      "z": 1,
      "name": "Empty"
    },
    {
      "x": -2,
      "y": 32,
      "z": 1,
      "name": "Empty"
    },
    {
      "x": -2,
      "y": 33,
      "z": 1,
      "name": "Empty"
    },
    {
      "x": -2,
      "y": 34,
      "z": 1,
      "name": "Empty"
    },
    {
      "x": -2,
      "y": 35,
      "z": 1,
      "name": "Empty"
    },
    {
      "x": -2,
      "y": 36,
      "z": 1,
      "name": "Empty"
    },
    {
      "x": -2,
      "y": 37,
      "z": 1,
      "name": "Empty"
    },
    {
      "x": -2,
      "y": 38,
      "z": 1,
      "name": "Empty"
    },
    {
      "x": -2,
      "y": 39,
      "z": 1,
      "name": "Soil_Dirt_Burnt"
    },
    {
      "x": -2,
      "y": 40,
      "z": 1,
      "name": "Soil_Dirt_Burnt"
    },
    {
      "x": -2,
      "y": 41,
      "z": 1,
      "name": "Soil_Grass_Full"
    },
    {
      "x": -2,
      "y": 42,
      "z": 1,
      "name": "Empty"
    },
    {
      "x": -2,
      "y": 43,
      "z": 1,
      "name": "Plant_Vine_Jungle",
      "support": 15,
      "rotation": 2
    },
    {
      "x": -2,
      "y": 44,
      "z": 1,
      "name": "Plant_Vine_Jungle",
      "support": 15,
      "rotation": 2
    },
    {
      "x": -2,
      "y": 45,
      "z": 1,
      "name": "Plant_Vine_Jungle",
      "support": 15,
      "rotation": 2
    },
    {
      "x": -2,
      "y": 46,
      "z": 1,
      "name": "Plant_Vine_Jungle",
      "support": 15,
      "rotation": 2
    },
    {
      "x": -2,
      "y": 47,
      "z": 1,
      "name": "Empty"
    },
    {
      "x": -2,
      "y": 48,
      "z": 1,
      "name": "Soil_Dirt_Burnt"
    },
    {
      "x": -2,
      "y": 49,
      "z": 1,
      "name": "Soil_Dirt_Burnt"
    },
    {
      "x": -2,
      "y": 50,
      "z": 1,
      "name": "Soil_Grass_Full"
    },
    {
      "x": -2,
      "y": 51,
      "z": 1,
      "name": "Empty"
    },
    {
      "x": -2,
      "y": 52,
      "z": 1,
      "name": "Empty"
    },
    {
      "x": -2,
      "y": 53,
      "z": 1,
      "name": "Empty"
    },
    {
      "x": -2,
      "y": 68,
      "z": 1,
      "name": "Plant_Leaves_Jungle",
      "support": 15
    },
    {
      "x": -2,
      "y": 73,
      "z": 1,
      "name": "Plant_Leaves_Jungle",
      "support": 15
    },
    {
      "x": -2,
      "y": 74,
      "z": 1,
      "name": "Plant_Leaves_Jungle",
      "support": 15
    },
    {
      "x": -2,
      "y": 75,
      "z": 1,
      "name": "Plant_Leaves_Jungle",
      "support": 15
    },
    {
      "x": -2,
      "y": 23,
      "z": 2,
      "name": "Empty"
    },
    {
      "x": -2,
      "y": 24,
      "z": 2,
      "name": "Empty"
    },
    {
      "x": -2,
      "y": 25,
      "z": 2,
      "name": "Empty"
    },
    {
      "x": -2,
      "y": 26,
      "z": 2,
      "name": "Empty"
    },
    {
      "x": -2,
      "y": 27,
      "z": 2,
      "name": "Wood_Jungle_Trunk",
      "support": 15
    },
    {
      "x": -2,
      "y": 28,
      "z": 2,
      "name": "Wood_Jungle_Trunk",
      "support": 15
    },
    {
      "x": -2,
      "y": 29,
      "z": 2,
      "name": "Soil_Dirt_Burnt"
    },
    {
      "x": -2,
      "y": 30,
      "z": 2,
      "name": "Soil_Grass_Full"
    },
    {
      "x": -2,
      "y": 31,
      "z": 2,
      "name": "Empty"
    },
    {
      "x": -2,
      "y": 32,
      "z": 2,
      "name": "Empty"
    },
    {
